Workbook

Sheet Calculadora
B2: AMORTIZADOR DE DEUDAS PRO
B3: No Somos Ignorantes | v1.0 | Frances - Aleman - Americano en un solo lugar
B5: DATOS DEL PRESTAMO
B6: Capital del prestamo (Bs.) | C6: 200000
B7: Tasa de interes anual (%) | C7: 0.08
B8: Plazo (meses) | C8: 120 | E8: =IFERROR(ROUND(C8/12,1)&" anios","")
B9: Fecha de inicio | C9: 45658
B11: COMPARACION DE METODOS
B12: METRICA | C12: FRANCES | D12: ALEMAN | E12: AMERICANO | F12: MEJOR
B14: Cuota del primer mes (Bs.) | C14: =IFERROR(-PMT($C$7/12,$C$8,$C$6),0) | D14: =IFERROR($C$6/$C$8+$C$6*$C$7/12,0) | E14: =IFERROR($C$6*$C$7/12,0) | F14: =IF(MIN(C14,D14,E14)=C14,"Frances",IF(MIN(C14,D14,E14)=D14,"Aleman","Americano"))
B15: Cuota del ultimo mes (Bs.) | C15: =IFERROR(-PMT($C$7/12,$C$8,$C$6),0) | D15: =IFERROR($C$6/$C$8+($C$6/$C$8)*$C$7/12,0) | E15: =IFERROR($C$6+$C$6*$C$7/12,0) | F15: =IF(MIN(C15,D15,E15)=C15,"Frances",IF(MIN(C15,D15,E15)=D15,"Aleman","Americano"))
B16: Cuota promedio (Bs.) | C16: =IFERROR(-PMT($C$7/12,$C$8,$C$6),0) | D16: =IFERROR(($C$6/$C$8+$C$6*$C$7/12+$C$6/$C$8+($C$6/$C$8)*$C$7/12)/2,0) | E16: =IFERROR(($C$6*$C$7/12*($C$8-1)+$C$6+$C$6*$C$7/12)/$C$8,0) | F16: =IF(MIN(C16,D16,E16)=C16,"Frances",IF(MIN(C16,D16,E16)=D16,"Aleman","Americano"))
B17: Total a pagar (Bs.) | C17: =IFERROR(-PMT($C$7/12,$C$8,$C$6)*$C$8,0) | D17: =IFERROR($C$6+$C$6*$C$7/12*($C$8+1)/2,0) | E17: =IFERROR($C$6+$C$6*$C$7/12*$C$8,0) | F17: =IF(MIN(C17,D17,E17)=C17,"Frances",IF(MIN(C17,D17,E17)=D17,"Aleman","Americano"))
B18: Total intereses (Bs.) | C18: =IFERROR(C17-$C$6,0) | D18: =IFERROR(D17-$C$6,0) | E18: =IFERROR(E17-$C$6,0) | F18: =IF(MIN(C18,D18,E18)=C18,"Frances",IF(MIN(C18,D18,E18)=D18,"Aleman","Americano"))
B19: Relacion intereses/capital (%) | C19: =IFERROR(C18/$C$6,0) | D19: =IFERROR(D18/$C$6,0) | E19: =IFERROR(E18/$C$6,0) | F19: =IF(MIN(C19,D19,E19)=C19,"Frances",IF(MIN(C19,D19,E19)=D19,"Aleman","Americano"))
B21: =IFERROR("MENOR COSTO TOTAL: "&F17&" - Pagas Bs. "&TEXT(MIN(C17,D17,E17),"#,##0.00")&" | Ahorras Bs. "&TEXT(MAX(C17,D17,E17)-MIN(C17,D17,E17),"#,##0.00")&" vs el mas caro","Ingresa datos del prestamo")
B23: COMO FUNCIONA CADA METODO
B24: FRANCES (Cuota Fija) | C24: La cuota es siempre igual. Al inicio pagas mas interes, al final mas capital. El mas comun en Bolivia.
B25: ALEMAN (Amortizacion Fija) | C25: El capital que pagas es fijo cada mes. La cuota baja con el tiempo porque los intereses disminuyen.
B26: AMERICANO (Solo Interes) | C26: Solo pagas intereses cada mes. Al final devuelves TODO el capital de golpe (pago balloon).
B70: Metodo | C70: Total a Pagar | D70: Total Intereses
B71: Frances | C71: =C17 | D71: =C18
B72: Aleman | C72: =D17 | D72: =D18
B73: Americano | C73: =E17 | D73: =E18
B76: Metodo | C76: Capital | D76: Intereses
B77: Frances | C77: =$C$6 | D77: =C18
B78: Aleman | C78: =$C$6 | D78: =D18
B79: Americano | C79: =$C$6 | D79: =E18

Sheet Tabla_Frances
A1: TABLA DE AMORTIZACION - METODO FRANCES (Cuota Fija)
A2: Capital: | B2: =Calculadora!C6 | C2: Tasa: | D2: =Calculadora!C7 | E2: Plazo: | F2: =Calculadora!C8&" meses"
A3: Total Pagado: | B3: =IFERROR(SUM(D5:D364),0) | C3: Total Interes: | D3: =IFERROR(SUM(E5:E364),0) | E3: Total Capital: | F3: =IFERROR(SUM(F5:F364),0)
A4: # | B4: FECHA | C4: SALDO INICIAL | D4: CUOTA | E4: INTERES | F4: CAPITAL | G4: SALDO FINAL | H4: % PAGADO
A5: 1 | B5: =Calculadora!$C$9 | C5: =IF(Calculadora!$C$6>0,Calculadora!$C$6,0) | D5: =IF(C5<=0.01,0,IFERROR(-PMT(Calculadora!$C$7/12,Calculadora!$C$8,Calculadora!$C$6),0)) | E5: =IF(C5<=0.01,0,ROUND(C5*Calculadora!$C$7/12,2)) | F5: =IF(C5<=0.01,0,D5-E5) | G5: =IF(C5<=0.01,0,MAX(ROUND(C5-F5,2),0)) | H5: =IFERROR(IF(Calculadora!$C$6>0,1-(G5/Calculadora!$C$6),0),0)
A6: 2 | B6: =IFERROR(IF(C6<=0.01,"",EDATE(B5,1)),"") | C6: =IF(G5<=0.01,0,G5) | D6: =IF(C6<=0.01,0,IFERROR(-PMT(Calculadora!$C$7/12,Calculadora!$C$8,Calculadora!$C$6),0)) | E6: =IF(C6<=0.01,0,ROUND(C6*Calculadora!$C$7/12,2)) | F6: =IF(C6<=0.01,0,D6-E6) | G6: =IF(C6<=0.01,0,MAX(ROUND(C6-F6,2),0)) | H6: =IFERROR(IF(Calculadora!$C$6>0,1-(G6/Calculadora!$C$6),0),0)
A7: 3 | B7: =IFERROR(IF(C7<=0.01,"",EDATE(B6,1)),"") | C7: =IF(G6<=0.01,0,G6) | D7: =IF(C7<=0.01,0,IFERROR(-PMT(Calculadora!$C$7/12,Calculadora!$C$8,Calculadora!$C$6),0)) | E7: =IF(C7<=0.01,0,ROUND(C7*Calculadora!$C$7/12,2)) | F7: =IF(C7<=0.01,0,D7-E7) | G7: =IF(C7<=0.01,0,MAX(ROUND(C7-F7,2),0)) | H7: =IFERROR(IF(Calculadora!$C$6>0,1-(G7/Calculadora!$C$6),0),0)
A8: 4 | B8: =IFERROR(IF(C8<=0.01,"",EDATE(B7,1)),"") | C8: =IF(G7<=0.01,0,G7) | D8: =IF(C8<=0.01,0,IFERROR(-PMT(Calculadora!$C$7/12,Calculadora!$C$8,Calculadora!$C$6),0)) | E8: =IF(C8<=0.01,0,ROUND(C8*Calculadora!$C$7/12,2)) | F8: =IF(C8<=0.01,0,D8-E8) | G8: =IF(C8<=0.01,0,MAX(ROUND(C8-F8,2),0)) | H8: =IFERROR(IF(Calculadora!$C$6>0,1-(G8/Calculadora!$C$6),0),0)
A9: 5 | B9: =IFERROR(IF(C9<=0.01,"",EDATE(B8,1)),"") | C9: =IF(G8<=0.01,0,G8) | D9: =IF(C9<=0.01,0,IFERROR(-PMT(Calculadora!$C$7/12,Calculadora!$C$8,Calculadora!$C$6),0)) | E9: =IF(C9<=0.01,0,ROUND(C9*Calculadora!$C$7/12,2)) | F9: =IF(C9<=0.01,0,D9-E9) | G9: =IF(C9<=0.01,0,MAX(ROUND(C9-F9,2),0)) | H9: =IFERROR(IF(Calculadora!$C$6>0,1-(G9/Calculadora!$C$6),0),0)
A10: 6 | B10: =IFERROR(IF(C10<=0.01,"",EDATE(B9,1)),"") | C10: =IF(G9<=0.01,0,G9) | D10: =IF(C10<=0.01,0,IFERROR(-PMT(Calculadora!$C$7/12,Calculadora!$C$8,Calculadora!$C$6),0)) | E10: =IF(C10<=0.01,0,ROUND(C10*Calculadora!$C$7/12,2)) | F10: =IF(C10<=0.01,0,D10-E10) | G10: =IF(C10<=0.01,0,MAX(ROUND(C10-F10,2),0)) | H10: =IFERROR(IF(Calculadora!$C$6>0,1-(G10/Calculadora!$C$6),0),0)
A11: 7 | B11: =IFERROR(IF(C11<=0.01,"",EDATE(B10,1)),"") | C11: =IF(G10<=0.01,0,G10) | D11: =IF(C11<=0.01,0,IFERROR(-PMT(Calculadora!$C$7/12,Calculadora!$C$8,Calculadora!$C$6),0)) | E11: =IF(C11<=0.01,0,ROUND(C11*Calculadora!$C$7/12,2)) | F11: =IF(C11<=0.01,0,D11-E11) | G11: =IF(C11<=0.01,0,MAX(ROUND(C11-F11,2),0)) | H11: =IFERROR(IF(Calculadora!$C$6>0,1-(G11/Calculadora!$C$6),0),0)
A12: 8 | B12: =IFERROR(IF(C12<=0.01,"",EDATE(B11,1)),"") | C12: =IF(G11<=0.01,0,G11) | D12: =IF(C12<=0.01,0,IFERROR(-PMT(Calculadora!$C$7/12,Calculadora!$C$8,Calculadora!$C$6),0)) | E12: =IF(C12<=0.01,0,ROUND(C12*Calculadora!$C$7/12,2)) | F12: =IF(C12<=0.01,0,D12-E12) | G12: =IF(C12<=0.01,0,MAX(ROUND(C12-F12,2),0)) | H12: =IFERROR(IF(Calculadora!$C$6>0,1-(G12/Calculadora!$C$6),0),0)
A13: 9 | B13: =IFERROR(IF(C13<=0.01,"",EDATE(B12,1)),"") | C13: =IF(G12<=0.01,0,G12) | D13: =IF(C13<=0.01,0,IFERROR(-PMT(Calculadora!$C$7/12,Calculadora!$C$8,Calculadora!$C$6),0)) | E13: =IF(C13<=0.01,0,ROUND(C13*Calculadora!$C$7/12,2)) | F13: =IF(C13<=0.01,0,D13-E13) | G13: =IF(C13<=0.01,0,MAX(ROUND(C13-F13,2),0)) | H13: =IFERROR(IF(Calculadora!$C$6>0,1-(G13/Calculadora!$C$6),0),0)
A14: 10 | B14: =IFERROR(IF(C14<=0.01,"",EDATE(B13,1)),"") | C14: =IF(G13<=0.01,0,G13) | D14: =IF(C14<=0.01,0,IFERROR(-PMT(Calculadora!$C$7/12,Calculadora!$C$8,Calculadora!$C$6),0)) | E14: =IF(C14<=0.01,0,ROUND(C14*Calculadora!$C$7/12,2)) | F14: =IF(C14<=0.01,0,D14-E14) | G14: =IF(C14<=0.01,0,MAX(ROUND(C14-F14,2),0)) | H14: =IFERROR(IF(Calculadora!$C$6>0,1-(G14/Calculadora!$C$6),0),0)
A15: 11 | B15: =IFERROR(IF(C15<=0.01,"",EDATE(B14,1)),"") | C15: =IF(G14<=0.01,0,G14) | D15: =IF(C15<=0.01,0,IFERROR(-PMT(Calculadora!$C$7/12,Calculadora!$C$8,Calculadora!$C$6),0)) | E15: =IF(C15<=0.01,0,ROUND(C15*Calculadora!$C$7/12,2)) | F15: =IF(C15<=0.01,0,D15-E15) | G15: =IF(C15<=0.01,0,MAX(ROUND(C15-F15,2),0)) | H15: =IFERROR(IF(Calculadora!$C$6>0,1-(G15/Calculadora!$C$6),0),0)
A16: 12 | B16: =IFERROR(IF(C16<=0.01,"",EDATE(B15,1)),"") | C16: =IF(G15<=0.01,0,G15) | D16: =IF(C16<=0.01,0,IFERROR(-PMT(Calculadora!$C$7/12,Calculadora!$C$8,Calculadora!$C$6),0)) | E16: =IF(C16<=0.01,0,ROUND(C16*Calculadora!$C$7/12,2)) | F16: =IF(C16<=0.01,0,D16-E16) | G16: =IF(C16<=0.01,0,MAX(ROUND(C16-F16,2),0)) | H16: =IFERROR(IF(Calculadora!$C$6>0,1-(G16/Calculadora!$C$6),0),0)
A17: 13 | B17: =IFERROR(IF(C17<=0.01,"",EDATE(B16,1)),"") | C17: =IF(G16<=0.01,0,G16) | D17: =IF(C17<=0.01,0,IFERROR(-PMT(Calculadora!$C$7/12,Calculadora!$C$8,Calculadora!$C$6),0)) | E17: =IF(C17<=0.01,0,ROUND(C17*Calculadora!$C$7/12,2)) | F17: =IF(C17<=0.01,0,D17-E17) | G17: =IF(C17<=0.01,0,MAX(ROUND(C17-F17,2),0)) | H17: =IFERROR(IF(Calculadora!$C$6>0,1-(G17/Calculadora!$C$6),0),0)
... A364: 360 | B364: =IFERROR(IF(C364<=0.01,"",EDATE(B363,1)),"") | C364: =IF(G363<=0.01,0,G363) | D364: =IF(C364<=0.01,0,IFERROR(-PMT(Calculadora!$C$7/12,Calculadora!$C$8,Calculadora!$C$6),0)) | E364: =IF(C364<=0.01,0,ROUND(C364*Calculadora!$C$7/12,2)) | F364: =IF(C364<=0.01,0,D364-E364) | G364: =IF(C364<=0.01,0,MAX(ROUND(C364-F364,2),0)) | H364: =IFERROR(IF(Calculadora!$C$6>0,1-(G364/Calculadora!$C$6),0),0)
A365: TOTAL | D365: =SUM(D5:D364) | E365: =SUM(E5:E364) | F365: =SUM(F5:F364)

Sheet Tabla_Aleman
A1: TABLA DE AMORTIZACION - METODO ALEMAN (Amortizacion Fija)
A2: Capital: | B2: =Calculadora!C6 | C2: Tasa: | D2: =Calculadora!C7 | E2: Plazo: | F2: =Calculadora!C8&" meses"
A3: Total Pagado: | B3: =IFERROR(SUM(D5:D364),0) | C3: Total Interes: | D3: =IFERROR(SUM(E5:E364),0) | E3: Total Capital: | F3: =IFERROR(SUM(F5:F364),0)
A4: # | B4: FECHA | C4: SALDO INICIAL | D4: CUOTA | E4: INTERES | F4: CAPITAL | G4: SALDO FINAL | H4: % PAGADO
A5: 1 | B5: =Calculadora!$C$9 | C5: =IF(Calculadora!$C$6>0,Calculadora!$C$6,0) | D5: =IF(C5<=0.01,0,F5+E5) | E5: =IF(C5<=0.01,0,ROUND(C5*Calculadora!$C$7/12,2)) | F5: =IF(C5<=0.01,0,ROUND(Calculadora!$C$6/Calculadora!$C$8,2)) | G5: =IF(C5<=0.01,0,MAX(ROUND(C5-F5,2),0)) | H5: =IFERROR(IF(Calculadora!$C$6>0,1-(G5/Calculadora!$C$6),0),0)
A6: 2 | B6: =IFERROR(IF(C6<=0.01,"",EDATE(B5,1)),"") | C6: =IF(G5<=0.01,0,G5) | D6: =IF(C6<=0.01,0,F6+E6) | E6: =IF(C6<=0.01,0,ROUND(C6*Calculadora!$C$7/12,2)) | F6: =IF(C6<=0.01,0,ROUND(Calculadora!$C$6/Calculadora!$C$8,2)) | G6: =IF(C6<=0.01,0,MAX(ROUND(C6-F6,2),0)) | H6: =IFERROR(IF(Calculadora!$C$6>0,1-(G6/Calculadora!$C$6),0),0)
A7: 3 | B7: =IFERROR(IF(C7<=0.01,"",EDATE(B6,1)),"") | C7: =IF(G6<=0.01,0,G6) | D7: =IF(C7<=0.01,0,F7+E7) | E7: =IF(C7<=0.01,0,ROUND(C7*Calculadora!$C$7/12,2)) | F7: =IF(C7<=0.01,0,ROUND(Calculadora!$C$6/Calculadora!$C$8,2)) | G7: =IF(C7<=0.01,0,MAX(ROUND(C7-F7,2),0)) | H7: =IFERROR(IF(Calculadora!$C$6>0,1-(G7/Calculadora!$C$6),0),0)
A8: 4 | B8: =IFERROR(IF(C8<=0.01,"",EDATE(B7,1)),"") | C8: =IF(G7<=0.01,0,G7) | D8: =IF(C8<=0.01,0,F8+E8) | E8: =IF(C8<=0.01,0,ROUND(C8*Calculadora!$C$7/12,2)) | F8: =IF(C8<=0.01,0,ROUND(Calculadora!$C$6/Calculadora!$C$8,2)) | G8: =IF(C8<=0.01,0,MAX(ROUND(C8-F8,2),0)) | H8: =IFERROR(IF(Calculadora!$C$6>0,1-(G8/Calculadora!$C$6),0),0)
A9: 5 | B9: =IFERROR(IF(C9<=0.01,"",EDATE(B8,1)),"") | C9: =IF(G8<=0.01,0,G8) | D9: =IF(C9<=0.01,0,F9+E9) | E9: =IF(C9<=0.01,0,ROUND(C9*Calculadora!$C$7/12,2)) | F9: =IF(C9<=0.01,0,ROUND(Calculadora!$C$6/Calculadora!$C$8,2)) | G9: =IF(C9<=0.01,0,MAX(ROUND(C9-F9,2),0)) | H9: =IFERROR(IF(Calculadora!$C$6>0,1-(G9/Calculadora!$C$6),0),0)
A10: 6 | B10: =IFERROR(IF(C10<=0.01,"",EDATE(B9,1)),"") | C10: =IF(G9<=0.01,0,G9) | D10: =IF(C10<=0.01,0,F10+E10) | E10: =IF(C10<=0.01,0,ROUND(C10*Calculadora!$C$7/12,2)) | F10: =IF(C10<=0.01,0,ROUND(Calculadora!$C$6/Calculadora!$C$8,2)) | G10: =IF(C10<=0.01,0,MAX(ROUND(C10-F10,2),0)) | H10: =IFERROR(IF(Calculadora!$C$6>0,1-(G10/Calculadora!$C$6),0),0)
A11: 7 | B11: =IFERROR(IF(C11<=0.01,"",EDATE(B10,1)),"") | C11: =IF(G10<=0.01,0,G10) | D11: =IF(C11<=0.01,0,F11+E11) | E11: =IF(C11<=0.01,0,ROUND(C11*Calculadora!$C$7/12,2)) | F11: =IF(C11<=0.01,0,ROUND(Calculadora!$C$6/Calculadora!$C$8,2)) | G11: =IF(C11<=0.01,0,MAX(ROUND(C11-F11,2),0)) | H11: =IFERROR(IF(Calculadora!$C$6>0,1-(G11/Calculadora!$C$6),0),0)
A12: 8 | B12: =IFERROR(IF(C12<=0.01,"",EDATE(B11,1)),"") | C12: =IF(G11<=0.01,0,G11) | D12: =IF(C12<=0.01,0,F12+E12) | E12: =IF(C12<=0.01,0,ROUND(C12*Calculadora!$C$7/12,2)) | F12: =IF(C12<=0.01,0,ROUND(Calculadora!$C$6/Calculadora!$C$8,2)) | G12: =IF(C12<=0.01,0,MAX(ROUND(C12-F12,2),0)) | H12: =IFERROR(IF(Calculadora!$C$6>0,1-(G12/Calculadora!$C$6),0),0)
A13: 9 | B13: =IFERROR(IF(C13<=0.01,"",EDATE(B12,1)),"") | C13: =IF(G12<=0.01,0,G12) | D13: =IF(C13<=0.01,0,F13+E13) | E13: =IF(C13<=0.01,0,ROUND(C13*Calculadora!$C$7/12,2)) | F13: =IF(C13<=0.01,0,ROUND(Calculadora!$C$6/Calculadora!$C$8,2)) | G13: =IF(C13<=0.01,0,MAX(ROUND(C13-F13,2),0)) | H13: =IFERROR(IF(Calculadora!$C$6>0,1-(G13/Calculadora!$C$6),0),0)
A14: 10 | B14: =IFERROR(IF(C14<=0.01,"",EDATE(B13,1)),"") | C14: =IF(G13<=0.01,0,G13) | D14: =IF(C14<=0.01,0,F14+E14) | E14: =IF(C14<=0.01,0,ROUND(C14*Calculadora!$C$7/12,2)) | F14: =IF(C14<=0.01,0,ROUND(Calculadora!$C$6/Calculadora!$C$8,2)) | G14: =IF(C14<=0.01,0,MAX(ROUND(C14-F14,2),0)) | H14: =IFERROR(IF(Calculadora!$C$6>0,1-(G14/Calculadora!$C$6),0),0)
A15: 11 | B15: =IFERROR(IF(C15<=0.01,"",EDATE(B14,1)),"") | C15: =IF(G14<=0.01,0,G14) | D15: =IF(C15<=0.01,0,F15+E15) | E15: =IF(C15<=0.01,0,ROUND(C15*Calculadora!$C$7/12,2)) | F15: =IF(C15<=0.01,0,ROUND(Calculadora!$C$6/Calculadora!$C$8,2)) | G15: =IF(C15<=0.01,0,MAX(ROUND(C15-F15,2),0)) | H15: =IFERROR(IF(Calculadora!$C$6>0,1-(G15/Calculadora!$C$6),0),0)
A16: 12 | B16: =IFERROR(IF(C16<=0.01,"",EDATE(B15,1)),"") | C16: =IF(G15<=0.01,0,G15) | D16: =IF(C16<=0.01,0,F16+E16) | E16: =IF(C16<=0.01,0,ROUND(C16*Calculadora!$C$7/12,2)) | F16: =IF(C16<=0.01,0,ROUND(Calculadora!$C$6/Calculadora!$C$8,2)) | G16: =IF(C16<=0.01,0,MAX(ROUND(C16-F16,2),0)) | H16: =IFERROR(IF(Calculadora!$C$6>0,1-(G16/Calculadora!$C$6),0),0)
A17: 13 | B17: =IFERROR(IF(C17<=0.01,"",EDATE(B16,1)),"") | C17: =IF(G16<=0.01,0,G16) | D17: =IF(C17<=0.01,0,F17+E17) | E17: =IF(C17<=0.01,0,ROUND(C17*Calculadora!$C$7/12,2)) | F17: =IF(C17<=0.01,0,ROUND(Calculadora!$C$6/Calculadora!$C$8,2)) | G17: =IF(C17<=0.01,0,MAX(ROUND(C17-F17,2),0)) | H17: =IFERROR(IF(Calculadora!$C$6>0,1-(G17/Calculadora!$C$6),0),0)
... A364: 360 | B364: =IFERROR(IF(C364<=0.01,"",EDATE(B363,1)),"") | C364: =IF(G363<=0.01,0,G363) | D364: =IF(C364<=0.01,0,F364+E364) | E364: =IF(C364<=0.01,0,ROUND(C364*Calculadora!$C$7/12,2)) | F364: =IF(C364<=0.01,0,ROUND(Calculadora!$C$6/Calculadora!$C$8,2)) | G364: =IF(C364<=0.01,0,MAX(ROUND(C364-F364,2),0)) | H364: =IFERROR(IF(Calculadora!$C$6>0,1-(G364/Calculadora!$C$6),0),0)
A365: TOTAL | D365: =SUM(D5:D364) | E365: =SUM(E5:E364) | F365: =SUM(F5:F364)

Sheet Tabla_Americano
A1: TABLA DE AMORTIZACION - METODO AMERICANO (Interes + Balloon)
A2: Capital: | B2: =Calculadora!C6 | C2: Tasa: | D2: =Calculadora!C7 | E2: Plazo: | F2: =Calculadora!C8&" meses"
A3: Total Pagado: | B3: =IFERROR(SUM(D5:D364),0) | C3: Total Interes: | D3: =IFERROR(SUM(E5:E364),0) | E3: Total Capital: | F3: =IFERROR(SUM(F5:F364),0)
A4: # | B4: FECHA | C4: SALDO INICIAL | D4: CUOTA | E4: INTERES | F4: CAPITAL | G4: SALDO FINAL | H4: % PAGADO
A5: 1 | B5: =Calculadora!$C$9 | C5: =IF(Calculadora!$C$6>0,Calculadora!$C$6,0) | D5: =IF(C5<=0.01,0,IF(A5<Calculadora!$C$8,E5,E5+C5)) | E5: =IF(C5<=0.01,0,ROUND(C5*Calculadora!$C$7/12,2)) | F5: =IF(C5<=0.01,0,D5-E5) | G5: =IF(C5<=0.01,0,MAX(ROUND(C5-F5,2),0)) | H5: =IFERROR(IF(Calculadora!$C$6>0,1-(G5/Calculadora!$C$6),0),0)
A6: 2 | B6: =IFERROR(IF(C6<=0.01,"",EDATE(B5,1)),"") | C6: =IF(G5<=0.01,0,G5) | D6: =IF(C6<=0.01,0,IF(A6<Calculadora!$C$8,E6,E6+C6)) | E6: =IF(C6<=0.01,0,ROUND(C6*Calculadora!$C$7/12,2)) | F6: =IF(C6<=0.01,0,D6-E6) | G6: =IF(C6<=0.01,0,MAX(ROUND(C6-F6,2),0)) | H6: =IFERROR(IF(Calculadora!$C$6>0,1-(G6/Calculadora!$C$6),0),0)
A7: 3 | B7: =IFERROR(IF(C7<=0.01,"",EDATE(B6,1)),"") | C7: =IF(G6<=0.01,0,G6) | D7: =IF(C7<=0.01,0,IF(A7<Calculadora!$C$8,E7,E7+C7)) | E7: =IF(C7<=0.01,0,ROUND(C7*Calculadora!$C$7/12,2)) | F7: =IF(C7<=0.01,0,D7-E7) | G7: =IF(C7<=0.01,0,MAX(ROUND(C7-F7,2),0)) | H7: =IFERROR(IF(Calculadora!$C$6>0,1-(G7/Calculadora!$C$6),0),0)
A8: 4 | B8: =IFERROR(IF(C8<=0.01,"",EDATE(B7,1)),"") | C8: =IF(G7<=0.01,0,G7) | D8: =IF(C8<=0.01,0,IF(A8<Calculadora!$C$8,E8,E8+C8)) | E8: =IF(C8<=0.01,0,ROUND(C8*Calculadora!$C$7/12,2)) | F8: =IF(C8<=0.01,0,D8-E8) | G8: =IF(C8<=0.01,0,MAX(ROUND(C8-F8,2),0)) | H8: =IFERROR(IF(Calculadora!$C$6>0,1-(G8/Calculadora!$C$6),0),0)
A9: 5 | B9: =IFERROR(IF(C9<=0.01,"",EDATE(B8,1)),"") | C9: =IF(G8<=0.01,0,G8) | D9: =IF(C9<=0.01,0,IF(A9<Calculadora!$C$8,E9,E9+C9)) | E9: =IF(C9<=0.01,0,ROUND(C9*Calculadora!$C$7/12,2)) | F9: =IF(C9<=0.01,0,D9-E9) | G9: =IF(C9<=0.01,0,MAX(ROUND(C9-F9,2),0)) | H9: =IFERROR(IF(Calculadora!$C$6>0,1-(G9/Calculadora!$C$6),0),0)
A10: 6 | B10: =IFERROR(IF(C10<=0.01,"",EDATE(B9,1)),"") | C10: =IF(G9<=0.01,0,G9) | D10: =IF(C10<=0.01,0,IF(A10<Calculadora!$C$8,E10,E10+C10)) | E10: =IF(C10<=0.01,0,ROUND(C10*Calculadora!$C$7/12,2)) | F10: =IF(C10<=0.01,0,D10-E10) | G10: =IF(C10<=0.01,0,MAX(ROUND(C10-F10,2),0)) | H10: =IFERROR(IF(Calculadora!$C$6>0,1-(G10/Calculadora!$C$6),0),0)
A11: 7 | B11: =IFERROR(IF(C11<=0.01,"",EDATE(B10,1)),"") | C11: =IF(G10<=0.01,0,G10) | D11: =IF(C11<=0.01,0,IF(A11<Calculadora!$C$8,E11,E11+C11)) | E11: =IF(C11<=0.01,0,ROUND(C11*Calculadora!$C$7/12,2)) | F11: =IF(C11<=0.01,0,D11-E11) | G11: =IF(C11<=0.01,0,MAX(ROUND(C11-F11,2),0)) | H11: =IFERROR(IF(Calculadora!$C$6>0,1-(G11/Calculadora!$C$6),0),0)
A12: 8 | B12: =IFERROR(IF(C12<=0.01,"",EDATE(B11,1)),"") | C12: =IF(G11<=0.01,0,G11) | D12: =IF(C12<=0.01,0,IF(A12<Calculadora!$C$8,E12,E12+C12)) | E12: =IF(C12<=0.01,0,ROUND(C12*Calculadora!$C$7/12,2)) | F12: =IF(C12<=0.01,0,D12-E12) | G12: =IF(C12<=0.01,0,MAX(ROUND(C12-F12,2),0)) | H12: =IFERROR(IF(Calculadora!$C$6>0,1-(G12/Calculadora!$C$6),0),0)
A13: 9 | B13: =IFERROR(IF(C13<=0.01,"",EDATE(B12,1)),"") | C13: =IF(G12<=0.01,0,G12) | D13: =IF(C13<=0.01,0,IF(A13<Calculadora!$C$8,E13,E13+C13)) | E13: =IF(C13<=0.01,0,ROUND(C13*Calculadora!$C$7/12,2)) | F13: =IF(C13<=0.01,0,D13-E13) | G13: =IF(C13<=0.01,0,MAX(ROUND(C13-F13,2),0)) | H13: =IFERROR(IF(Calculadora!$C$6>0,1-(G13/Calculadora!$C$6),0),0)
A14: 10 | B14: =IFERROR(IF(C14<=0.01,"",EDATE(B13,1)),"") | C14: =IF(G13<=0.01,0,G13) | D14: =IF(C14<=0.01,0,IF(A14<Calculadora!$C$8,E14,E14+C14)) | E14: =IF(C14<=0.01,0,ROUND(C14*Calculadora!$C$7/12,2)) | F14: =IF(C14<=0.01,0,D14-E14) | G14: =IF(C14<=0.01,0,MAX(ROUND(C14-F14,2),0)) | H14: =IFERROR(IF(Calculadora!$C$6>0,1-(G14/Calculadora!$C$6),0),0)
A15: 11 | B15: =IFERROR(IF(C15<=0.01,"",EDATE(B14,1)),"") | C15: =IF(G14<=0.01,0,G14) | D15: =IF(C15<=0.01,0,IF(A15<Calculadora!$C$8,E15,E15+C15)) | E15: =IF(C15<=0.01,0,ROUND(C15*Calculadora!$C$7/12,2)) | F15: =IF(C15<=0.01,0,D15-E15) | G15: =IF(C15<=0.01,0,MAX(ROUND(C15-F15,2),0)) | H15: =IFERROR(IF(Calculadora!$C$6>0,1-(G15/Calculadora!$C$6),0),0)
A16: 12 | B16: =IFERROR(IF(C16<=0.01,"",EDATE(B15,1)),"") | C16: =IF(G15<=0.01,0,G15) | D16: =IF(C16<=0.01,0,IF(A16<Calculadora!$C$8,E16,E16+C16)) | E16: =IF(C16<=0.01,0,ROUND(C16*Calculadora!$C$7/12,2)) | F16: =IF(C16<=0.01,0,D16-E16) | G16: =IF(C16<=0.01,0,MAX(ROUND(C16-F16,2),0)) | H16: =IFERROR(IF(Calculadora!$C$6>0,1-(G16/Calculadora!$C$6),0),0)
A17: 13 | B17: =IFERROR(IF(C17<=0.01,"",EDATE(B16,1)),"") | C17: =IF(G16<=0.01,0,G16) | D17: =IF(C17<=0.01,0,IF(A17<Calculadora!$C$8,E17,E17+C17)) | E17: =IF(C17<=0.01,0,ROUND(C17*Calculadora!$C$7/12,2)) | F17: =IF(C17<=0.01,0,D17-E17) | G17: =IF(C17<=0.01,0,MAX(ROUND(C17-F17,2),0)) | H17: =IFERROR(IF(Calculadora!$C$6>0,1-(G17/Calculadora!$C$6),0),0)
... A364: 360 | B364: =IFERROR(IF(C364<=0.01,"",EDATE(B363,1)),"") | C364: =IF(G363<=0.01,0,G363) | D364: =IF(C364<=0.01,0,IF(A364<Calculadora!$C$8,E364,E364+C364)) | E364: =IF(C364<=0.01,0,ROUND(C364*Calculadora!$C$7/12,2)) | F364: =IF(C364<=0.01,0,D364-E364) | G364: =IF(C364<=0.01,0,MAX(ROUND(C364-F364,2),0)) | H364: =IFERROR(IF(Calculadora!$C$6>0,1-(G364/Calculadora!$C$6),0),0)
A365: TOTAL | D365: =SUM(D5:D364) | E365: =SUM(E5:E364) | F365: =SUM(F5:F364)

Sheet Comparacion
B2: COMPARACION VISUAL DE METODOS
B3: Evolucion de cuotas y saldos en los 3 metodos
B5: CUOTA POR ANIO (Bs.)
B6: ANIO | C6: FRANCES | D6: ALEMAN | E6: AMERICANO
B7: 1 | C7: =IFERROR(IF(Tabla_Frances!C5>0.01,Tabla_Frances!D5,""),"") | D7: =IFERROR(IF(Tabla_Aleman!C5>0.01,Tabla_Aleman!D5,""),"") | E7: =IFERROR(IF(Tabla_Americano!C5>0.01,Tabla_Americano!D5,""),"")
B8: 2 | C8: =IFERROR(IF(Tabla_Frances!C17>0.01,Tabla_Frances!D17,""),"") | D8: =IFERROR(IF(Tabla_Aleman!C17>0.01,Tabla_Aleman!D17,""),"") | E8: =IFERROR(IF(Tabla_Americano!C17>0.01,Tabla_Americano!D17,""),"")
B9: 3 | C9: =IFERROR(IF(Tabla_Frances!C29>0.01,Tabla_Frances!D29,""),"") | D9: =IFERROR(IF(Tabla_Aleman!C29>0.01,Tabla_Aleman!D29,""),"") | E9: =IFERROR(IF(Tabla_Americano!C29>0.01,Tabla_Americano!D29,""),"")
B10: 4 | C10: =IFERROR(IF(Tabla_Frances!C41>0.01,Tabla_Frances!D41,""),"") | D10: =IFERROR(IF(Tabla_Aleman!C41>0.01,Tabla_Aleman!D41,""),"") | E10: =IFERROR(IF(Tabla_Americano!C41>0.01,Tabla_Americano!D41,""),"")
B11: 5 | C11: =IFERROR(IF(Tabla_Frances!C53>0.01,Tabla_Frances!D53,""),"") | D11: =IFERROR(IF(Tabla_Aleman!C53>0.01,Tabla_Aleman!D53,""),"") | E11: =IFERROR(IF(Tabla_Americano!C53>0.01,Tabla_Americano!D53,""),"")
B12: 6 | C12: =IFERROR(IF(Tabla_Frances!C65>0.01,Tabla_Frances!D65,""),"") | D12: =IFERROR(IF(Tabla_Aleman!C65>0.01,Tabla_Aleman!D65,""),"") | E12: =IFERROR(IF(Tabla_Americano!C65>0.01,Tabla_Americano!D65,""),"")
B13: 7 | C13: =IFERROR(IF(Tabla_Frances!C77>0.01,Tabla_Frances!D77,""),"") | D13: =IFERROR(IF(Tabla_Aleman!C77>0.01,Tabla_Aleman!D77,""),"") | E13: =IFERROR(IF(Tabla_Americano!C77>0.01,Tabla_Americano!D77,""),"")
B14: 8 | C14: =IFERROR(IF(Tabla_Frances!C89>0.01,Tabla_Frances!D89,""),"") | D14: =IFERROR(IF(Tabla_Aleman!C89>0.01,Tabla_Aleman!D89,""),"") | E14: =IFERROR(IF(Tabla_Americano!C89>0.01,Tabla_Americano!D89,""),"")
B15: 9 | C15: =IFERROR(IF(Tabla_Frances!C101>0.01,Tabla_Frances!D101,""),"") | D15: =IFERROR(IF(Tabla_Aleman!C101>0.01,Tabla_Aleman!D101,""),"") | E15: =IFERROR(IF(Tabla_Americano!C101>0.01,Tabla_Americano!D101,""),"")
B16: 10 | C16: =IFERROR(IF(Tabla_Frances!C113>0.01,Tabla_Frances!D113,""),"") | D16: =IFERROR(IF(Tabla_Aleman!C113>0.01,Tabla_Aleman!D113,""),"") | E16: =IFERROR(IF(Tabla_Americano!C113>0.01,Tabla_Americano!D113,""),"")
B17: 11 | C17: =IFERROR(IF(Tabla_Frances!C125>0.01,Tabla_Frances!D125,""),"") | D17: =IFERROR(IF(Tabla_Aleman!C125>0.01,Tabla_Aleman!D125,""),"") | E17: =IFERROR(IF(Tabla_Americano!C125>0.01,Tabla_Americano!D125,""),"")
B18: 12 | C18: =IFERROR(IF(Tabla_Frances!C137>0.01,Tabla_Frances!D137,""),"") | D18: =IFERROR(IF(Tabla_Aleman!C137>0.01,Tabla_Aleman!D137,""),"") | E18: =IFERROR(IF(Tabla_Americano!C137>0.01,Tabla_Americano!D137,""),"")
B19: 13 | C19: =IFERROR(IF(Tabla_Frances!C149>0.01,Tabla_Frances!D149,""),"") | D19: =IFERROR(IF(Tabla_Aleman!C149>0.01,Tabla_Aleman!D149,""),"") | E19: =IFERROR(IF(Tabla_Americano!C149>0.01,Tabla_Americano!D149,""),"")
B20: 14 | C20: =IFERROR(IF(Tabla_Frances!C161>0.01,Tabla_Frances!D161,""),"") | D20: =IFERROR(IF(Tabla_Aleman!C161>0.01,Tabla_Aleman!D161,""),"") | E20: =IFERROR(IF(Tabla_Americano!C161>0.01,Tabla_Americano!D161,""),"")
B21: 15 | C21: =IFERROR(IF(Tabla_Frances!C173>0.01,Tabla_Frances!D173,""),"") | D21: =IFERROR(IF(Tabla_Aleman!C173>0.01,Tabla_Aleman!D173,""),"") | E21: =IFERROR(IF(Tabla_Americano!C173>0.01,Tabla_Americano!D173,""),"")
B22: 16 | C22: =IFERROR(IF(Tabla_Frances!C185>0.01,Tabla_Frances!D185,""),"") | D22: =IFERROR(IF(Tabla_Aleman!C185>0.01,Tabla_Aleman!D185,""),"") | E22: =IFERROR(IF(Tabla_Americano!C185>0.01,Tabla_Americano!D185,""),"")
B23: 17 | C23: =IFERROR(IF(Tabla_Frances!C197>0.01,Tabla_Frances!D197,""),"") | D23: =IFERROR(IF(Tabla_Aleman!C197>0.01,Tabla_Aleman!D197,""),"") | E23: =IFERROR(IF(Tabla_Americano!C197>0.01,Tabla_Americano!D197,""),"")
B24: 18 | C24: =IFERROR(IF(Tabla_Frances!C209>0.01,Tabla_Frances!D209,""),"") | D24: =IFERROR(IF(Tabla_Aleman!C209>0.01,Tabla_Aleman!D209,""),"") | E24: =IFERROR(IF(Tabla_Americano!C209>0.01,Tabla_Americano!D209,""),"")
B25: 19 | C25: =IFERROR(IF(Tabla_Frances!C221>0.01,Tabla_Frances!D221,""),"") | D25: =IFERROR(IF(Tabla_Aleman!C221>0.01,Tabla_Aleman!D221,""),"") | E25: =IFERROR(IF(Tabla_Americano!C221>0.01,Tabla_Americano!D221,""),"")
B26: 20 | C26: =IFERROR(IF(Tabla_Frances!C233>0.01,Tabla_Frances!D233,""),"") | D26: =IFERROR(IF(Tabla_Aleman!C233>0.01,Tabla_Aleman!D233,""),"") | E26: =IFERROR(IF(Tabla_Americano!C233>0.01,Tabla_Americano!D233,""),"")
B27: 21 | C27: =IFERROR(IF(Tabla_Frances!C245>0.01,Tabla_Frances!D245,""),"") | D27: =IFERROR(IF(Tabla_Aleman!C245>0.01,Tabla_Aleman!D245,""),"") | E27: =IFERROR(IF(Tabla_Americano!C245>0.01,Tabla_Americano!D245,""),"")
B28: 22 | C28: =IFERROR(IF(Tabla_Frances!C257>0.01,Tabla_Frances!D257,""),"") | D28: =IFERROR(IF(Tabla_Aleman!C257>0.01,Tabla_Aleman!D257,""),"") | E28: =IFERROR(IF(Tabla_Americano!C257>0.01,Tabla_Americano!D257,""),"")
B29: 23 | C29: =IFERROR(IF(Tabla_Frances!C269>0.01,Tabla_Frances!D269,""),"") | D29: =IFERROR(IF(Tabla_Aleman!C269>0.01,Tabla_Aleman!D269,""),"") | E29: =IFERROR(IF(Tabla_Americano!C269>0.01,Tabla_Americano!D269,""),"")
B30: 24 | C30: =IFERROR(IF(Tabla_Frances!C281>0.01,Tabla_Frances!D281,""),"") | D30: =IFERROR(IF(Tabla_Aleman!C281>0.01,Tabla_Aleman!D281,""),"") | E30: =IFERROR(IF(Tabla_Americano!C281>0.01,Tabla_Americano!D281,""),"")
B31: 25 | C31: =IFERROR(IF(Tabla_Frances!C293>0.01,Tabla_Frances!D293,""),"") | D31: =IFERROR(IF(Tabla_Aleman!C293>0.01,Tabla_Aleman!D293,""),"") | E31: =IFERROR(IF(Tabla_Americano!C293>0.01,Tabla_Americano!D293,""),"")
B32: 26 | C32: =IFERROR(IF(Tabla_Frances!C305>0.01,Tabla_Frances!D305,""),"") | D32: =IFERROR(IF(Tabla_Aleman!C305>0.01,Tabla_Aleman!D305,""),"") | E32: =IFERROR(IF(Tabla_Americano!C305>0.01,Tabla_Americano!D305,""),"")
B33: 27 | C33: =IFERROR(IF(Tabla_Frances!C317>0.01,Tabla_Frances!D317,""),"") | D33: =IFERROR(IF(Tabla_Aleman!C317>0.01,Tabla_Aleman!D317,""),"") | E33: =IFERROR(IF(Tabla_Americano!C317>0.01,Tabla_Americano!D317,""),"")
B34: 28 | C34: =IFERROR(IF(Tabla_Frances!C329>0.01,Tabla_Frances!D329,""),"") | D34: =IFERROR(IF(Tabla_Aleman!C329>0.01,Tabla_Aleman!D329,""),"") | E34: =IFERROR(IF(Tabla_Americano!C329>0.01,Tabla_Americano!D329,""),"")
B35: 29 | C35: =IFERROR(IF(Tabla_Frances!C341>0.01,Tabla_Frances!D341,""),"") | D35: =IFERROR(IF(Tabla_Aleman!C341>0.01,Tabla_Aleman!D341,""),"") | E35: =IFERROR(IF(Tabla_Americano!C341>0.01,Tabla_Americano!D341,""),"")
B36: 30 | C36: =IFERROR(IF(Tabla_Frances!C353>0.01,Tabla_Frances!D353,""),"") | D36: =IFERROR(IF(Tabla_Aleman!C353>0.01,Tabla_Aleman!D353,""),"") | E36: =IFERROR(IF(Tabla_Americano!C353>0.01,Tabla_Americano!D353,""),"")
B55: SALDO PENDIENTE POR ANIO (Bs.)
B56: ANIO | C56: FRANCES | D56: ALEMAN | E56: AMERICANO
B57: 1 | C57: =IFERROR(Tabla_Frances!G16,"") | D57: =IFERROR(Tabla_Aleman!G16,"") | E57: =IFERROR(Tabla_Americano!G16,"")
B58: 2 | C58: =IFERROR(Tabla_Frances!G28,"") | D58: =IFERROR(Tabla_Aleman!G28,"") | E58: =IFERROR(Tabla_Americano!G28,"")
B59: 3 | C59: =IFERROR(Tabla_Frances!G40,"") | D59: =IFERROR(Tabla_Aleman!G40,"") | E59: =IFERROR(Tabla_Americano!G40,"")
B60: 4 | C60: =IFERROR(Tabla_Frances!G52,"") | D60: =IFERROR(Tabla_Aleman!G52,"") | E60: =IFERROR(Tabla_Americano!G52,"")
...

Sheet Config
A1: CONFIGURACION
A3: Producto | B3: Amortizador de Deudas PRO
A4: Version | B4: v1.0.0
A5: Marca | B5: No Somos Ignorantes
A6: Precio | B6: Bs. 69
A7: Metodos | B7: Frances, Aleman, Americano
A8: Max plazo | B8: 360 meses (30 anios)
A9: Proteccion | B9: nsi2024
A10: Contacto | B10: nosomosignorantes@gmail.com
A13: INSTRUCCIONES DE USO
A14: 1. En la hoja 'Calculadora' ingresa: capital, tasa anual, plazo y fecha de inicio.
A15: 2. La tabla de comparacion muestra los 3 metodos lado a lado automaticamente.
A16: 3. Revisa cada hoja de tabla (Frances, Aleman, Americano) para el detalle mes a mes.
A17: 4. La hoja 'Comparacion' muestra graficos de evolucion de cuotas y saldos.
A19: METODO FRANCES (el mas comun en Bolivia):
A20: - Cuota FIJA todos los meses.
A21: - Al inicio pagas mas interes, al final mas capital.
A22: - Ideal si quieres planificar un presupuesto fijo.
A24: METODO ALEMAN:
A25: - Amortizacion de capital FIJA (siempre pagas lo mismo de capital).
A26: - La cuota BAJA cada mes porque los intereses disminuyen.
... A33: - Pagas MAS intereses que cualquier otro metodo.
