Workbook

Sheet Dashboard
B2: BOLA DE NIEVE - ELIMINA TUS DEUDAS
B3: No Somos Ignorantes | v1.0 | El metodo mas poderoso para eliminar deudas
B5: RESUMEN DE TUS DEUDAS
B6: Total de deudas (Bs.) | C6: =Deudas!G3
B7: Numero de deudas activas | C7: =COUNTIF(Deudas!B7:B16,">0")
B8: Pago minimo total mensual (Bs.) | C8: =Deudas!G4
B9: Pago extra disponible (Bs.) | C9: =Deudas!G5
B10: Pago total mensual (Bs.) | C10: =Deudas!G4+Deudas!G5
B12: TIEMPO PARA LIBERTAD FINANCIERA
B13: Meses SIN bola de nieve | C13: =IFERROR(IF(Deudas!G4>0,ROUND(Deudas!G3/(Deudas!G4)*1.35,0),"--"),"--")
B14: Meses CON bola de nieve | C14: =IFERROR(IF(Deudas!G4+Deudas!G5>0,ROUND(Deudas!G3/(Deudas!G4+Deudas!G5)*1.1,0),"--"),"--")
B15: Meses que ahorras | C15: =IFERROR(IF(AND(ISNUMBER(C13),ISNUMBER(C14)),C13-C14,"--"),"--")
B17: AHORRO EN INTERESES
B18: Intereses SIN metodo (Bs.) | C18: =IFERROR(Deudas!G6,"--")
B19: Intereses CON bola de nieve (Bs.) | C19: =IFERROR(Deudas!G7,"--")
B20: TU AHORRO TOTAL (Bs.) | C20: =IFERROR(IF(AND(ISNUMBER(C18),ISNUMBER(C19)),C18-C19,"--"),"--")
B22: PROGRESO GENERAL
B23: Porcentaje completado | C23: =IFERROR(IF(Deudas!G3>0,Plan!B3/Deudas!G3,0),0)
B26: ORDEN DE PAGO BOLA DE NIEVE (menor saldo primero)
B27: ORDEN | C27: DEUDA | D27: SALDO (Bs.) | E27: PAGO MIN. (Bs.) | F27: ESTADO
B28: =IFERROR(IF(Deudas!B7>0,RANK(Deudas!B7,Deudas!$B$7:$B$16,1),""),"") | C28: =IF(Deudas!A7<>"",Deudas!A7,"") | D28: =IF(Deudas!B7>0,Deudas!B7,"") | E28: =IF(Deudas!D7>0,Deudas!D7,"") | F28: =IF(Deudas!A7="","",IF(Deudas!B7<=0,"PAGADA","Pendiente"))
B29: =IFERROR(IF(Deudas!B8>0,RANK(Deudas!B8,Deudas!$B$7:$B$16,1),""),"") | C29: =IF(Deudas!A8<>"",Deudas!A8,"") | D29: =IF(Deudas!B8>0,Deudas!B8,"") | E29: =IF(Deudas!D8>0,Deudas!D8,"") | F29: =IF(Deudas!A8="","",IF(Deudas!B8<=0,"PAGADA","Pendiente"))
B30: =IFERROR(IF(Deudas!B9>0,RANK(Deudas!B9,Deudas!$B$7:$B$16,1),""),"") | C30: =IF(Deudas!A9<>"",Deudas!A9,"") | D30: =IF(Deudas!B9>0,Deudas!B9,"") | E30: =IF(Deudas!D9>0,Deudas!D9,"") | F30: =IF(Deudas!A9="","",IF(Deudas!B9<=0,"PAGADA","Pendiente"))
B31: =IFERROR(IF(Deudas!B10>0,RANK(Deudas!B10,Deudas!$B$7:$B$16,1),""),"") | C31: =IF(Deudas!A10<>"",Deudas!A10,"") | D31: =IF(Deudas!B10>0,Deudas!B10,"") | E31: =IF(Deudas!D10>0,Deudas!D10,"") | F31: =IF(Deudas!A10="","",IF(Deudas!B10<=0,"PAGADA","Pendiente"))
B32: =IFERROR(IF(Deudas!B11>0,RANK(Deudas!B11,Deudas!$B$7:$B$16,1),""),"") | C32: =IF(Deudas!A11<>"",Deudas!A11,"") | D32: =IF(Deudas!B11>0,Deudas!B11,"") | E32: =IF(Deudas!D11>0,Deudas!D11,"") | F32: =IF(Deudas!A11="","",IF(Deudas!B11<=0,"PAGADA","Pendiente"))
B33: =IFERROR(IF(Deudas!B12>0,RANK(Deudas!B12,Deudas!$B$7:$B$16,1),""),"") | C33: =IF(Deudas!A12<>"",Deudas!A12,"") | D33: =IF(Deudas!B12>0,Deudas!B12,"") | E33: =IF(Deudas!D12>0,Deudas!D12,"") | F33: =IF(Deudas!A12="","",IF(Deudas!B12<=0,"PAGADA","Pendiente"))
B34: =IFERROR(IF(Deudas!B13>0,RANK(Deudas!B13,Deudas!$B$7:$B$16,1),""),"") | C34: =IF(Deudas!A13<>"",Deudas!A13,"") | D34: =IF(Deudas!B13>0,Deudas!B13,"") | E34: =IF(Deudas!D13>0,Deudas!D13,"") | F34: =IF(Deudas!A13="","",IF(Deudas!B13<=0,"PAGADA","Pendiente"))
B35: =IFERROR(IF(Deudas!B14>0,RANK(Deudas!B14,Deudas!$B$7:$B$16,1),""),"") | C35: =IF(Deudas!A14<>"",Deudas!A14,"") | D35: =IF(Deudas!B14>0,Deudas!B14,"") | E35: =IF(Deudas!D14>0,Deudas!D14,"") | F35: =IF(Deudas!A14="","",IF(Deudas!B14<=0,"PAGADA","Pendiente"))
B36: =IFERROR(IF(Deudas!B15>0,RANK(Deudas!B15,Deudas!$B$7:$B$16,1),""),"") | C36: =IF(Deudas!A15<>"",Deudas!A15,"") | D36: =IF(Deudas!B15>0,Deudas!B15,"") | E36: =IF(Deudas!D15>0,Deudas!D15,"") | F36: =IF(Deudas!A15="","",IF(Deudas!B15<=0,"PAGADA","Pendiente"))
B37: =IFERROR(IF(Deudas!B16>0,RANK(Deudas!B16,Deudas!$B$7:$B$16,1),""),"") | C37: =IF(Deudas!A16<>"",Deudas!A16,"") | D37: =IF(Deudas!B16>0,Deudas!B16,"") | E37: =IF(Deudas!D16>0,Deudas!D16,"") | F37: =IF(Deudas!A16="","",IF(Deudas!B16<=0,"PAGADA","Pendiente"))

Sheet Deudas
A1: REGISTRO DE DEUDAS
A2: Ingresa todas tus deudas. El sistema las ordenara automaticamente de menor a mayor saldo.
F3: Total Deuda: | G3: =SUM(B7:B16)
F4: Total Pago Min: | G4: =SUM(D7:D16)
F5: Pago Extra: | G5: 500
A6: NOMBRE DE LA DEUDA | B6: SALDO ACTUAL (Bs.) | C6: TASA ANUAL (%) | D6: PAGO MINIMO (Bs.) | E6: ORDEN BOLA DE NIEVE | F6: ESTADO | G6: =SUMPRODUCT(IFERROR((B7:B16*C7:C16/12)*IFERROR(NPER(C7:C16/12,-D7:D16,B7:B16),0),0))
A7: Tarjeta de credito Visa | B7: 3500 | C7: 0.45 | D7: 350 | E7: =IF(B7>0,RANK(B7,$B$7:$B$16,1),"") | F7: =IF(A7="","",IF(B7<=0,"PAGADA",IF(E7=1,"PAGANDO","Pendiente"))) | G7: =G6*0.65
A8: Prestamo personal BNB | B8: 8000 | C8: 0.18 | D8: 450 | E8: =IF(B8>0,RANK(B8,$B$7:$B$16,1),"") | F8: =IF(A8="","",IF(B8<=0,"PAGADA",IF(E8=1,"PAGANDO","Pendiente")))
A9: Tarjeta Mastercard | B9: 1200 | C9: 0.5 | D9: 200 | E9: =IF(B9>0,RANK(B9,$B$7:$B$16,1),"") | F9: =IF(A9="","",IF(B9<=0,"PAGADA",IF(E9=1,"PAGANDO","Pendiente")))
A10: Credito vehicular | B10: 25000 | C10: 0.12 | D10: 800 | E10: =IF(B10>0,RANK(B10,$B$7:$B$16,1),"") | F10: =IF(A10="","",IF(B10<=0,"PAGADA",IF(E10=1,"PAGANDO","Pendiente")))
A11: Prestamo familiar | B11: 2000 | C11: 0 | D11: 300 | E11: =IF(B11>0,RANK(B11,$B$7:$B$16,1),"") | F11: =IF(A11="","",IF(B11<=0,"PAGADA",IF(E11=1,"PAGANDO","Pendiente")))
E12: =IF(B12>0,RANK(B12,$B$7:$B$16,1),"") | F12: =IF(A12="","",IF(B12<=0,"PAGADA",IF(E12=1,"PAGANDO","Pendiente")))
E13: =IF(B13>0,RANK(B13,$B$7:$B$16,1),"") | F13: =IF(A13="","",IF(B13<=0,"PAGADA",IF(E13=1,"PAGANDO","Pendiente")))
E14: =IF(B14>0,RANK(B14,$B$7:$B$16,1),"") | F14: =IF(A14="","",IF(B14<=0,"PAGADA",IF(E14=1,"PAGANDO","Pendiente")))
E15: =IF(B15>0,RANK(B15,$B$7:$B$16,1),"") | F15: =IF(A15="","",IF(B15<=0,"PAGADA",IF(E15=1,"PAGANDO","Pendiente")))
E16: =IF(B16>0,RANK(B16,$B$7:$B$16,1),"") | F16: =IF(A16="","",IF(B16<=0,"PAGADA",IF(E16=1,"PAGANDO","Pendiente")))
A17: TOTALES | B17: =SUM(B7:B16) | C17: =IFERROR(SUMPRODUCT(B7:B16,C7:C16)/SUM(B7:B16),0) | D17: =SUM(D7:D16)
A19: METODO BOLA DE NIEVE: Paga el minimo en todas las deudas, y aplica TODO el extra a la deuda con menor saldo. Cuando esa se paga, su pago se suma al siguiente.

Sheet Plan
A1: PLAN DE PAGO MES A MES
A2: Deuda Inicial: | B2: =Deudas!G3
A3: Total Pagado: | B3: =IFERROR(SUM(C5:C64),0)
A4: MES | B4: SALDO INICIAL | C4: PAGO TOTAL | D4: A CAPITAL | E4: A INTERESES | F4: SALDO FINAL
A5: 1 | B5: =Deudas!G3 | C5: =IF(B5<=0,0,MIN(Deudas!G4+Deudas!G5, B5+E5)) | D5: =IF(B5<=0,0,C5-E5) | E5: =IF(B5<=0,0,ROUND(B5*Deudas!C17/12,2)) | F5: =IF(B5<=0,0,MAX(B5-D5,0))
A6: 2 | B6: =IF(F5<=0,0,F5) | C6: =IF(B6<=0,0,MIN(Deudas!G4+Deudas!G5, B6+E6)) | D6: =IF(B6<=0,0,C6-E6) | E6: =IF(B6<=0,0,ROUND(B6*Deudas!C17/12,2)) | F6: =IF(B6<=0,0,MAX(B6-D6,0))
A7: 3 | B7: =IF(F6<=0,0,F6) | C7: =IF(B7<=0,0,MIN(Deudas!G4+Deudas!G5, B7+E7)) | D7: =IF(B7<=0,0,C7-E7) | E7: =IF(B7<=0,0,ROUND(B7*Deudas!C17/12,2)) | F7: =IF(B7<=0,0,MAX(B7-D7,0))
A8: 4 | B8: =IF(F7<=0,0,F7) | C8: =IF(B8<=0,0,MIN(Deudas!G4+Deudas!G5, B8+E8)) | D8: =IF(B8<=0,0,C8-E8) | E8: =IF(B8<=0,0,ROUND(B8*Deudas!C17/12,2)) | F8: =IF(B8<=0,0,MAX(B8-D8,0))
A9: 5 | B9: =IF(F8<=0,0,F8) | C9: =IF(B9<=0,0,MIN(Deudas!G4+Deudas!G5, B9+E9)) | D9: =IF(B9<=0,0,C9-E9) | E9: =IF(B9<=0,0,ROUND(B9*Deudas!C17/12,2)) | F9: =IF(B9<=0,0,MAX(B9-D9,0))
A10: 6 | B10: =IF(F9<=0,0,F9) | C10: =IF(B10<=0,0,MIN(Deudas!G4+Deudas!G5, B10+E10)) | D10: =IF(B10<=0,0,C10-E10) | E10: =IF(B10<=0,0,ROUND(B10*Deudas!C17/12,2)) | F10: =IF(B10<=0,0,MAX(B10-D10,0))
A11: 7 | B11: =IF(F10<=0,0,F10) | C11: =IF(B11<=0,0,MIN(Deudas!G4+Deudas!G5, B11+E11)) | D11: =IF(B11<=0,0,C11-E11) | E11: =IF(B11<=0,0,ROUND(B11*Deudas!C17/12,2)) | F11: =IF(B11<=0,0,MAX(B11-D11,0))
A12: 8 | B12: =IF(F11<=0,0,F11) | C12: =IF(B12<=0,0,MIN(Deudas!G4+Deudas!G5, B12+E12)) | D12: =IF(B12<=0,0,C12-E12) | E12: =IF(B12<=0,0,ROUND(B12*Deudas!C17/12,2)) | F12: =IF(B12<=0,0,MAX(B12-D12,0))
A13: 9 | B13: =IF(F12<=0,0,F12) | C13: =IF(B13<=0,0,MIN(Deudas!G4+Deudas!G5, B13+E13)) | D13: =IF(B13<=0,0,C13-E13) | E13: =IF(B13<=0,0,ROUND(B13*Deudas!C17/12,2)) | F13: =IF(B13<=0,0,MAX(B13-D13,0))
A14: 10 | B14: =IF(F13<=0,0,F13) | C14: =IF(B14<=0,0,MIN(Deudas!G4+Deudas!G5, B14+E14)) | D14: =IF(B14<=0,0,C14-E14) | E14: =IF(B14<=0,0,ROUND(B14*Deudas!C17/12,2)) | F14: =IF(B14<=0,0,MAX(B14-D14,0))
A15: 11 | B15: =IF(F14<=0,0,F14) | C15: =IF(B15<=0,0,MIN(Deudas!G4+Deudas!G5, B15+E15)) | D15: =IF(B15<=0,0,C15-E15) | E15: =IF(B15<=0,0,ROUND(B15*Deudas!C17/12,2)) | F15: =IF(B15<=0,0,MAX(B15-D15,0))
A16: 12 | B16: =IF(F15<=0,0,F15) | C16: =IF(B16<=0,0,MIN(Deudas!G4+Deudas!G5, B16+E16)) | D16: =IF(B16<=0,0,C16-E16) | E16: =IF(B16<=0,0,ROUND(B16*Deudas!C17/12,2)) | F16: =IF(B16<=0,0,MAX(B16-D16,0))
A17: 13 | B17: =IF(F16<=0,0,F16) | C17: =IF(B17<=0,0,MIN(Deudas!G4+Deudas!G5, B17+E17)) | D17: =IF(B17<=0,0,C17-E17) | E17: =IF(B17<=0,0,ROUND(B17*Deudas!C17/12,2)) | F17: =IF(B17<=0,0,MAX(B17-D17,0))
A18: 14 | B18: =IF(F17<=0,0,F17) | C18: =IF(B18<=0,0,MIN(Deudas!G4+Deudas!G5, B18+E18)) | D18: =IF(B18<=0,0,C18-E18) | E18: =IF(B18<=0,0,ROUND(B18*Deudas!C17/12,2)) | F18: =IF(B18<=0,0,MAX(B18-D18,0))
A19: 15 | B19: =IF(F18<=0,0,F18) | C19: =IF(B19<=0,0,MIN(Deudas!G4+Deudas!G5, B19+E19)) | D19: =IF(B19<=0,0,C19-E19) | E19: =IF(B19<=0,0,ROUND(B19*Deudas!C17/12,2)) | F19: =IF(B19<=0,0,MAX(B19-D19,0))
A20: 16 | B20: =IF(F19<=0,0,F19) | C20: =IF(B20<=0,0,MIN(Deudas!G4+Deudas!G5, B20+E20)) | D20: =IF(B20<=0,0,C20-E20) | E20: =IF(B20<=0,0,ROUND(B20*Deudas!C17/12,2)) | F20: =IF(B20<=0,0,MAX(B20-D20,0))
A21: 17 | B21: =IF(F20<=0,0,F20) | C21: =IF(B21<=0,0,MIN(Deudas!G4+Deudas!G5, B21+E21)) | D21: =IF(B21<=0,0,C21-E21) | E21: =IF(B21<=0,0,ROUND(B21*Deudas!C17/12,2)) | F21: =IF(B21<=0,0,MAX(B21-D21,0))
A22: 18 | B22: =IF(F21<=0,0,F21) | C22: =IF(B22<=0,0,MIN(Deudas!G4+Deudas!G5, B22+E22)) | D22: =IF(B22<=0,0,C22-E22) | E22: =IF(B22<=0,0,ROUND(B22*Deudas!C17/12,2)) | F22: =IF(B22<=0,0,MAX(B22-D22,0))
A23: 19 | B23: =IF(F22<=0,0,F22) | C23: =IF(B23<=0,0,MIN(Deudas!G4+Deudas!G5, B23+E23)) | D23: =IF(B23<=0,0,C23-E23) | E23: =IF(B23<=0,0,ROUND(B23*Deudas!C17/12,2)) | F23: =IF(B23<=0,0,MAX(B23-D23,0))
A24: 20 | B24: =IF(F23<=0,0,F23) | C24: =IF(B24<=0,0,MIN(Deudas!G4+Deudas!G5, B24+E24)) | D24: =IF(B24<=0,0,C24-E24) | E24: =IF(B24<=0,0,ROUND(B24*Deudas!C17/12,2)) | F24: =IF(B24<=0,0,MAX(B24-D24,0))
A25: 21 | B25: =IF(F24<=0,0,F24) | C25: =IF(B25<=0,0,MIN(Deudas!G4+Deudas!G5, B25+E25)) | D25: =IF(B25<=0,0,C25-E25) | E25: =IF(B25<=0,0,ROUND(B25*Deudas!C17/12,2)) | F25: =IF(B25<=0,0,MAX(B25-D25,0))
A26: 22 | B26: =IF(F25<=0,0,F25) | C26: =IF(B26<=0,0,MIN(Deudas!G4+Deudas!G5, B26+E26)) | D26: =IF(B26<=0,0,C26-E26) | E26: =IF(B26<=0,0,ROUND(B26*Deudas!C17/12,2)) | F26: =IF(B26<=0,0,MAX(B26-D26,0))
A27: 23 | B27: =IF(F26<=0,0,F26) | C27: =IF(B27<=0,0,MIN(Deudas!G4+Deudas!G5, B27+E27)) | D27: =IF(B27<=0,0,C27-E27) | E27: =IF(B27<=0,0,ROUND(B27*Deudas!C17/12,2)) | F27: =IF(B27<=0,0,MAX(B27-D27,0))
A28: 24 | B28: =IF(F27<=0,0,F27) | C28: =IF(B28<=0,0,MIN(Deudas!G4+Deudas!G5, B28+E28)) | D28: =IF(B28<=0,0,C28-E28) | E28: =IF(B28<=0,0,ROUND(B28*Deudas!C17/12,2)) | F28: =IF(B28<=0,0,MAX(B28-D28,0))
A29: 25 | B29: =IF(F28<=0,0,F28) | C29: =IF(B29<=0,0,MIN(Deudas!G4+Deudas!G5, B29+E29)) | D29: =IF(B29<=0,0,C29-E29) | E29: =IF(B29<=0,0,ROUND(B29*Deudas!C17/12,2)) | F29: =IF(B29<=0,0,MAX(B29-D29,0))
A30: 26 | B30: =IF(F29<=0,0,F29) | C30: =IF(B30<=0,0,MIN(Deudas!G4+Deudas!G5, B30+E30)) | D30: =IF(B30<=0,0,C30-E30) | E30: =IF(B30<=0,0,ROUND(B30*Deudas!C17/12,2)) | F30: =IF(B30<=0,0,MAX(B30-D30,0))
A31: 27 | B31: =IF(F30<=0,0,F30) | C31: =IF(B31<=0,0,MIN(Deudas!G4+Deudas!G5, B31+E31)) | D31: =IF(B31<=0,0,C31-E31) | E31: =IF(B31<=0,0,ROUND(B31*Deudas!C17/12,2)) | F31: =IF(B31<=0,0,MAX(B31-D31,0))
A32: 28 | B32: =IF(F31<=0,0,F31) | C32: =IF(B32<=0,0,MIN(Deudas!G4+Deudas!G5, B32+E32)) | D32: =IF(B32<=0,0,C32-E32) | E32: =IF(B32<=0,0,ROUND(B32*Deudas!C17/12,2)) | F32: =IF(B32<=0,0,MAX(B32-D32,0))
A33: 29 | B33: =IF(F32<=0,0,F32) | C33: =IF(B33<=0,0,MIN(Deudas!G4+Deudas!G5, B33+E33)) | D33: =IF(B33<=0,0,C33-E33) | E33: =IF(B33<=0,0,ROUND(B33*Deudas!C17/12,2)) | F33: =IF(B33<=0,0,MAX(B33-D33,0))
A34: 30 | B34: =IF(F33<=0,0,F33) | C34: =IF(B34<=0,0,MIN(Deudas!G4+Deudas!G5, B34+E34)) | D34: =IF(B34<=0,0,C34-E34) | E34: =IF(B34<=0,0,ROUND(B34*Deudas!C17/12,2)) | F34: =IF(B34<=0,0,MAX(B34-D34,0))
A35: 31 | B35: =IF(F34<=0,0,F34) | C35: =IF(B35<=0,0,MIN(Deudas!G4+Deudas!G5, B35+E35)) | D35: =IF(B35<=0,0,C35-E35) | E35: =IF(B35<=0,0,ROUND(B35*Deudas!C17/12,2)) | F35: =IF(B35<=0,0,MAX(B35-D35,0))
A36: 32 | B36: =IF(F35<=0,0,F35) | C36: =IF(B36<=0,0,MIN(Deudas!G4+Deudas!G5, B36+E36)) | D36: =IF(B36<=0,0,C36-E36) | E36: =IF(B36<=0,0,ROUND(B36*Deudas!C17/12,2)) | F36: =IF(B36<=0,0,MAX(B36-D36,0))
A37: 33 | B37: =IF(F36<=0,0,F36) | C37: =IF(B37<=0,0,MIN(Deudas!G4+Deudas!G5, B37+E37)) | D37: =IF(B37<=0,0,C37-E37) | E37: =IF(B37<=0,0,ROUND(B37*Deudas!C17/12,2)) | F37: =IF(B37<=0,0,MAX(B37-D37,0))
A38: 34 | B38: =IF(F37<=0,0,F37) | C38: =IF(B38<=0,0,MIN(Deudas!G4+Deudas!G5, B38+E38)) | D38: =IF(B38<=0,0,C38-E38) | E38: =IF(B38<=0,0,ROUND(B38*Deudas!C17/12,2)) | F38: =IF(B38<=0,0,MAX(B38-D38,0))
A39: 35 | B39: =IF(F38<=0,0,F38) | C39: =IF(B39<=0,0,MIN(Deudas!G4+Deudas!G5, B39+E39)) | D39: =IF(B39<=0,0,C39-E39) | E39: =IF(B39<=0,0,ROUND(B39*Deudas!C17/12,2)) | F39: =IF(B39<=0,0,MAX(B39-D39,0))
A40: 36 | B40: =IF(F39<=0,0,F39) | C40: =IF(B40<=0,0,MIN(Deudas!G4+Deudas!G5, B40+E40)) | D40: =IF(B40<=0,0,C40-E40) | E40: =IF(B40<=0,0,ROUND(B40*Deudas!C17/12,2)) | F40: =IF(B40<=0,0,MAX(B40-D40,0))
...

Sheet Motivacion
B2: MOTIVACION Y PROGRESO
B3: Cada deuda pagada es una victoria. Celebra tu progreso!
B5: HITOS DE LIBERTAD FINANCIERA
B6: 25% de deuda eliminada | C6: =IF(Dashboard!C23>=0.25,"LOGRADO","Pendiente")
B7: 50% de deuda eliminada | C7: =IF(Dashboard!C23>=0.50,"LOGRADO","Pendiente")
B8: 75% de deuda eliminada | C8: =IF(Dashboard!C23>=0.75,"LOGRADO","Pendiente")
B9: Primera deuda PAGADA | C9: =IF(COUNTIF(Deudas!F7:F16,"PAGADA")>=1,"LOGRADO","Pendiente")
B10: 3 deudas PAGADAS | C10: =IF(COUNTIF(Deudas!F7:F16,"PAGADA")>=3,"LOGRADO","Pendiente")
B11: 100% LIBRE DE DEUDAS | C11: =IF(Dashboard!C23>=1.0,"LOGRADO","Pendiente")
B14: FRASES QUE TE IMPULSAN
B15: "El mejor momento para empezar a pagar tus deudas fue ayer. El segundo mejor momento es AHORA."
B16: "No se trata de cuanto ganas, sino de cuanto conservas y como lo pones a trabajar."
B17: "La bola de nieve no es solo un metodo, es una mentalidad de conquista."
B18: "Cada pago extra es un paso mas hacia tu libertad financiera."
B19: "Las deudas son cadenas invisibles. Rompe una y sentiras el poder de seguir."
B20: "La disciplina de hoy es la libertad de manana."
B23: REGISTRO DE VICTORIAS
B24: DEUDA PAGADA | C24: MONTO ELIMINADO | D24: FECHA | E24: COMO TE SIENTES?
B25: =IF(Deudas!F7="PAGADA",Deudas!A7,"") | C25: =IF(Deudas!F7="PAGADA",Deudas!B7,"")
B26: =IF(Deudas!F8="PAGADA",Deudas!A8,"") | C26: =IF(Deudas!F8="PAGADA",Deudas!B8,"")
B27: =IF(Deudas!F9="PAGADA",Deudas!A9,"") | C27: =IF(Deudas!F9="PAGADA",Deudas!B9,"")
B28: =IF(Deudas!F10="PAGADA",Deudas!A10,"") | C28: =IF(Deudas!F10="PAGADA",Deudas!B10,"")
B29: =IF(Deudas!F11="PAGADA",Deudas!A11,"") | C29: =IF(Deudas!F11="PAGADA",Deudas!B11,"")
B30: =IF(Deudas!F12="PAGADA",Deudas!A12,"") | C30: =IF(Deudas!F12="PAGADA",Deudas!B12,"")
B31: =IF(Deudas!F13="PAGADA",Deudas!A13,"") | C31: =IF(Deudas!F13="PAGADA",Deudas!B13,"")
B32: =IF(Deudas!F14="PAGADA",Deudas!A14,"") | C32: =IF(Deudas!F14="PAGADA",Deudas!B14,"")
B33: =IF(Deudas!F15="PAGADA",Deudas!A15,"") | C33: =IF(Deudas!F15="PAGADA",Deudas!B15,"")
B34: =IF(Deudas!F16="PAGADA",Deudas!A16,"") | C34: =IF(Deudas!F16="PAGADA",Deudas!B16,"")

Sheet Config
A1: CONFIGURACION
A3: Producto | B3: Bola de Nieve - Elimina tus Deudas
A4: Version | B4: v1.0.0
A5: Marca | B5: No Somos Ignorantes
A6: Precio | B6: Bs. 49
A7: Metodo | B7: Snowball (menor saldo primero)
A8: Proteccion | B8: nsi2024
A9: Maximo deudas | B9: 10
A10: Meses simulados | B10: 60
A11: Contacto | B11: nosomosignorantes@gmail.com
A14: INSTRUCCIONES DE USO
A15: 1. Ve a la hoja 'Deudas' e ingresa todas tus deudas actuales.
A16: 2. Para cada deuda ingresa: nombre, saldo actual, tasa anual y pago minimo.
A17: 3. En la celda G5 de 'Deudas', ingresa cuanto extra puedes pagar cada mes.
A18: 4. El sistema automaticamente ordena tus deudas de menor a mayor (bola de nieve).
A19: 5. Ve a la hoja 'Plan' para ver el calendario mes a mes de pagos.
A20: 6. La hoja 'Dashboard' muestra tu resumen, ahorro y progreso.
A21: 7. La hoja 'Motivacion' te ayuda a celebrar cada victoria.
A22: 8. A medida que pagas deudas, actualiza el saldo a 0 y registra la fecha.
A24: METODO BOLA DE NIEVE:
A25: - Paga el MINIMO en todas las deudas
A26: - Aplica TODO el dinero extra a la deuda con MENOR saldo
... A28: - Repite hasta ser LIBRE DE DEUDAS
