Workbook

Sheet Dashboard
B2: COMPARADOR DE CREDITOS HIPOTECARIOS
B3: No Somos Ignorantes | v1.0 | Encuentra el mejor credito para tu hogar
B5: DATOS DEL PRESTAMO
B6: MONTO DEL PRESTAMO (Bs.) | C6: 350000
B7: PLAZO DESEADO (meses) | C7: 240 | E7: =IFERROR(C7/12&" anios","")
B9: COMPARACION RAPIDA
B10: BANCO | C10: TASA ANUAL | D10: CUOTA MENSUAL | E10: TOTAL A PAGAR | F10: TOTAL INTERESES | G10: CAE | H10: DIFERENCIA
B11: =Banco1!C3 | C11: =Banco1!C5 | D11: =Banco1!C11 | E11: =Banco1!C12 | F11: =Banco1!C13 | G11: =Banco1!C14 | H11: =IFERROR(E11-MIN($E$11:$E$15),"")
B12: =Banco2!C3 | C12: =Banco2!C5 | D12: =Banco2!C11 | E12: =Banco2!C12 | F12: =Banco2!C13 | G12: =Banco2!C14 | H12: =IFERROR(E12-MIN($E$11:$E$15),"")
B13: =Banco3!C3 | C13: =Banco3!C5 | D13: =Banco3!C11 | E13: =Banco3!C12 | F13: =Banco3!C13 | G13: =Banco3!C14 | H13: =IFERROR(E13-MIN($E$11:$E$15),"")
B14: =Banco4!C3 | C14: =Banco4!C5 | D14: =Banco4!C11 | E14: =Banco4!C12 | F14: =Banco4!C13 | G14: =Banco4!C14 | H14: =IFERROR(E14-MIN($E$11:$E$15),"")
B15: =Banco5!C3 | C15: =Banco5!C5 | D15: =Banco5!C11 | E15: =Banco5!C12 | F15: =Banco5!C13 | G15: =Banco5!C14 | H15: =IFERROR(E15-MIN($E$11:$E$15),"")
B17: =IFERROR("MEJOR OPCION: "&INDEX(B11:B15,MATCH(MIN(E11:E15),E11:E15,0))&" - Ahorras Bs. "&TEXT(MAX(E11:E15)-MIN(E11:E15),"#,##0")&" vs la peor opcion","Ingresa datos en las hojas de bancos")
B19: METRICAS CLAVE
B20: Cuota mas baja (Bs.) | C20: =IFERROR(MIN(D11:D15),0)
B21: Cuota mas alta (Bs.) | C21: =IFERROR(MAX(D11:D15),0)
B22: Diferencia mensual (Bs.) | C22: =IFERROR(MAX(D11:D15)-MIN(D11:D15),0)
B23: Menor costo total (Bs.) | C23: =IFERROR(MIN(E11:E15),0)
B24: Mayor costo total (Bs.) | C24: =IFERROR(MAX(E11:E15),0)
B25: Ahorro maximo posible (Bs.) | C25: =IFERROR(MAX(E11:E15)-MIN(E11:E15),0)
B26: Tasa promedio (%) | C26: =IFERROR(AVERAGE(C11:C15),0)
B60: Banco | C60: Capital | D60: Intereses
B61: =B11 | C61: =C6 | D61: =F11
B62: =B12 | C62: =C6 | D62: =F12
B63: =B13 | C63: =C6 | D63: =F13
B64: =B14 | C64: =C6 | D64: =F14
B65: =B15 | C65: =C6 | D65: =F15

Sheet Banco1
B2: BANCO 1 - DATOS DEL CREDITO
B3: Nombre del Banco | C3: Banco Nacional de Bolivia
B5: Tasa de interes anual (%) | C5: 0.065
B6: Comision de apertura (%) | C6: 0.01
B7: Seguro de desgravamen anual (%) | C7: 0.0005
B8: Otros costos fijos (Bs.) | C8: 500
B10: RESULTADOS DEL CALCULO
B11: Cuota mensual (Bs.) | C11: =IFERROR(-PMT(C5/12,Dashboard!$C$7,Dashboard!$C$6)+(Dashboard!$C$6*C7/12),0)
B12: Total a pagar (Bs.) | C12: =IFERROR(C11*Dashboard!$C$7+C8+(Dashboard!$C$6*C6),0)
B13: Total intereses (Bs.) | C13: =IFERROR(C12-Dashboard!$C$6,0)
B14: CAE - Costo Anual Equivalente | C14: =IFERROR(((1+(C5/12+C7/12))^12-1)+C6/IFERROR(Dashboard!$C$7/12,1),0)
B15: Cuota/Ingreso recomendado (%) | C15: =IFERROR(IF(D15>0,C11/D15,0),0) | D15: 8000
B16: =IF(C15>0.35,"ALERTA: La cuota supera el 35% de tu ingreso. Riesgo alto.","OK: La cuota esta dentro del rango recomendado (<35%)")
B18: TABLA DE AMORTIZACION (primeros 12 meses)
B19: MES | C19: CUOTA (Bs.) | D19: A CAPITAL (Bs.) | E19: INTERES (Bs.) | F19: SALDO (Bs.)
B20: 1 | C20: =IFERROR(C11,0) | D20: =IFERROR(C20-E20,0) | E20: =IFERROR(ROUND(Dashboard!$C$6*C5/12,2),0) | F20: =IFERROR(Dashboard!$C$6-D20,0)
B21: 2 | C21: =IFERROR(C11,0) | D21: =IFERROR(C21-E21,0) | E21: =IFERROR(ROUND(F20*C5/12,2),0) | F21: =IFERROR(F20-D21,0)
B22: 3 | C22: =IFERROR(C11,0) | D22: =IFERROR(C22-E22,0) | E22: =IFERROR(ROUND(F21*C5/12,2),0) | F22: =IFERROR(F21-D22,0)
B23: 4 | C23: =IFERROR(C11,0) | D23: =IFERROR(C23-E23,0) | E23: =IFERROR(ROUND(F22*C5/12,2),0) | F23: =IFERROR(F22-D23,0)
B24: 5 | C24: =IFERROR(C11,0) | D24: =IFERROR(C24-E24,0) | E24: =IFERROR(ROUND(F23*C5/12,2),0) | F24: =IFERROR(F23-D24,0)
B25: 6 | C25: =IFERROR(C11,0) | D25: =IFERROR(C25-E25,0) | E25: =IFERROR(ROUND(F24*C5/12,2),0) | F25: =IFERROR(F24-D25,0)
B26: 7 | C26: =IFERROR(C11,0) | D26: =IFERROR(C26-E26,0) | E26: =IFERROR(ROUND(F25*C5/12,2),0) | F26: =IFERROR(F25-D26,0)
B27: 8 | C27: =IFERROR(C11,0) | D27: =IFERROR(C27-E27,0) | E27: =IFERROR(ROUND(F26*C5/12,2),0) | F27: =IFERROR(F26-D27,0)
B28: 9 | C28: =IFERROR(C11,0) | D28: =IFERROR(C28-E28,0) | E28: =IFERROR(ROUND(F27*C5/12,2),0) | F28: =IFERROR(F27-D28,0)
B29: 10 | C29: =IFERROR(C11,0) | D29: =IFERROR(C29-E29,0) | E29: =IFERROR(ROUND(F28*C5/12,2),0) | F29: =IFERROR(F28-D29,0)
B30: 11 | C30: =IFERROR(C11,0) | D30: =IFERROR(C30-E30,0) | E30: =IFERROR(ROUND(F29*C5/12,2),0) | F30: =IFERROR(F29-D30,0)
B31: 12 | C31: =IFERROR(C11,0) | D31: =IFERROR(C31-E31,0) | E31: =IFERROR(ROUND(F30*C5/12,2),0) | F31: =IFERROR(F30-D31,0)
B32: TOTAL 12 MESES | C32: =SUM(C20:C31) | D32: =SUM(D20:D31) | E32: =SUM(E20:E31) | F32: =F31

Sheet Banco2
B2: BANCO 2 - DATOS DEL CREDITO
B3: Nombre del Banco | C3: Banco Mercantil Santa Cruz
B5: Tasa de interes anual (%) | C5: 0.07
B6: Comision de apertura (%) | C6: 0.012
B7: Seguro de desgravamen anual (%) | C7: 0.0006
B8: Otros costos fijos (Bs.) | C8: 700
B10: RESULTADOS DEL CALCULO
B11: Cuota mensual (Bs.) | C11: =IFERROR(-PMT(C5/12,Dashboard!$C$7,Dashboard!$C$6)+(Dashboard!$C$6*C7/12),0)
B12: Total a pagar (Bs.) | C12: =IFERROR(C11*Dashboard!$C$7+C8+(Dashboard!$C$6*C6),0)
B13: Total intereses (Bs.) | C13: =IFERROR(C12-Dashboard!$C$6,0)
B14: CAE - Costo Anual Equivalente | C14: =IFERROR(((1+(C5/12+C7/12))^12-1)+C6/IFERROR(Dashboard!$C$7/12,1),0)
B15: Cuota/Ingreso recomendado (%) | C15: =IFERROR(IF(D15>0,C11/D15,0),0) | D15: 8500
B16: =IF(C15>0.35,"ALERTA: La cuota supera el 35% de tu ingreso. Riesgo alto.","OK: La cuota esta dentro del rango recomendado (<35%)")
B18: TABLA DE AMORTIZACION (primeros 12 meses)
B19: MES | C19: CUOTA (Bs.) | D19: A CAPITAL (Bs.) | E19: INTERES (Bs.) | F19: SALDO (Bs.)
B20: 1 | C20: =IFERROR(C11,0) | D20: =IFERROR(C20-E20,0) | E20: =IFERROR(ROUND(Dashboard!$C$6*C5/12,2),0) | F20: =IFERROR(Dashboard!$C$6-D20,0)
B21: 2 | C21: =IFERROR(C11,0) | D21: =IFERROR(C21-E21,0) | E21: =IFERROR(ROUND(F20*C5/12,2),0) | F21: =IFERROR(F20-D21,0)
B22: 3 | C22: =IFERROR(C11,0) | D22: =IFERROR(C22-E22,0) | E22: =IFERROR(ROUND(F21*C5/12,2),0) | F22: =IFERROR(F21-D22,0)
B23: 4 | C23: =IFERROR(C11,0) | D23: =IFERROR(C23-E23,0) | E23: =IFERROR(ROUND(F22*C5/12,2),0) | F23: =IFERROR(F22-D23,0)
B24: 5 | C24: =IFERROR(C11,0) | D24: =IFERROR(C24-E24,0) | E24: =IFERROR(ROUND(F23*C5/12,2),0) | F24: =IFERROR(F23-D24,0)
B25: 6 | C25: =IFERROR(C11,0) | D25: =IFERROR(C25-E25,0) | E25: =IFERROR(ROUND(F24*C5/12,2),0) | F25: =IFERROR(F24-D25,0)
B26: 7 | C26: =IFERROR(C11,0) | D26: =IFERROR(C26-E26,0) | E26: =IFERROR(ROUND(F25*C5/12,2),0) | F26: =IFERROR(F25-D26,0)
B27: 8 | C27: =IFERROR(C11,0) | D27: =IFERROR(C27-E27,0) | E27: =IFERROR(ROUND(F26*C5/12,2),0) | F27: =IFERROR(F26-D27,0)
B28: 9 | C28: =IFERROR(C11,0) | D28: =IFERROR(C28-E28,0) | E28: =IFERROR(ROUND(F27*C5/12,2),0) | F28: =IFERROR(F27-D28,0)
B29: 10 | C29: =IFERROR(C11,0) | D29: =IFERROR(C29-E29,0) | E29: =IFERROR(ROUND(F28*C5/12,2),0) | F29: =IFERROR(F28-D29,0)
B30: 11 | C30: =IFERROR(C11,0) | D30: =IFERROR(C30-E30,0) | E30: =IFERROR(ROUND(F29*C5/12,2),0) | F30: =IFERROR(F29-D30,0)
B31: 12 | C31: =IFERROR(C11,0) | D31: =IFERROR(C31-E31,0) | E31: =IFERROR(ROUND(F30*C5/12,2),0) | F31: =IFERROR(F30-D31,0)
B32: TOTAL 12 MESES | C32: =SUM(C20:C31) | D32: =SUM(D20:D31) | E32: =SUM(E20:E31) | F32: =F31

Sheet Banco3
B2: BANCO 3 - DATOS DEL CREDITO
B3: Nombre del Banco | C3: Banco Union
B5: Tasa de interes anual (%) | C5: 0.075
B6: Comision de apertura (%) | C6: 0.014
B7: Seguro de desgravamen anual (%) | C7: 0.0007
B8: Otros costos fijos (Bs.) | C8: 900
B10: RESULTADOS DEL CALCULO
B11: Cuota mensual (Bs.) | C11: =IFERROR(-PMT(C5/12,Dashboard!$C$7,Dashboard!$C$6)+(Dashboard!$C$6*C7/12),0)
B12: Total a pagar (Bs.) | C12: =IFERROR(C11*Dashboard!$C$7+C8+(Dashboard!$C$6*C6),0)
B13: Total intereses (Bs.) | C13: =IFERROR(C12-Dashboard!$C$6,0)
B14: CAE - Costo Anual Equivalente | C14: =IFERROR(((1+(C5/12+C7/12))^12-1)+C6/IFERROR(Dashboard!$C$7/12,1),0)
B15: Cuota/Ingreso recomendado (%) | C15: =IFERROR(IF(D15>0,C11/D15,0),0) | D15: 9000
B16: =IF(C15>0.35,"ALERTA: La cuota supera el 35% de tu ingreso. Riesgo alto.","OK: La cuota esta dentro del rango recomendado (<35%)")
B18: TABLA DE AMORTIZACION (primeros 12 meses)
B19: MES | C19: CUOTA (Bs.) | D19: A CAPITAL (Bs.) | E19: INTERES (Bs.) | F19: SALDO (Bs.)
B20: 1 | C20: =IFERROR(C11,0) | D20: =IFERROR(C20-E20,0) | E20: =IFERROR(ROUND(Dashboard!$C$6*C5/12,2),0) | F20: =IFERROR(Dashboard!$C$6-D20,0)
B21: 2 | C21: =IFERROR(C11,0) | D21: =IFERROR(C21-E21,0) | E21: =IFERROR(ROUND(F20*C5/12,2),0) | F21: =IFERROR(F20-D21,0)
B22: 3 | C22: =IFERROR(C11,0) | D22: =IFERROR(C22-E22,0) | E22: =IFERROR(ROUND(F21*C5/12,2),0) | F22: =IFERROR(F21-D22,0)
B23: 4 | C23: =IFERROR(C11,0) | D23: =IFERROR(C23-E23,0) | E23: =IFERROR(ROUND(F22*C5/12,2),0) | F23: =IFERROR(F22-D23,0)
B24: 5 | C24: =IFERROR(C11,0) | D24: =IFERROR(C24-E24,0) | E24: =IFERROR(ROUND(F23*C5/12,2),0) | F24: =IFERROR(F23-D24,0)
B25: 6 | C25: =IFERROR(C11,0) | D25: =IFERROR(C25-E25,0) | E25: =IFERROR(ROUND(F24*C5/12,2),0) | F25: =IFERROR(F24-D25,0)
B26: 7 | C26: =IFERROR(C11,0) | D26: =IFERROR(C26-E26,0) | E26: =IFERROR(ROUND(F25*C5/12,2),0) | F26: =IFERROR(F25-D26,0)
B27: 8 | C27: =IFERROR(C11,0) | D27: =IFERROR(C27-E27,0) | E27: =IFERROR(ROUND(F26*C5/12,2),0) | F27: =IFERROR(F26-D27,0)
B28: 9 | C28: =IFERROR(C11,0) | D28: =IFERROR(C28-E28,0) | E28: =IFERROR(ROUND(F27*C5/12,2),0) | F28: =IFERROR(F27-D28,0)
B29: 10 | C29: =IFERROR(C11,0) | D29: =IFERROR(C29-E29,0) | E29: =IFERROR(ROUND(F28*C5/12,2),0) | F29: =IFERROR(F28-D29,0)
B30: 11 | C30: =IFERROR(C11,0) | D30: =IFERROR(C30-E30,0) | E30: =IFERROR(ROUND(F29*C5/12,2),0) | F30: =IFERROR(F29-D30,0)
B31: 12 | C31: =IFERROR(C11,0) | D31: =IFERROR(C31-E31,0) | E31: =IFERROR(ROUND(F30*C5/12,2),0) | F31: =IFERROR(F30-D31,0)
B32: TOTAL 12 MESES | C32: =SUM(C20:C31) | D32: =SUM(D20:D31) | E32: =SUM(E20:E31) | F32: =F31

Sheet Banco4
B2: BANCO 4 - DATOS DEL CREDITO
B3: Nombre del Banco | C3: BancoSol
B5: Tasa de interes anual (%) | C5: 0.08
B6: Comision de apertura (%) | C6: 0.016
B7: Seguro de desgravamen anual (%) | C7: 0.0008
B8: Otros costos fijos (Bs.) | C8: 1100
B10: RESULTADOS DEL CALCULO
B11: Cuota mensual (Bs.) | C11: =IFERROR(-PMT(C5/12,Dashboard!$C$7,Dashboard!$C$6)+(Dashboard!$C$6*C7/12),0)
B12: Total a pagar (Bs.) | C12: =IFERROR(C11*Dashboard!$C$7+C8+(Dashboard!$C$6*C6),0)
B13: Total intereses (Bs.) | C13: =IFERROR(C12-Dashboard!$C$6,0)
B14: CAE - Costo Anual Equivalente | C14: =IFERROR(((1+(C5/12+C7/12))^12-1)+C6/IFERROR(Dashboard!$C$7/12,1),0)
B15: Cuota/Ingreso recomendado (%) | C15: =IFERROR(IF(D15>0,C11/D15,0),0) | D15: 9500
B16: =IF(C15>0.35,"ALERTA: La cuota supera el 35% de tu ingreso. Riesgo alto.","OK: La cuota esta dentro del rango recomendado (<35%)")
B18: TABLA DE AMORTIZACION (primeros 12 meses)
B19: MES | C19: CUOTA (Bs.) | D19: A CAPITAL (Bs.) | E19: INTERES (Bs.) | F19: SALDO (Bs.)
B20: 1 | C20: =IFERROR(C11,0) | D20: =IFERROR(C20-E20,0) | E20: =IFERROR(ROUND(Dashboard!$C$6*C5/12,2),0) | F20: =IFERROR(Dashboard!$C$6-D20,0)
B21: 2 | C21: =IFERROR(C11,0) | D21: =IFERROR(C21-E21,0) | E21: =IFERROR(ROUND(F20*C5/12,2),0) | F21: =IFERROR(F20-D21,0)
B22: 3 | C22: =IFERROR(C11,0) | D22: =IFERROR(C22-E22,0) | E22: =IFERROR(ROUND(F21*C5/12,2),0) | F22: =IFERROR(F21-D22,0)
B23: 4 | C23: =IFERROR(C11,0) | D23: =IFERROR(C23-E23,0) | E23: =IFERROR(ROUND(F22*C5/12,2),0) | F23: =IFERROR(F22-D23,0)
B24: 5 | C24: =IFERROR(C11,0) | D24: =IFERROR(C24-E24,0) | E24: =IFERROR(ROUND(F23*C5/12,2),0) | F24: =IFERROR(F23-D24,0)
B25: 6 | C25: =IFERROR(C11,0) | D25: =IFERROR(C25-E25,0) | E25: =IFERROR(ROUND(F24*C5/12,2),0) | F25: =IFERROR(F24-D25,0)
B26: 7 | C26: =IFERROR(C11,0) | D26: =IFERROR(C26-E26,0) | E26: =IFERROR(ROUND(F25*C5/12,2),0) | F26: =IFERROR(F25-D26,0)
B27: 8 | C27: =IFERROR(C11,0) | D27: =IFERROR(C27-E27,0) | E27: =IFERROR(ROUND(F26*C5/12,2),0) | F27: =IFERROR(F26-D27,0)
B28: 9 | C28: =IFERROR(C11,0) | D28: =IFERROR(C28-E28,0) | E28: =IFERROR(ROUND(F27*C5/12,2),0) | F28: =IFERROR(F27-D28,0)
B29: 10 | C29: =IFERROR(C11,0) | D29: =IFERROR(C29-E29,0) | E29: =IFERROR(ROUND(F28*C5/12,2),0) | F29: =IFERROR(F28-D29,0)
B30: 11 | C30: =IFERROR(C11,0) | D30: =IFERROR(C30-E30,0) | E30: =IFERROR(ROUND(F29*C5/12,2),0) | F30: =IFERROR(F29-D30,0)
B31: 12 | C31: =IFERROR(C11,0) | D31: =IFERROR(C31-E31,0) | E31: =IFERROR(ROUND(F30*C5/12,2),0) | F31: =IFERROR(F30-D31,0)
B32: TOTAL 12 MESES | C32: =SUM(C20:C31) | D32: =SUM(D20:D31) | E32: =SUM(E20:E31) | F32: =F31

Sheet Banco5
B2: BANCO 5 - DATOS DEL CREDITO
B3: Nombre del Banco | C3: Banco BISA
B5: Tasa de interes anual (%) | C5: 0.085
B6: Comision de apertura (%) | C6: 0.018
B7: Seguro de desgravamen anual (%) | C7: 0.0009
B8: Otros costos fijos (Bs.) | C8: 1300
B10: RESULTADOS DEL CALCULO
B11: Cuota mensual (Bs.) | C11: =IFERROR(-PMT(C5/12,Dashboard!$C$7,Dashboard!$C$6)+(Dashboard!$C$6*C7/12),0)
B12: Total a pagar (Bs.) | C12: =IFERROR(C11*Dashboard!$C$7+C8+(Dashboard!$C$6*C6),0)
B13: Total intereses (Bs.) | C13: =IFERROR(C12-Dashboard!$C$6,0)
B14: CAE - Costo Anual Equivalente | C14: =IFERROR(((1+(C5/12+C7/12))^12-1)+C6/IFERROR(Dashboard!$C$7/12,1),0)
B15: Cuota/Ingreso recomendado (%) | C15: =IFERROR(IF(D15>0,C11/D15,0),0) | D15: 10000
B16: =IF(C15>0.35,"ALERTA: La cuota supera el 35% de tu ingreso. Riesgo alto.","OK: La cuota esta dentro del rango recomendado (<35%)")
B18: TABLA DE AMORTIZACION (primeros 12 meses)
B19: MES | C19: CUOTA (Bs.) | D19: A CAPITAL (Bs.) | E19: INTERES (Bs.) | F19: SALDO (Bs.)
B20: 1 | C20: =IFERROR(C11,0) | D20: =IFERROR(C20-E20,0) | E20: =IFERROR(ROUND(Dashboard!$C$6*C5/12,2),0) | F20: =IFERROR(Dashboard!$C$6-D20,0)
B21: 2 | C21: =IFERROR(C11,0) | D21: =IFERROR(C21-E21,0) | E21: =IFERROR(ROUND(F20*C5/12,2),0) | F21: =IFERROR(F20-D21,0)
B22: 3 | C22: =IFERROR(C11,0) | D22: =IFERROR(C22-E22,0) | E22: =IFERROR(ROUND(F21*C5/12,2),0) | F22: =IFERROR(F21-D22,0)
B23: 4 | C23: =IFERROR(C11,0) | D23: =IFERROR(C23-E23,0) | E23: =IFERROR(ROUND(F22*C5/12,2),0) | F23: =IFERROR(F22-D23,0)
B24: 5 | C24: =IFERROR(C11,0) | D24: =IFERROR(C24-E24,0) | E24: =IFERROR(ROUND(F23*C5/12,2),0) | F24: =IFERROR(F23-D24,0)
B25: 6 | C25: =IFERROR(C11,0) | D25: =IFERROR(C25-E25,0) | E25: =IFERROR(ROUND(F24*C5/12,2),0) | F25: =IFERROR(F24-D25,0)
B26: 7 | C26: =IFERROR(C11,0) | D26: =IFERROR(C26-E26,0) | E26: =IFERROR(ROUND(F25*C5/12,2),0) | F26: =IFERROR(F25-D26,0)
B27: 8 | C27: =IFERROR(C11,0) | D27: =IFERROR(C27-E27,0) | E27: =IFERROR(ROUND(F26*C5/12,2),0) | F27: =IFERROR(F26-D27,0)
B28: 9 | C28: =IFERROR(C11,0) | D28: =IFERROR(C28-E28,0) | E28: =IFERROR(ROUND(F27*C5/12,2),0) | F28: =IFERROR(F27-D28,0)
B29: 10 | C29: =IFERROR(C11,0) | D29: =IFERROR(C29-E29,0) | E29: =IFERROR(ROUND(F28*C5/12,2),0) | F29: =IFERROR(F28-D29,0)
B30: 11 | C30: =IFERROR(C11,0) | D30: =IFERROR(C30-E30,0) | E30: =IFERROR(ROUND(F29*C5/12,2),0) | F30: =IFERROR(F29-D30,0)
B31: 12 | C31: =IFERROR(C11,0) | D31: =IFERROR(C31-E31,0) | E31: =IFERROR(ROUND(F30*C5/12,2),0) | F31: =IFERROR(F30-D31,0)
B32: TOTAL 12 MESES | C32: =SUM(C20:C31) | D32: =SUM(D20:D31) | E32: =SUM(E20:E31) | F32: =F31

Sheet Amortizacion
A1: TABLA DE AMORTIZACION COMPLETA
A2: Amortizacion Frances (cuota fija) - Selecciona el banco a analizar
A3: Selecciona Banco: | B3: 1 | C3: Banco: | D3: =IFERROR(CHOOSE(B3,Banco1!C3,Banco2!C3,Banco3!C3,Banco4!C3,Banco5!C3),"") | E3: Tasa: | F3: =IFERROR(CHOOSE(B3,Banco1!C5,Banco2!C5,Banco3!C5,Banco4!C5,Banco5!C5),"")
A5: MES | B5: SALDO INICIAL | C5: CUOTA | D5: A CAPITAL | E5: A INTERESES | F5: SALDO FINAL | G5: % PAGADO
A6: 1 | B6: =Dashboard!C6 | C6: =IF(B6<=0.01,0,IFERROR(-PMT(CHOOSE($B$3,Banco1!$C$5,Banco2!$C$5,Banco3!$C$5,Banco4!$C$5,Banco5!$C$5)/12,Dashboard!$C$7,Dashboard!$C$6),0)) | D6: =IF(B6<=0.01,0,MIN(C6-E6,B6)) | E6: =IF(B6<=0.01,0,ROUND(B6*CHOOSE($B$3,Banco1!$C$5,Banco2!$C$5,Banco3!$C$5,Banco4!$C$5,Banco5!$C$5)/12,2)) | F6: =IF(B6<=0.01,0,MAX(B6-D6,0)) | G6: =IFERROR(IF(Dashboard!C6>0,1-(F6/Dashboard!C6),0),0)
A7: 2 | B7: =IF(F6<=0.01,0,F6) | C7: =IF(B7<=0.01,0,IFERROR(-PMT(CHOOSE($B$3,Banco1!$C$5,Banco2!$C$5,Banco3!$C$5,Banco4!$C$5,Banco5!$C$5)/12,Dashboard!$C$7,Dashboard!$C$6),0)) | D7: =IF(B7<=0.01,0,MIN(C7-E7,B7)) | E7: =IF(B7<=0.01,0,ROUND(B7*CHOOSE($B$3,Banco1!$C$5,Banco2!$C$5,Banco3!$C$5,Banco4!$C$5,Banco5!$C$5)/12,2)) | F7: =IF(B7<=0.01,0,MAX(B7-D7,0)) | G7: =IFERROR(IF(Dashboard!C6>0,1-(F7/Dashboard!C6),0),0)
A8: 3 | B8: =IF(F7<=0.01,0,F7) | C8: =IF(B8<=0.01,0,IFERROR(-PMT(CHOOSE($B$3,Banco1!$C$5,Banco2!$C$5,Banco3!$C$5,Banco4!$C$5,Banco5!$C$5)/12,Dashboard!$C$7,Dashboard!$C$6),0)) | D8: =IF(B8<=0.01,0,MIN(C8-E8,B8)) | E8: =IF(B8<=0.01,0,ROUND(B8*CHOOSE($B$3,Banco1!$C$5,Banco2!$C$5,Banco3!$C$5,Banco4!$C$5,Banco5!$C$5)/12,2)) | F8: =IF(B8<=0.01,0,MAX(B8-D8,0)) | G8: =IFERROR(IF(Dashboard!C6>0,1-(F8/Dashboard!C6),0),0)
A9: 4 | B9: =IF(F8<=0.01,0,F8) | C9: =IF(B9<=0.01,0,IFERROR(-PMT(CHOOSE($B$3,Banco1!$C$5,Banco2!$C$5,Banco3!$C$5,Banco4!$C$5,Banco5!$C$5)/12,Dashboard!$C$7,Dashboard!$C$6),0)) | D9: =IF(B9<=0.01,0,MIN(C9-E9,B9)) | E9: =IF(B9<=0.01,0,ROUND(B9*CHOOSE($B$3,Banco1!$C$5,Banco2!$C$5,Banco3!$C$5,Banco4!$C$5,Banco5!$C$5)/12,2)) | F9: =IF(B9<=0.01,0,MAX(B9-D9,0)) | G9: =IFERROR(IF(Dashboard!C6>0,1-(F9/Dashboard!C6),0),0)
A10: 5 | B10: =IF(F9<=0.01,0,F9) | C10: =IF(B10<=0.01,0,IFERROR(-PMT(CHOOSE($B$3,Banco1!$C$5,Banco2!$C$5,Banco3!$C$5,Banco4!$C$5,Banco5!$C$5)/12,Dashboard!$C$7,Dashboard!$C$6),0)) | D10: =IF(B10<=0.01,0,MIN(C10-E10,B10)) | E10: =IF(B10<=0.01,0,ROUND(B10*CHOOSE($B$3,Banco1!$C$5,Banco2!$C$5,Banco3!$C$5,Banco4!$C$5,Banco5!$C$5)/12,2)) | F10: =IF(B10<=0.01,0,MAX(B10-D10,0)) | G10: =IFERROR(IF(Dashboard!C6>0,1-(F10/Dashboard!C6),0),0)
A11: 6 | B11: =IF(F10<=0.01,0,F10) | C11: =IF(B11<=0.01,0,IFERROR(-PMT(CHOOSE($B$3,Banco1!$C$5,Banco2!$C$5,Banco3!$C$5,Banco4!$C$5,Banco5!$C$5)/12,Dashboard!$C$7,Dashboard!$C$6),0)) | D11: =IF(B11<=0.01,0,MIN(C11-E11,B11)) | E11: =IF(B11<=0.01,0,ROUND(B11*CHOOSE($B$3,Banco1!$C$5,Banco2!$C$5,Banco3!$C$5,Banco4!$C$5,Banco5!$C$5)/12,2)) | F11: =IF(B11<=0.01,0,MAX(B11-D11,0)) | G11: =IFERROR(IF(Dashboard!C6>0,1-(F11/Dashboard!C6),0),0)
A12: 7 | B12: =IF(F11<=0.01,0,F11) | C12: =IF(B12<=0.01,0,IFERROR(-PMT(CHOOSE($B$3,Banco1!$C$5,Banco2!$C$5,Banco3!$C$5,Banco4!$C$5,Banco5!$C$5)/12,Dashboard!$C$7,Dashboard!$C$6),0)) | D12: =IF(B12<=0.01,0,MIN(C12-E12,B12)) | E12: =IF(B12<=0.01,0,ROUND(B12*CHOOSE($B$3,Banco1!$C$5,Banco2!$C$5,Banco3!$C$5,Banco4!$C$5,Banco5!$C$5)/12,2)) | F12: =IF(B12<=0.01,0,MAX(B12-D12,0)) | G12: =IFERROR(IF(Dashboard!C6>0,1-(F12/Dashboard!C6),0),0)
A13: 8 | B13: =IF(F12<=0.01,0,F12) | C13: =IF(B13<=0.01,0,IFERROR(-PMT(CHOOSE($B$3,Banco1!$C$5,Banco2!$C$5,Banco3!$C$5,Banco4!$C$5,Banco5!$C$5)/12,Dashboard!$C$7,Dashboard!$C$6),0)) | D13: =IF(B13<=0.01,0,MIN(C13-E13,B13)) | E13: =IF(B13<=0.01,0,ROUND(B13*CHOOSE($B$3,Banco1!$C$5,Banco2!$C$5,Banco3!$C$5,Banco4!$C$5,Banco5!$C$5)/12,2)) | F13: =IF(B13<=0.01,0,MAX(B13-D13,0)) | G13: =IFERROR(IF(Dashboard!C6>0,1-(F13/Dashboard!C6),0),0)
A14: 9 | B14: =IF(F13<=0.01,0,F13) | C14: =IF(B14<=0.01,0,IFERROR(-PMT(CHOOSE($B$3,Banco1!$C$5,Banco2!$C$5,Banco3!$C$5,Banco4!$C$5,Banco5!$C$5)/12,Dashboard!$C$7,Dashboard!$C$6),0)) | D14: =IF(B14<=0.01,0,MIN(C14-E14,B14)) | E14: =IF(B14<=0.01,0,ROUND(B14*CHOOSE($B$3,Banco1!$C$5,Banco2!$C$5,Banco3!$C$5,Banco4!$C$5,Banco5!$C$5)/12,2)) | F14: =IF(B14<=0.01,0,MAX(B14-D14,0)) | G14: =IFERROR(IF(Dashboard!C6>0,1-(F14/Dashboard!C6),0),0)
A15: 10 | B15: =IF(F14<=0.01,0,F14) | C15: =IF(B15<=0.01,0,IFERROR(-PMT(CHOOSE($B$3,Banco1!$C$5,Banco2!$C$5,Banco3!$C$5,Banco4!$C$5,Banco5!$C$5)/12,Dashboard!$C$7,Dashboard!$C$6),0)) | D15: =IF(B15<=0.01,0,MIN(C15-E15,B15)) | E15: =IF(B15<=0.01,0,ROUND(B15*CHOOSE($B$3,Banco1!$C$5,Banco2!$C$5,Banco3!$C$5,Banco4!$C$5,Banco5!$C$5)/12,2)) | F15: =IF(B15<=0.01,0,MAX(B15-D15,0)) | G15: =IFERROR(IF(Dashboard!C6>0,1-(F15/Dashboard!C6),0),0)
A16: 11 | B16: =IF(F15<=0.01,0,F15) | C16: =IF(B16<=0.01,0,IFERROR(-PMT(CHOOSE($B$3,Banco1!$C$5,Banco2!$C$5,Banco3!$C$5,Banco4!$C$5,Banco5!$C$5)/12,Dashboard!$C$7,Dashboard!$C$6),0)) | D16: =IF(B16<=0.01,0,MIN(C16-E16,B16)) | E16: =IF(B16<=0.01,0,ROUND(B16*CHOOSE($B$3,Banco1!$C$5,Banco2!$C$5,Banco3!$C$5,Banco4!$C$5,Banco5!$C$5)/12,2)) | F16: =IF(B16<=0.01,0,MAX(B16-D16,0)) | G16: =IFERROR(IF(Dashboard!C6>0,1-(F16/Dashboard!C6),0),0)
A17: 12 | B17: =IF(F16<=0.01,0,F16) | C17: =IF(B17<=0.01,0,IFERROR(-PMT(CHOOSE($B$3,Banco1!$C$5,Banco2!$C$5,Banco3!$C$5,Banco4!$C$5,Banco5!$C$5)/12,Dashboard!$C$7,Dashboard!$C$6),0)) | D17: =IF(B17<=0.01,0,MIN(C17-E17,B17)) | E17: =IF(B17<=0.01,0,ROUND(B17*CHOOSE($B$3,Banco1!$C$5,Banco2!$C$5,Banco3!$C$5,Banco4!$C$5,Banco5!$C$5)/12,2)) | F17: =IF(B17<=0.01,0,MAX(B17-D17,0)) | G17: =IFERROR(IF(Dashboard!C6>0,1-(F17/Dashboard!C6),0),0)
A18: 13 | B18: =IF(F17<=0.01,0,F17) | C18: =IF(B18<=0.01,0,IFERROR(-PMT(CHOOSE($B$3,Banco1!$C$5,Banco2!$C$5,Banco3!$C$5,Banco4!$C$5,Banco5!$C$5)/12,Dashboard!$C$7,Dashboard!$C$6),0)) | D18: =IF(B18<=0.01,0,MIN(C18-E18,B18)) | E18: =IF(B18<=0.01,0,ROUND(B18*CHOOSE($B$3,Banco1!$C$5,Banco2!$C$5,Banco3!$C$5,Banco4!$C$5,Banco5!$C$5)/12,2)) | F18: =IF(B18<=0.01,0,MAX(B18-D18,0)) | G18: =IFERROR(IF(Dashboard!C6>0,1-(F18/Dashboard!C6),0),0)
A19: 14 | B19: =IF(F18<=0.01,0,F18) | C19: =IF(B19<=0.01,0,IFERROR(-PMT(CHOOSE($B$3,Banco1!$C$5,Banco2!$C$5,Banco3!$C$5,Banco4!$C$5,Banco5!$C$5)/12,Dashboard!$C$7,Dashboard!$C$6),0)) | D19: =IF(B19<=0.01,0,MIN(C19-E19,B19)) | E19: =IF(B19<=0.01,0,ROUND(B19*CHOOSE($B$3,Banco1!$C$5,Banco2!$C$5,Banco3!$C$5,Banco4!$C$5,Banco5!$C$5)/12,2)) | F19: =IF(B19<=0.01,0,MAX(B19-D19,0)) | G19: =IFERROR(IF(Dashboard!C6>0,1-(F19/Dashboard!C6),0),0)
A20: 15 | B20: =IF(F19<=0.01,0,F19) | C20: =IF(B20<=0.01,0,IFERROR(-PMT(CHOOSE($B$3,Banco1!$C$5,Banco2!$C$5,Banco3!$C$5,Banco4!$C$5,Banco5!$C$5)/12,Dashboard!$C$7,Dashboard!$C$6),0)) | D20: =IF(B20<=0.01,0,MIN(C20-E20,B20)) | E20: =IF(B20<=0.01,0,ROUND(B20*CHOOSE($B$3,Banco1!$C$5,Banco2!$C$5,Banco3!$C$5,Banco4!$C$5,Banco5!$C$5)/12,2)) | F20: =IF(B20<=0.01,0,MAX(B20-D20,0)) | G20: =IFERROR(IF(Dashboard!C6>0,1-(F20/Dashboard!C6),0),0)
A21: 16 | B21: =IF(F20<=0.01,0,F20) | C21: =IF(B21<=0.01,0,IFERROR(-PMT(CHOOSE($B$3,Banco1!$C$5,Banco2!$C$5,Banco3!$C$5,Banco4!$C$5,Banco5!$C$5)/12,Dashboard!$C$7,Dashboard!$C$6),0)) | D21: =IF(B21<=0.01,0,MIN(C21-E21,B21)) | E21: =IF(B21<=0.01,0,ROUND(B21*CHOOSE($B$3,Banco1!$C$5,Banco2!$C$5,Banco3!$C$5,Banco4!$C$5,Banco5!$C$5)/12,2)) | F21: =IF(B21<=0.01,0,MAX(B21-D21,0)) | G21: =IFERROR(IF(Dashboard!C6>0,1-(F21/Dashboard!C6),0),0)
A22: 17 | B22: =IF(F21<=0.01,0,F21) | C22: =IF(B22<=0.01,0,IFERROR(-PMT(CHOOSE($B$3,Banco1!$C$5,Banco2!$C$5,Banco3!$C$5,Banco4!$C$5,Banco5!$C$5)/12,Dashboard!$C$7,Dashboard!$C$6),0)) | D22: =IF(B22<=0.01,0,MIN(C22-E22,B22)) | E22: =IF(B22<=0.01,0,ROUND(B22*CHOOSE($B$3,Banco1!$C$5,Banco2!$C$5,Banco3!$C$5,Banco4!$C$5,Banco5!$C$5)/12,2)) | F22: =IF(B22<=0.01,0,MAX(B22-D22,0)) | G22: =IFERROR(IF(Dashboard!C6>0,1-(F22/Dashboard!C6),0),0)
A23: 18 | B23: =IF(F22<=0.01,0,F22) | C23: =IF(B23<=0.01,0,IFERROR(-PMT(CHOOSE($B$3,Banco1!$C$5,Banco2!$C$5,Banco3!$C$5,Banco4!$C$5,Banco5!$C$5)/12,Dashboard!$C$7,Dashboard!$C$6),0)) | D23: =IF(B23<=0.01,0,MIN(C23-E23,B23)) | E23: =IF(B23<=0.01,0,ROUND(B23*CHOOSE($B$3,Banco1!$C$5,Banco2!$C$5,Banco3!$C$5,Banco4!$C$5,Banco5!$C$5)/12,2)) | F23: =IF(B23<=0.01,0,MAX(B23-D23,0)) | G23: =IFERROR(IF(Dashboard!C6>0,1-(F23/Dashboard!C6),0),0)
A24: 19 | B24: =IF(F23<=0.01,0,F23) | C24: =IF(B24<=0.01,0,IFERROR(-PMT(CHOOSE($B$3,Banco1!$C$5,Banco2!$C$5,Banco3!$C$5,Banco4!$C$5,Banco5!$C$5)/12,Dashboard!$C$7,Dashboard!$C$6),0)) | D24: =IF(B24<=0.01,0,MIN(C24-E24,B24)) | E24: =IF(B24<=0.01,0,ROUND(B24*CHOOSE($B$3,Banco1!$C$5,Banco2!$C$5,Banco3!$C$5,Banco4!$C$5,Banco5!$C$5)/12,2)) | F24: =IF(B24<=0.01,0,MAX(B24-D24,0)) | G24: =IFERROR(IF(Dashboard!C6>0,1-(F24/Dashboard!C6),0),0)
A25: 20 | B25: =IF(F24<=0.01,0,F24) | C25: =IF(B25<=0.01,0,IFERROR(-PMT(CHOOSE($B$3,Banco1!$C$5,Banco2!$C$5,Banco3!$C$5,Banco4!$C$5,Banco5!$C$5)/12,Dashboard!$C$7,Dashboard!$C$6),0)) | D25: =IF(B25<=0.01,0,MIN(C25-E25,B25)) | E25: =IF(B25<=0.01,0,ROUND(B25*CHOOSE($B$3,Banco1!$C$5,Banco2!$C$5,Banco3!$C$5,Banco4!$C$5,Banco5!$C$5)/12,2)) | F25: =IF(B25<=0.01,0,MAX(B25-D25,0)) | G25: =IFERROR(IF(Dashboard!C6>0,1-(F25/Dashboard!C6),0),0)
A26: 21 | B26: =IF(F25<=0.01,0,F25) | C26: =IF(B26<=0.01,0,IFERROR(-PMT(CHOOSE($B$3,Banco1!$C$5,Banco2!$C$5,Banco3!$C$5,Banco4!$C$5,Banco5!$C$5)/12,Dashboard!$C$7,Dashboard!$C$6),0)) | D26: =IF(B26<=0.01,0,MIN(C26-E26,B26)) | E26: =IF(B26<=0.01,0,ROUND(B26*CHOOSE($B$3,Banco1!$C$5,Banco2!$C$5,Banco3!$C$5,Banco4!$C$5,Banco5!$C$5)/12,2)) | F26: =IF(B26<=0.01,0,MAX(B26-D26,0)) | G26: =IFERROR(IF(Dashboard!C6>0,1-(F26/Dashboard!C6),0),0)
A27: 22 | B27: =IF(F26<=0.01,0,F26) | C27: =IF(B27<=0.01,0,IFERROR(-PMT(CHOOSE($B$3,Banco1!$C$5,Banco2!$C$5,Banco3!$C$5,Banco4!$C$5,Banco5!$C$5)/12,Dashboard!$C$7,Dashboard!$C$6),0)) | D27: =IF(B27<=0.01,0,MIN(C27-E27,B27)) | E27: =IF(B27<=0.01,0,ROUND(B27*CHOOSE($B$3,Banco1!$C$5,Banco2!$C$5,Banco3!$C$5,Banco4!$C$5,Banco5!$C$5)/12,2)) | F27: =IF(B27<=0.01,0,MAX(B27-D27,0)) | G27: =IFERROR(IF(Dashboard!C6>0,1-(F27/Dashboard!C6),0),0)
A28: 23 | B28: =IF(F27<=0.01,0,F27) | C28: =IF(B28<=0.01,0,IFERROR(-PMT(CHOOSE($B$3,Banco1!$C$5,Banco2!$C$5,Banco3!$C$5,Banco4!$C$5,Banco5!$C$5)/12,Dashboard!$C$7,Dashboard!$C$6),0)) | D28: =IF(B28<=0.01,0,MIN(C28-E28,B28)) | E28: =IF(B28<=0.01,0,ROUND(B28*CHOOSE($B$3,Banco1!$C$5,Banco2!$C$5,Banco3!$C$5,Banco4!$C$5,Banco5!$C$5)/12,2)) | F28: =IF(B28<=0.01,0,MAX(B28-D28,0)) | G28: =IFERROR(IF(Dashboard!C6>0,1-(F28/Dashboard!C6),0),0)
A29: 24 | B29: =IF(F28<=0.01,0,F28) | C29: =IF(B29<=0.01,0,IFERROR(-PMT(CHOOSE($B$3,Banco1!$C$5,Banco2!$C$5,Banco3!$C$5,Banco4!$C$5,Banco5!$C$5)/12,Dashboard!$C$7,Dashboard!$C$6),0)) | D29: =IF(B29<=0.01,0,MIN(C29-E29,B29)) | E29: =IF(B29<=0.01,0,ROUND(B29*CHOOSE($B$3,Banco1!$C$5,Banco2!$C$5,Banco3!$C$5,Banco4!$C$5,Banco5!$C$5)/12,2)) | F29: =IF(B29<=0.01,0,MAX(B29-D29,0)) | G29: =IFERROR(IF(Dashboard!C6>0,1-(F29/Dashboard!C6),0),0)
A30: 25 | B30: =IF(F29<=0.01,0,F29) | C30: =IF(B30<=0.01,0,IFERROR(-PMT(CHOOSE($B$3,Banco1!$C$5,Banco2!$C$5,Banco3!$C$5,Banco4!$C$5,Banco5!$C$5)/12,Dashboard!$C$7,Dashboard!$C$6),0)) | D30: =IF(B30<=0.01,0,MIN(C30-E30,B30)) | E30: =IF(B30<=0.01,0,ROUND(B30*CHOOSE($B$3,Banco1!$C$5,Banco2!$C$5,Banco3!$C$5,Banco4!$C$5,Banco5!$C$5)/12,2)) | F30: =IF(B30<=0.01,0,MAX(B30-D30,0)) | G30: =IFERROR(IF(Dashboard!C6>0,1-(F30/Dashboard!C6),0),0)
A31: 26 | B31: =IF(F30<=0.01,0,F30) | C31: =IF(B31<=0.01,0,IFERROR(-PMT(CHOOSE($B$3,Banco1!$C$5,Banco2!$C$5,Banco3!$C$5,Banco4!$C$5,Banco5!$C$5)/12,Dashboard!$C$7,Dashboard!$C$6),0)) | D31: =IF(B31<=0.01,0,MIN(C31-E31,B31)) | E31: =IF(B31<=0.01,0,ROUND(B31*CHOOSE($B$3,Banco1!$C$5,Banco2!$C$5,Banco3!$C$5,Banco4!$C$5,Banco5!$C$5)/12,2)) | F31: =IF(B31<=0.01,0,MAX(B31-D31,0)) | G31: =IFERROR(IF(Dashboard!C6>0,1-(F31/Dashboard!C6),0),0)
A32: 27 | B32: =IF(F31<=0.01,0,F31) | C32: =IF(B32<=0.01,0,IFERROR(-PMT(CHOOSE($B$3,Banco1!$C$5,Banco2!$C$5,Banco3!$C$5,Banco4!$C$5,Banco5!$C$5)/12,Dashboard!$C$7,Dashboard!$C$6),0)) | D32: =IF(B32<=0.01,0,MIN(C32-E32,B32)) | E32: =IF(B32<=0.01,0,ROUND(B32*CHOOSE($B$3,Banco1!$C$5,Banco2!$C$5,Banco3!$C$5,Banco4!$C$5,Banco5!$C$5)/12,2)) | F32: =IF(B32<=0.01,0,MAX(B32-D32,0)) | G32: =IFERROR(IF(Dashboard!C6>0,1-(F32/Dashboard!C6),0),0)
A33: 28 | B33: =IF(F32<=0.01,0,F32) | C33: =IF(B33<=0.01,0,IFERROR(-PMT(CHOOSE($B$3,Banco1!$C$5,Banco2!$C$5,Banco3!$C$5,Banco4!$C$5,Banco5!$C$5)/12,Dashboard!$C$7,Dashboard!$C$6),0)) | D33: =IF(B33<=0.01,0,MIN(C33-E33,B33)) | E33: =IF(B33<=0.01,0,ROUND(B33*CHOOSE($B$3,Banco1!$C$5,Banco2!$C$5,Banco3!$C$5,Banco4!$C$5,Banco5!$C$5)/12,2)) | F33: =IF(B33<=0.01,0,MAX(B33-D33,0)) | G33: =IFERROR(IF(Dashboard!C6>0,1-(F33/Dashboard!C6),0),0)
A34: 29 | B34: =IF(F33<=0.01,0,F33) | C34: =IF(B34<=0.01,0,IFERROR(-PMT(CHOOSE($B$3,Banco1!$C$5,Banco2!$C$5,Banco3!$C$5,Banco4!$C$5,Banco5!$C$5)/12,Dashboard!$C$7,Dashboard!$C$6),0)) | D34: =IF(B34<=0.01,0,MIN(C34-E34,B34)) | E34: =IF(B34<=0.01,0,ROUND(B34*CHOOSE($B$3,Banco1!$C$5,Banco2!$C$5,Banco3!$C$5,Banco4!$C$5,Banco5!$C$5)/12,2)) | F34: =IF(B34<=0.01,0,MAX(B34-D34,0)) | G34: =IFERROR(IF(Dashboard!C6>0,1-(F34/Dashboard!C6),0),0)
A35: 30 | B35: =IF(F34<=0.01,0,F34) | C35: =IF(B35<=0.01,0,IFERROR(-PMT(CHOOSE($B$3,Banco1!$C$5,Banco2!$C$5,Banco3!$C$5,Banco4!$C$5,Banco5!$C$5)/12,Dashboard!$C$7,Dashboard!$C$6),0)) | D35: =IF(B35<=0.01,0,MIN(C35-E35,B35)) | E35: =IF(B35<=0.01,0,ROUND(B35*CHOOSE($B$3,Banco1!$C$5,Banco2!$C$5,Banco3!$C$5,Banco4!$C$5,Banco5!$C$5)/12,2)) | F35: =IF(B35<=0.01,0,MAX(B35-D35,0)) | G35: =IFERROR(IF(Dashboard!C6>0,1-(F35/Dashboard!C6),0),0)
A36: 31 | B36: =IF(F35<=0.01,0,F35) | C36: =IF(B36<=0.01,0,IFERROR(-PMT(CHOOSE($B$3,Banco1!$C$5,Banco2!$C$5,Banco3!$C$5,Banco4!$C$5,Banco5!$C$5)/12,Dashboard!$C$7,Dashboard!$C$6),0)) | D36: =IF(B36<=0.01,0,MIN(C36-E36,B36)) | E36: =IF(B36<=0.01,0,ROUND(B36*CHOOSE($B$3,Banco1!$C$5,Banco2!$C$5,Banco3!$C$5,Banco4!$C$5,Banco5!$C$5)/12,2)) | F36: =IF(B36<=0.01,0,MAX(B36-D36,0)) | G36: =IFERROR(IF(Dashboard!C6>0,1-(F36/Dashboard!C6),0),0)
A37: 32 | B37: =IF(F36<=0.01,0,F36) | C37: =IF(B37<=0.01,0,IFERROR(-PMT(CHOOSE($B$3,Banco1!$C$5,Banco2!$C$5,Banco3!$C$5,Banco4!$C$5,Banco5!$C$5)/12,Dashboard!$C$7,Dashboard!$C$6),0)) | D37: =IF(B37<=0.01,0,MIN(C37-E37,B37)) | E37: =IF(B37<=0.01,0,ROUND(B37*CHOOSE($B$3,Banco1!$C$5,Banco2!$C$5,Banco3!$C$5,Banco4!$C$5,Banco5!$C$5)/12,2)) | F37: =IF(B37<=0.01,0,MAX(B37-D37,0)) | G37: =IFERROR(IF(Dashboard!C6>0,1-(F37/Dashboard!C6),0),0)
A38: 33 | B38: =IF(F37<=0.01,0,F37) | C38: =IF(B38<=0.01,0,IFERROR(-PMT(CHOOSE($B$3,Banco1!$C$5,Banco2!$C$5,Banco3!$C$5,Banco4!$C$5,Banco5!$C$5)/12,Dashboard!$C$7,Dashboard!$C$6),0)) | D38: =IF(B38<=0.01,0,MIN(C38-E38,B38)) | E38: =IF(B38<=0.01,0,ROUND(B38*CHOOSE($B$3,Banco1!$C$5,Banco2!$C$5,Banco3!$C$5,Banco4!$C$5,Banco5!$C$5)/12,2)) | F38: =IF(B38<=0.01,0,MAX(B38-D38,0)) | G38: =IFERROR(IF(Dashboard!C6>0,1-(F38/Dashboard!C6),0),0)
A39: 34 | B39: =IF(F38<=0.01,0,F38) | C39: =IF(B39<=0.01,0,IFERROR(-PMT(CHOOSE($B$3,Banco1!$C$5,Banco2!$C$5,Banco3!$C$5,Banco4!$C$5,Banco5!$C$5)/12,Dashboard!$C$7,Dashboard!$C$6),0)) | D39: =IF(B39<=0.01,0,MIN(C39-E39,B39)) | E39: =IF(B39<=0.01,0,ROUND(B39*CHOOSE($B$3,Banco1!$C$5,Banco2!$C$5,Banco3!$C$5,Banco4!$C$5,Banco5!$C$5)/12,2)) | F39: =IF(B39<=0.01,0,MAX(B39-D39,0)) | G39: =IFERROR(IF(Dashboard!C6>0,1-(F39/Dashboard!C6),0),0)
A40: 35 | B40: =IF(F39<=0.01,0,F39) | C40: =IF(B40<=0.01,0,IFERROR(-PMT(CHOOSE($B$3,Banco1!$C$5,Banco2!$C$5,Banco3!$C$5,Banco4!$C$5,Banco5!$C$5)/12,Dashboard!$C$7,Dashboard!$C$6),0)) | D40: =IF(B40<=0.01,0,MIN(C40-E40,B40)) | E40: =IF(B40<=0.01,0,ROUND(B40*CHOOSE($B$3,Banco1!$C$5,Banco2!$C$5,Banco3!$C$5,Banco4!$C$5,Banco5!$C$5)/12,2)) | F40: =IF(B40<=0.01,0,MAX(B40-D40,0)) | G40: =IFERROR(IF(Dashboard!C6>0,1-(F40/Dashboard!C6),0),0)
A41: 36 | B41: =IF(F40<=0.01,0,F40) | C41: =IF(B41<=0.01,0,IFERROR(-PMT(CHOOSE($B$3,Banco1!$C$5,Banco2!$C$5,Banco3!$C$5,Banco4!$C$5,Banco5!$C$5)/12,Dashboard!$C$7,Dashboard!$C$6),0)) | D41: =IF(B41<=0.01,0,MIN(C41-E41,B41)) | E41: =IF(B41<=0.01,0,ROUND(B41*CHOOSE($B$3,Banco1!$C$5,Banco2!$C$5,Banco3!$C$5,Banco4!$C$5,Banco5!$C$5)/12,2)) | F41: =IF(B41<=0.01,0,MAX(B41-D41,0)) | G41: =IFERROR(IF(Dashboard!C6>0,1-(F41/Dashboard!C6),0),0)
...

Sheet Sensibilidad
B1: ANALISIS DE SENSIBILIDAD
B2: Que pasa si cambia la tasa o el plazo? Analiza diferentes escenarios
B4: CUOTA MENSUAL (Bs.) segun Tasa y Plazo
B5: TASA \ PLAZO | C5: 10 anios | D5: 15 anios | E5: 20 anios | F5: 25 anios | G5: 30 anios
B6: 0.05 | C6: =IFERROR(-PMT($B6/12,120,Dashboard!$C$6),0) | D6: =IFERROR(-PMT($B6/12,180,Dashboard!$C$6),0) | E6: =IFERROR(-PMT($B6/12,240,Dashboard!$C$6),0) | F6: =IFERROR(-PMT($B6/12,300,Dashboard!$C$6),0) | G6: =IFERROR(-PMT($B6/12,360,Dashboard!$C$6),0)
B7: 0.06 | C7: =IFERROR(-PMT($B7/12,120,Dashboard!$C$6),0) | D7: =IFERROR(-PMT($B7/12,180,Dashboard!$C$6),0) | E7: =IFERROR(-PMT($B7/12,240,Dashboard!$C$6),0) | F7: =IFERROR(-PMT($B7/12,300,Dashboard!$C$6),0) | G7: =IFERROR(-PMT($B7/12,360,Dashboard!$C$6),0)
B8: 0.065 | C8: =IFERROR(-PMT($B8/12,120,Dashboard!$C$6),0) | D8: =IFERROR(-PMT($B8/12,180,Dashboard!$C$6),0) | E8: =IFERROR(-PMT($B8/12,240,Dashboard!$C$6),0) | F8: =IFERROR(-PMT($B8/12,300,Dashboard!$C$6),0) | G8: =IFERROR(-PMT($B8/12,360,Dashboard!$C$6),0)
B9: 0.07 | C9: =IFERROR(-PMT($B9/12,120,Dashboard!$C$6),0) | D9: =IFERROR(-PMT($B9/12,180,Dashboard!$C$6),0) | E9: =IFERROR(-PMT($B9/12,240,Dashboard!$C$6),0) | F9: =IFERROR(-PMT($B9/12,300,Dashboard!$C$6),0) | G9: =IFERROR(-PMT($B9/12,360,Dashboard!$C$6),0)
B10: 0.08 | C10: =IFERROR(-PMT($B10/12,120,Dashboard!$C$6),0) | D10: =IFERROR(-PMT($B10/12,180,Dashboard!$C$6),0) | E10: =IFERROR(-PMT($B10/12,240,Dashboard!$C$6),0) | F10: =IFERROR(-PMT($B10/12,300,Dashboard!$C$6),0) | G10: =IFERROR(-PMT($B10/12,360,Dashboard!$C$6),0)
B11: 0.09 | C11: =IFERROR(-PMT($B11/12,120,Dashboard!$C$6),0) | D11: =IFERROR(-PMT($B11/12,180,Dashboard!$C$6),0) | E11: =IFERROR(-PMT($B11/12,240,Dashboard!$C$6),0) | F11: =IFERROR(-PMT($B11/12,300,Dashboard!$C$6),0) | G11: =IFERROR(-PMT($B11/12,360,Dashboard!$C$6),0)
B12: 0.1 | C12: =IFERROR(-PMT($B12/12,120,Dashboard!$C$6),0) | D12: =IFERROR(-PMT($B12/12,180,Dashboard!$C$6),0) | E12: =IFERROR(-PMT($B12/12,240,Dashboard!$C$6),0) | F12: =IFERROR(-PMT($B12/12,300,Dashboard!$C$6),0) | G12: =IFERROR(-PMT($B12/12,360,Dashboard!$C$6),0)
B13: 0.12 | C13: =IFERROR(-PMT($B13/12,120,Dashboard!$C$6),0) | D13: =IFERROR(-PMT($B13/12,180,Dashboard!$C$6),0) | E13: =IFERROR(-PMT($B13/12,240,Dashboard!$C$6),0) | F13: =IFERROR(-PMT($B13/12,300,Dashboard!$C$6),0) | G13: =IFERROR(-PMT($B13/12,360,Dashboard!$C$6),0)
B15: TOTAL INTERESES (Bs.) segun Tasa y Plazo
B16: TASA \ PLAZO | C16: 10 anios | D16: 15 anios | E16: 20 anios | F16: 25 anios | G16: 30 anios
B17: 0.05 | C17: =IFERROR(-PMT($B17/12,120,Dashboard!$C$6)*120-Dashboard!$C$6,0) | D17: =IFERROR(-PMT($B17/12,180,Dashboard!$C$6)*180-Dashboard!$C$6,0) | E17: =IFERROR(-PMT($B17/12,240,Dashboard!$C$6)*240-Dashboard!$C$6,0) | F17: =IFERROR(-PMT($B17/12,300,Dashboard!$C$6)*300-Dashboard!$C$6,0) | G17: =IFERROR(-PMT($B17/12,360,Dashboard!$C$6)*360-Dashboard!$C$6,0)
B18: 0.06 | C18: =IFERROR(-PMT($B18/12,120,Dashboard!$C$6)*120-Dashboard!$C$6,0) | D18: =IFERROR(-PMT($B18/12,180,Dashboard!$C$6)*180-Dashboard!$C$6,0) | E18: =IFERROR(-PMT($B18/12,240,Dashboard!$C$6)*240-Dashboard!$C$6,0) | F18: =IFERROR(-PMT($B18/12,300,Dashboard!$C$6)*300-Dashboard!$C$6,0) | G18: =IFERROR(-PMT($B18/12,360,Dashboard!$C$6)*360-Dashboard!$C$6,0)
B19: 0.065 | C19: =IFERROR(-PMT($B19/12,120,Dashboard!$C$6)*120-Dashboard!$C$6,0) | D19: =IFERROR(-PMT($B19/12,180,Dashboard!$C$6)*180-Dashboard!$C$6,0) | E19: =IFERROR(-PMT($B19/12,240,Dashboard!$C$6)*240-Dashboard!$C$6,0) | F19: =IFERROR(-PMT($B19/12,300,Dashboard!$C$6)*300-Dashboard!$C$6,0) | G19: =IFERROR(-PMT($B19/12,360,Dashboard!$C$6)*360-Dashboard!$C$6,0)
B20: 0.07 | C20: =IFERROR(-PMT($B20/12,120,Dashboard!$C$6)*120-Dashboard!$C$6,0) | D20: =IFERROR(-PMT($B20/12,180,Dashboard!$C$6)*180-Dashboard!$C$6,0) | E20: =IFERROR(-PMT($B20/12,240,Dashboard!$C$6)*240-Dashboard!$C$6,0) | F20: =IFERROR(-PMT($B20/12,300,Dashboard!$C$6)*300-Dashboard!$C$6,0) | G20: =IFERROR(-PMT($B20/12,360,Dashboard!$C$6)*360-Dashboard!$C$6,0)
B21: 0.08 | C21: =IFERROR(-PMT($B21/12,120,Dashboard!$C$6)*120-Dashboard!$C$6,0) | D21: =IFERROR(-PMT($B21/12,180,Dashboard!$C$6)*180-Dashboard!$C$6,0) | E21: =IFERROR(-PMT($B21/12,240,Dashboard!$C$6)*240-Dashboard!$C$6,0) | F21: =IFERROR(-PMT($B21/12,300,Dashboard!$C$6)*300-Dashboard!$C$6,0) | G21: =IFERROR(-PMT($B21/12,360,Dashboard!$C$6)*360-Dashboard!$C$6,0)
B22: 0.09 | C22: =IFERROR(-PMT($B22/12,120,Dashboard!$C$6)*120-Dashboard!$C$6,0) | D22: =IFERROR(-PMT($B22/12,180,Dashboard!$C$6)*180-Dashboard!$C$6,0) | E22: =IFERROR(-PMT($B22/12,240,Dashboard!$C$6)*240-Dashboard!$C$6,0) | F22: =IFERROR(-PMT($B22/12,300,Dashboard!$C$6)*300-Dashboard!$C$6,0) | G22: =IFERROR(-PMT($B22/12,360,Dashboard!$C$6)*360-Dashboard!$C$6,0)
B23: 0.1 | C23: =IFERROR(-PMT($B23/12,120,Dashboard!$C$6)*120-Dashboard!$C$6,0) | D23: =IFERROR(-PMT($B23/12,180,Dashboard!$C$6)*180-Dashboard!$C$6,0) | E23: =IFERROR(-PMT($B23/12,240,Dashboard!$C$6)*240-Dashboard!$C$6,0) | F23: =IFERROR(-PMT($B23/12,300,Dashboard!$C$6)*300-Dashboard!$C$6,0) | G23: =IFERROR(-PMT($B23/12,360,Dashboard!$C$6)*360-Dashboard!$C$6,0)
B24: 0.12 | C24: =IFERROR(-PMT($B24/12,120,Dashboard!$C$6)*120-Dashboard!$C$6,0) | D24: =IFERROR(-PMT($B24/12,180,Dashboard!$C$6)*180-Dashboard!$C$6,0) | E24: =IFERROR(-PMT($B24/12,240,Dashboard!$C$6)*240-Dashboard!$C$6,0) | F24: =IFERROR(-PMT($B24/12,300,Dashboard!$C$6)*300-Dashboard!$C$6,0) | G24: =IFERROR(-PMT($B24/12,360,Dashboard!$C$6)*360-Dashboard!$C$6,0)
B26: CALCULADORA DE PREPAGO
B27: Pago extra mensual (Bs.) | C27: 1000
B28: Meses que ahorras | C28: =IFERROR(Dashboard!C7-C30,0)
B29: Interes que ahorras (Bs.) | C29: =IFERROR((CHOOSE(Amortizacion!$B$3,Banco1!$C$11,Banco2!$C$11,Banco3!$C$11,Banco4!$C$11,Banco5!$C$11)*Dashboard!C7-Dashboard!C6)-((CHOOSE(Amortizacion!$B$3,Banco1!$C$11,Banco2!$C$11,Banco3!$C$11,Banco4!$C$11,Banco5!$C$11)+C27)*C30-Dashboard!C6),0)
B30: Nuevo plazo total (meses) | C30: =IFERROR(ROUND(NPER(CHOOSE(Amortizacion!$B$3,Banco1!$C$5,Banco2!$C$5,Banco3!$C$5,Banco4!$C$5,Banco5!$C$5)/12,-(CHOOSE(Amortizacion!$B$3,Banco1!$C$11,Banco2!$C$11,Banco3!$C$11,Banco4!$C$11,Banco5!$C$11)+C27),Dashboard!$C$6),0),0)
C50: 120 | D50: 180 | E50: 240 | F50: 300 | G50: 360

Sheet Config
A1: CONFIGURACION
A3: Producto | B3: Comparador de Creditos Hipotecarios
A4: Version | B4: v1.0.0
A5: Marca | B5: No Somos Ignorantes
A6: Precio | B6: Bs. 49
A7: Max bancos | B7: 5
A8: Max plazo | B8: 360 meses (30 anios)
A9: Metodo amortizacion | B9: Frances (cuota fija)
A10: Proteccion | B10: nsi2024
A11: Contacto | B11: nosomosignorantes@gmail.com
A14: INSTRUCCIONES DE USO
A15: 1. En el Dashboard ingresa el monto del prestamo y el plazo deseado en meses.
A16: 2. Ve a cada hoja de banco (Banco1-Banco5) e ingresa los datos de la oferta.
A17: 3. Para cada banco ingresa: nombre, tasa anual, comision, seguro y otros costos.
A18: 4. Regresa al Dashboard para ver la comparacion automatica.
A19: 5. El sistema destaca el banco con menor costo total en verde.
A20: 6. Ve a 'Amortizacion' para ver la tabla mes a mes del banco que elijas.
A21: 7. Usa 'Sensibilidad' para analizar que pasa si cambian tasas o plazos.
A22: 8. La calculadora de prepago muestra cuanto ahorras pagando extra.
A24: TIPS:
A25: - Pide a cada banco su tasa efectiva anual, no solo la nominal.
A26: - Incluye TODOS los costos: comision, seguros, gastos notariales.
... A28: - La regla de oro: la cuota no debe superar el 35% de tu ingreso.
