Workbook

Sheet Dashboard
B2: CONTROL DE GASTOS OPERATIVOS
B3: No Somos Ignorantes | v1.0 | Resumen del periodo actual
B4: Ano: | C4: 2025
B6: GASTOS DEL MES ACTUAL (Bs.) | F6: GASTOS ACUMULADOS ANO (Bs.)
B7: =IFERROR(SUMPRODUCT((MONTH(Gastos!A4:A503)=MONTH(TODAY()))*(YEAR(Gastos!A4:A503)=YEAR(TODAY()))*Gastos!D4:D503),0) | F7: =IFERROR(SUMPRODUCT((YEAR(Gastos!A4:A503)=C4)*Gastos!D4:D503),0)
B8: Presupuesto mes: | C8: =IFERROR(INDEX(Presupuesto!C18:N18,1,MONTH(TODAY())),0) | F8: Presupuesto anual: | G8: =IFERROR(Presupuesto!O18,0)
B9: Desviacion: | C9: =IFERROR(B7-C8,0) | F9: % ejecutado: | G9: =IFERROR(F7/G8,0)
B11: PROMEDIO MENSUAL (Bs.) | F11: CATEGORIA MAYOR GASTO
B12: =IFERROR(F7/MONTH(TODAY()),0) | F12: =IFERROR(INDEX(Gastos!C4:C503,MATCH(MAX(Gastos!D4:D503),Gastos!D4:D503,0)),"--")
B14: TENDENCIA MENSUAL | F14: GASTOS POR CATEGORIA
B15: Mes | C15: Gasto Real | D15: Presupuesto | F15: Categoria | G15: Total (Bs.)
B16: Ene | C16: =IFERROR(SUMPRODUCT((MONTH(Gastos!A4:A503)=1)*(YEAR(Gastos!A4:A503)=C4)*Gastos!D4:D503),0) | D16: =IFERROR(Presupuesto!C18,0) | F16: Alquiler | G16: =IFERROR(SUMPRODUCT((Gastos!C4:C503=F16)*(YEAR(Gastos!A4:A503)=C4)*Gastos!D4:D503),0)
B17: Feb | C17: =IFERROR(SUMPRODUCT((MONTH(Gastos!A4:A503)=2)*(YEAR(Gastos!A4:A503)=C4)*Gastos!D4:D503),0) | D17: =IFERROR(Presupuesto!D18,0) | F17: Servicios (luz/agua/gas) | G17: =IFERROR(SUMPRODUCT((Gastos!C4:C503=F17)*(YEAR(Gastos!A4:A503)=C4)*Gastos!D4:D503),0)
B18: Mar | C18: =IFERROR(SUMPRODUCT((MONTH(Gastos!A4:A503)=3)*(YEAR(Gastos!A4:A503)=C4)*Gastos!D4:D503),0) | D18: =IFERROR(Presupuesto!E18,0) | F18: Internet/Telefono | G18: =IFERROR(SUMPRODUCT((Gastos!C4:C503=F18)*(YEAR(Gastos!A4:A503)=C4)*Gastos!D4:D503),0)
B19: Abr | C19: =IFERROR(SUMPRODUCT((MONTH(Gastos!A4:A503)=4)*(YEAR(Gastos!A4:A503)=C4)*Gastos!D4:D503),0) | D19: =IFERROR(Presupuesto!F18,0) | F19: Sueldos y Salarios | G19: =IFERROR(SUMPRODUCT((Gastos!C4:C503=F19)*(YEAR(Gastos!A4:A503)=C4)*Gastos!D4:D503),0)
B20: May | C20: =IFERROR(SUMPRODUCT((MONTH(Gastos!A4:A503)=5)*(YEAR(Gastos!A4:A503)=C4)*Gastos!D4:D503),0) | D20: =IFERROR(Presupuesto!G18,0) | F20: Seguro Social | G20: =IFERROR(SUMPRODUCT((Gastos!C4:C503=F20)*(YEAR(Gastos!A4:A503)=C4)*Gastos!D4:D503),0)
B21: Jun | C21: =IFERROR(SUMPRODUCT((MONTH(Gastos!A4:A503)=6)*(YEAR(Gastos!A4:A503)=C4)*Gastos!D4:D503),0) | D21: =IFERROR(Presupuesto!H18,0) | F21: Material de Oficina | G21: =IFERROR(SUMPRODUCT((Gastos!C4:C503=F21)*(YEAR(Gastos!A4:A503)=C4)*Gastos!D4:D503),0)
B22: Jul | C22: =IFERROR(SUMPRODUCT((MONTH(Gastos!A4:A503)=7)*(YEAR(Gastos!A4:A503)=C4)*Gastos!D4:D503),0) | D22: =IFERROR(Presupuesto!I18,0) | F22: Publicidad/Marketing | G22: =IFERROR(SUMPRODUCT((Gastos!C4:C503=F22)*(YEAR(Gastos!A4:A503)=C4)*Gastos!D4:D503),0)
B23: Ago | C23: =IFERROR(SUMPRODUCT((MONTH(Gastos!A4:A503)=8)*(YEAR(Gastos!A4:A503)=C4)*Gastos!D4:D503),0) | D23: =IFERROR(Presupuesto!J18,0) | F23: Transporte/Combustible | G23: =IFERROR(SUMPRODUCT((Gastos!C4:C503=F23)*(YEAR(Gastos!A4:A503)=C4)*Gastos!D4:D503),0)
B24: Sep | C24: =IFERROR(SUMPRODUCT((MONTH(Gastos!A4:A503)=9)*(YEAR(Gastos!A4:A503)=C4)*Gastos!D4:D503),0) | D24: =IFERROR(Presupuesto!K18,0) | F24: Mantenimiento | G24: =IFERROR(SUMPRODUCT((Gastos!C4:C503=F24)*(YEAR(Gastos!A4:A503)=C4)*Gastos!D4:D503),0)
B25: Oct | C25: =IFERROR(SUMPRODUCT((MONTH(Gastos!A4:A503)=10)*(YEAR(Gastos!A4:A503)=C4)*Gastos!D4:D503),0) | D25: =IFERROR(Presupuesto!L18,0) | F25: Seguros | G25: =IFERROR(SUMPRODUCT((Gastos!C4:C503=F25)*(YEAR(Gastos!A4:A503)=C4)*Gastos!D4:D503),0)
B26: Nov | C26: =IFERROR(SUMPRODUCT((MONTH(Gastos!A4:A503)=11)*(YEAR(Gastos!A4:A503)=C4)*Gastos!D4:D503),0) | D26: =IFERROR(Presupuesto!M18,0) | F26: Impuestos/Patentes | G26: =IFERROR(SUMPRODUCT((Gastos!C4:C503=F26)*(YEAR(Gastos!A4:A503)=C4)*Gastos!D4:D503),0)
B27: Dic | C27: =IFERROR(SUMPRODUCT((MONTH(Gastos!A4:A503)=12)*(YEAR(Gastos!A4:A503)=C4)*Gastos!D4:D503),0) | D27: =IFERROR(Presupuesto!N18,0) | F27: Otros Gastos | G27: =IFERROR(SUMPRODUCT((Gastos!C4:C503=F27)*(YEAR(Gastos!A4:A503)=C4)*Gastos!D4:D503),0)

Sheet Gastos
A1: REGISTRO DE GASTOS OPERATIVOS
A2: Registra cada gasto con fecha, descripcion y categoria. Las celdas amarillas son editables.
A3: FECHA | B3: DESCRIPCION | C3: CATEGORIA | D3: MONTO (Bs.) | E3: METODO PAGO | F3: OBSERVACION
A4: 45658 | B4: Alquiler local enero | C4: Alquiler | D4: 3500 | E4: Transferencia
A5: 45662 | B5: Luz y agua enero | C5: Servicios (luz/agua/gas) | D5: 450 | E5: Efectivo
A6: 45662 | B6: Internet fibra optica | C6: Internet/Telefono | D6: 250 | E6: Transferencia | F6: Plan empresarial
A7: 45667 | B7: Sueldos enero | C7: Sueldos y Salarios | D7: 8000 | E7: Transferencia | F7: 3 empleados
A8: 45672 | B8: Papeleria y toner | C8: Material de Oficina | D8: 320 | E8: Efectivo
A9: 45672 | B9: Publicidad Facebook | C9: Publicidad/Marketing | D9: 500 | E9: Tarjeta | F9: Campana enero
A10: 45677 | B10: Gasolina vehiculo | C10: Transporte/Combustible | D10: 400 | E10: Efectivo
A11: 45682 | B11: Reparacion AC | C11: Mantenimiento | D11: 600 | E11: Cheque | F11: Aire acondicionado
A12: 45689 | B12: Alquiler local febrero | C12: Alquiler | D12: 3500 | E12: Transferencia
A13: 45693 | B13: Luz y agua febrero | C13: Servicios (luz/agua/gas) | D13: 480 | E13: Efectivo

Sheet Presupuesto
B1: PRESUPUESTO vs REAL POR CATEGORIA
B2: Ano: | C2: =Dashboard!C4
B4: PRESUPUESTO MENSUAL (Bs.)
B5: CATEGORIA | C5: ENE | D5: FEB | E5: MAR | F5: ABR | G5: MAY | H5: JUN | I5: JUL | J5: AGO | K5: SEP | L5: OCT | M5: NOV | N5: DIC | O5: TOTAL
B6: Alquiler | C6: 3500 | D6: 3500 | E6: 3500 | F6: 3500 | G6: 3500 | H6: 3500 | I6: 3500 | J6: 3500 | K6: 3500 | L6: 3500 | M6: 3500 | N6: 3500 | O6: =SUM(C6:N6)
B7: Servicios (luz/agua/gas) | C7: 500 | D7: 500 | E7: 500 | F7: 500 | G7: 500 | H7: 500 | I7: 500 | J7: 500 | K7: 500 | L7: 500 | M7: 500 | N7: 500 | O7: =SUM(C7:N7)
B8: Internet/Telefono | C8: 250 | D8: 250 | E8: 250 | F8: 250 | G8: 250 | H8: 250 | I8: 250 | J8: 250 | K8: 250 | L8: 250 | M8: 250 | N8: 250 | O8: =SUM(C8:N8)
B9: Sueldos y Salarios | C9: 8000 | D9: 8000 | E9: 8000 | F9: 8000 | G9: 8000 | H9: 8000 | I9: 8000 | J9: 8000 | K9: 8000 | L9: 8000 | M9: 8000 | N9: 8000 | O9: =SUM(C9:N9)
B10: Seguro Social | C10: 1200 | D10: 1200 | E10: 1200 | F10: 1200 | G10: 1200 | H10: 1200 | I10: 1200 | J10: 1200 | K10: 1200 | L10: 1200 | M10: 1200 | N10: 1200 | O10: =SUM(C10:N10)
B11: Material de Oficina | C11: 400 | D11: 400 | E11: 400 | F11: 400 | G11: 400 | H11: 400 | I11: 400 | J11: 400 | K11: 400 | L11: 400 | M11: 400 | N11: 400 | O11: =SUM(C11:N11)
B12: Publicidad/Marketing | C12: 600 | D12: 600 | E12: 600 | F12: 600 | G12: 600 | H12: 600 | I12: 600 | J12: 600 | K12: 600 | L12: 600 | M12: 600 | N12: 600 | O12: =SUM(C12:N12)
B13: Transporte/Combustible | C13: 500 | D13: 500 | E13: 500 | F13: 500 | G13: 500 | H13: 500 | I13: 500 | J13: 500 | K13: 500 | L13: 500 | M13: 500 | N13: 500 | O13: =SUM(C13:N13)
B14: Mantenimiento | C14: 300 | D14: 300 | E14: 300 | F14: 300 | G14: 300 | H14: 300 | I14: 300 | J14: 300 | K14: 300 | L14: 300 | M14: 300 | N14: 300 | O14: =SUM(C14:N14)
B15: Seguros | C15: 200 | D15: 200 | E15: 200 | F15: 200 | G15: 200 | H15: 200 | I15: 200 | J15: 200 | K15: 200 | L15: 200 | M15: 200 | N15: 200 | O15: =SUM(C15:N15)
B16: Impuestos/Patentes | C16: 150 | D16: 150 | E16: 150 | F16: 150 | G16: 150 | H16: 150 | I16: 150 | J16: 150 | K16: 150 | L16: 150 | M16: 150 | N16: 150 | O16: =SUM(C16:N16)
B17: Otros Gastos | C17: 200 | D17: 200 | E17: 200 | F17: 200 | G17: 200 | H17: 200 | I17: 200 | J17: 200 | K17: 200 | L17: 200 | M17: 200 | N17: 200 | O17: =SUM(C17:N17)
B18: TOTAL PRESUPUESTO | C18: =SUM(C6:C17) | D18: =SUM(D6:D17) | E18: =SUM(E6:E17) | F18: =SUM(F6:F17) | G18: =SUM(G6:G17) | H18: =SUM(H6:H17) | I18: =SUM(I6:I17) | J18: =SUM(J6:J17) | ... O18: =SUM(O6:O17)
B20: GASTO REAL MENSUAL (Bs.)
B21: CATEGORIA | C21: ENE | D21: FEB | E21: MAR | F21: ABR | G21: MAY | H21: JUN | I21: JUL | J21: AGO | K21: SEP | L21: OCT | M21: NOV | N21: DIC | O21: TOTAL
B22: Alquiler | C22: =IFERROR(SUMPRODUCT((Gastos!C4:C503="Alquiler")*(MONTH(Gastos!A4:A503)=1)*(YEAR(Gastos!A4:A503)=C2)*Gastos!D4:D503),0) | D22: =IFERROR(SUMPRODUCT((Gastos!C4:C503="Alquiler")*(MONTH(Gastos!A4:A503)=2)*(YEAR(Gastos!A4:A503)=C2)*Gastos!D4:D503),0) | E22: =IFERROR(SUMPRODUCT((Gastos!C4:C503="Alquiler")*(MONTH(Gastos!A4:A503)=3)*(YEAR(Gastos!A4:A503)=C2)*Gastos!D4:D503),0) | F22: =IFERROR(SUMPRODUCT((Gastos!C4:C503="Alquiler")*(MONTH(Gastos!A4:A503)=4)*(YEAR(Gastos!A4:A503)=C2)*Gastos!D4:D503),0) | G22: =IFERROR(SUMPRODUCT((Gastos!C4:C503="Alquiler")*(MONTH(Gastos!A4:A503)=5)*(YEAR(Gastos!A4:A503)=C2)*Gastos!D4:D503),0) | H22: =IFERROR(SUMPRODUCT((Gastos!C4:C503="Alquiler")*(MONTH(Gastos!A4:A503)=6)*(YEAR(Gastos!A4:A503)=C2)*Gastos!D4:D503),0) | I22: =IFERROR(SUMPRODUCT((Gastos!C4:C503="Alquiler")*(MONTH(Gastos!A4:A503)=7)*(YEAR(Gastos!A4:A503)=C2)*Gastos!D4:D503),0) | J22: =IFERROR(SUMPRODUCT((Gastos!C4:C503="Alquiler")*(MONTH(Gastos!A4:A503)=8)*(YEAR(Gastos!A4:A503)=C2)*Gastos!D4:D503),0) | K22: =IFERROR(SUMPRODUCT((Gastos!C4:C503="Alquiler")*(MONTH(Gastos!A4:A503)=9)*(YEAR(Gastos!A4:A503)=C2)*Gastos!D4:D503),0) | L22: =IFERROR(SUMPRODUCT((Gastos!C4:C503="Alquiler")*(MONTH(Gastos!A4:A503)=10)*(YEAR(Gastos!A4:A503)=C2)*Gastos!D4:D503),0) | M22: =IFERROR(SUMPRODUCT((Gastos!C4:C503="Alquiler")*(MONTH(Gastos!A4:A503)=11)*(YEAR(Gastos!A4:A503)=C2)*Gastos!D4:D503),0) | N22: =IFERROR(SUMPRODUCT((Gastos!C4:C503="Alquiler")*(MONTH(Gastos!A4:A503)=12)*(YEAR(Gastos!A4:A503)=C2)*Gastos!D4:D503),0) | O22: =SUM(C22:N22)
B23: Servicios (luz/agua/gas) | C23: =IFERROR(SUMPRODUCT((Gastos!C4:C503="Servicios (luz/agua/gas)")*(MONTH(Gastos!A4:A503)=1)*(YEAR(Gastos!A4:A503)=C2)*Gastos!D4:D503),0) | D23: =IFERROR(SUMPRODUCT((Gastos!C4:C503="Servicios (luz/agua/gas)")*(MONTH(Gastos!A4:A503)=2)*(YEAR(Gastos!A4:A503)=C2)*Gastos!D4:D503),0) | E23: =IFERROR(SUMPRODUCT((Gastos!C4:C503="Servicios (luz/agua/gas)")*(MONTH(Gastos!A4:A503)=3)*(YEAR(Gastos!A4:A503)=C2)*Gastos!D4:D503),0) | F23: =IFERROR(SUMPRODUCT((Gastos!C4:C503="Servicios (luz/agua/gas)")*(MONTH(Gastos!A4:A503)=4)*(YEAR(Gastos!A4:A503)=C2)*Gastos!D4:D503),0) | G23: =IFERROR(SUMPRODUCT((Gastos!C4:C503="Servicios (luz/agua/gas)")*(MONTH(Gastos!A4:A503)=5)*(YEAR(Gastos!A4:A503)=C2)*Gastos!D4:D503),0) | H23: =IFERROR(SUMPRODUCT((Gastos!C4:C503="Servicios (luz/agua/gas)")*(MONTH(Gastos!A4:A503)=6)*(YEAR(Gastos!A4:A503)=C2)*Gastos!D4:D503),0) | I23: =IFERROR(SUMPRODUCT((Gastos!C4:C503="Servicios (luz/agua/gas)")*(MONTH(Gastos!A4:A503)=7)*(YEAR(Gastos!A4:A503)=C2)*Gastos!D4:D503),0) | J23: =IFERROR(SUMPRODUCT((Gastos!C4:C503="Servicios (luz/agua/gas)")*(MONTH(Gastos!A4:A503)=8)*(YEAR(Gastos!A4:A503)=C2)*Gastos!D4:D503),0) | K23: =IFERROR(SUMPRODUCT((Gastos!C4:C503="Servicios (luz/agua/gas)")*(MONTH(Gastos!A4:A503)=9)*(YEAR(Gastos!A4:A503)=C2)*Gastos!D4:D503),0) | L23: =IFERROR(SUMPRODUCT((Gastos!C4:C503="Servicios (luz/agua/gas)")*(MONTH(Gastos!A4:A503)=10)*(YEAR(Gastos!A4:A503)=C2)*Gastos!D4:D503),0) | M23: =IFERROR(SUMPRODUCT((Gastos!C4:C503="Servicios (luz/agua/gas)")*(MONTH(Gastos!A4:A503)=11)*(YEAR(Gastos!A4:A503)=C2)*Gastos!D4:D503),0) | N23: =IFERROR(SUMPRODUCT((Gastos!C4:C503="Servicios (luz/agua/gas)")*(MONTH(Gastos!A4:A503)=12)*(YEAR(Gastos!A4:A503)=C2)*Gastos!D4:D503),0) | O23: =SUM(C23:N23)
B24: Internet/Telefono | C24: =IFERROR(SUMPRODUCT((Gastos!C4:C503="Internet/Telefono")*(MONTH(Gastos!A4:A503)=1)*(YEAR(Gastos!A4:A503)=C2)*Gastos!D4:D503),0) | D24: =IFERROR(SUMPRODUCT((Gastos!C4:C503="Internet/Telefono")*(MONTH(Gastos!A4:A503)=2)*(YEAR(Gastos!A4:A503)=C2)*Gastos!D4:D503),0) | E24: =IFERROR(SUMPRODUCT((Gastos!C4:C503="Internet/Telefono")*(MONTH(Gastos!A4:A503)=3)*(YEAR(Gastos!A4:A503)=C2)*Gastos!D4:D503),0) | F24: =IFERROR(SUMPRODUCT((Gastos!C4:C503="Internet/Telefono")*(MONTH(Gastos!A4:A503)=4)*(YEAR(Gastos!A4:A503)=C2)*Gastos!D4:D503),0) | G24: =IFERROR(SUMPRODUCT((Gastos!C4:C503="Internet/Telefono")*(MONTH(Gastos!A4:A503)=5)*(YEAR(Gastos!A4:A503)=C2)*Gastos!D4:D503),0) | H24: =IFERROR(SUMPRODUCT((Gastos!C4:C503="Internet/Telefono")*(MONTH(Gastos!A4:A503)=6)*(YEAR(Gastos!A4:A503)=C2)*Gastos!D4:D503),0) | I24: =IFERROR(SUMPRODUCT((Gastos!C4:C503="Internet/Telefono")*(MONTH(Gastos!A4:A503)=7)*(YEAR(Gastos!A4:A503)=C2)*Gastos!D4:D503),0) | J24: =IFERROR(SUMPRODUCT((Gastos!C4:C503="Internet/Telefono")*(MONTH(Gastos!A4:A503)=8)*(YEAR(Gastos!A4:A503)=C2)*Gastos!D4:D503),0) | K24: =IFERROR(SUMPRODUCT((Gastos!C4:C503="Internet/Telefono")*(MONTH(Gastos!A4:A503)=9)*(YEAR(Gastos!A4:A503)=C2)*Gastos!D4:D503),0) | L24: =IFERROR(SUMPRODUCT((Gastos!C4:C503="Internet/Telefono")*(MONTH(Gastos!A4:A503)=10)*(YEAR(Gastos!A4:A503)=C2)*Gastos!D4:D503),0) | M24: =IFERROR(SUMPRODUCT((Gastos!C4:C503="Internet/Telefono")*(MONTH(Gastos!A4:A503)=11)*(YEAR(Gastos!A4:A503)=C2)*Gastos!D4:D503),0) | N24: =IFERROR(SUMPRODUCT((Gastos!C4:C503="Internet/Telefono")*(MONTH(Gastos!A4:A503)=12)*(YEAR(Gastos!A4:A503)=C2)*Gastos!D4:D503),0) | O24: =SUM(C24:N24)
B25: Sueldos y Salarios | C25: =IFERROR(SUMPRODUCT((Gastos!C4:C503="Sueldos y Salarios")*(MONTH(Gastos!A4:A503)=1)*(YEAR(Gastos!A4:A503)=C2)*Gastos!D4:D503),0) | D25: =IFERROR(SUMPRODUCT((Gastos!C4:C503="Sueldos y Salarios")*(MONTH(Gastos!A4:A503)=2)*(YEAR(Gastos!A4:A503)=C2)*Gastos!D4:D503),0) | E25: =IFERROR(SUMPRODUCT((Gastos!C4:C503="Sueldos y Salarios")*(MONTH(Gastos!A4:A503)=3)*(YEAR(Gastos!A4:A503)=C2)*Gastos!D4:D503),0) | F25: =IFERROR(SUMPRODUCT((Gastos!C4:C503="Sueldos y Salarios")*(MONTH(Gastos!A4:A503)=4)*(YEAR(Gastos!A4:A503)=C2)*Gastos!D4:D503),0) | G25: =IFERROR(SUMPRODUCT((Gastos!C4:C503="Sueldos y Salarios")*(MONTH(Gastos!A4:A503)=5)*(YEAR(Gastos!A4:A503)=C2)*Gastos!D4:D503),0) | H25: =IFERROR(SUMPRODUCT((Gastos!C4:C503="Sueldos y Salarios")*(MONTH(Gastos!A4:A503)=6)*(YEAR(Gastos!A4:A503)=C2)*Gastos!D4:D503),0) | I25: =IFERROR(SUMPRODUCT((Gastos!C4:C503="Sueldos y Salarios")*(MONTH(Gastos!A4:A503)=7)*(YEAR(Gastos!A4:A503)=C2)*Gastos!D4:D503),0) | J25: =IFERROR(SUMPRODUCT((Gastos!C4:C503="Sueldos y Salarios")*(MONTH(Gastos!A4:A503)=8)*(YEAR(Gastos!A4:A503)=C2)*Gastos!D4:D503),0) | K25: =IFERROR(SUMPRODUCT((Gastos!C4:C503="Sueldos y Salarios")*(MONTH(Gastos!A4:A503)=9)*(YEAR(Gastos!A4:A503)=C2)*Gastos!D4:D503),0) | L25: =IFERROR(SUMPRODUCT((Gastos!C4:C503="Sueldos y Salarios")*(MONTH(Gastos!A4:A503)=10)*(YEAR(Gastos!A4:A503)=C2)*Gastos!D4:D503),0) | M25: =IFERROR(SUMPRODUCT((Gastos!C4:C503="Sueldos y Salarios")*(MONTH(Gastos!A4:A503)=11)*(YEAR(Gastos!A4:A503)=C2)*Gastos!D4:D503),0) | N25: =IFERROR(SUMPRODUCT((Gastos!C4:C503="Sueldos y Salarios")*(MONTH(Gastos!A4:A503)=12)*(YEAR(Gastos!A4:A503)=C2)*Gastos!D4:D503),0) | O25: =SUM(C25:N25)
B26: Seguro Social | C26: =IFERROR(SUMPRODUCT((Gastos!C4:C503="Seguro Social")*(MONTH(Gastos!A4:A503)=1)*(YEAR(Gastos!A4:A503)=C2)*Gastos!D4:D503),0) | D26: =IFERROR(SUMPRODUCT((Gastos!C4:C503="Seguro Social")*(MONTH(Gastos!A4:A503)=2)*(YEAR(Gastos!A4:A503)=C2)*Gastos!D4:D503),0) | E26: =IFERROR(SUMPRODUCT((Gastos!C4:C503="Seguro Social")*(MONTH(Gastos!A4:A503)=3)*(YEAR(Gastos!A4:A503)=C2)*Gastos!D4:D503),0) | F26: =IFERROR(SUMPRODUCT((Gastos!C4:C503="Seguro Social")*(MONTH(Gastos!A4:A503)=4)*(YEAR(Gastos!A4:A503)=C2)*Gastos!D4:D503),0) | G26: =IFERROR(SUMPRODUCT((Gastos!C4:C503="Seguro Social")*(MONTH(Gastos!A4:A503)=5)*(YEAR(Gastos!A4:A503)=C2)*Gastos!D4:D503),0) | H26: =IFERROR(SUMPRODUCT((Gastos!C4:C503="Seguro Social")*(MONTH(Gastos!A4:A503)=6)*(YEAR(Gastos!A4:A503)=C2)*Gastos!D4:D503),0) | I26: =IFERROR(SUMPRODUCT((Gastos!C4:C503="Seguro Social")*(MONTH(Gastos!A4:A503)=7)*(YEAR(Gastos!A4:A503)=C2)*Gastos!D4:D503),0) | J26: =IFERROR(SUMPRODUCT((Gastos!C4:C503="Seguro Social")*(MONTH(Gastos!A4:A503)=8)*(YEAR(Gastos!A4:A503)=C2)*Gastos!D4:D503),0) | K26: =IFERROR(SUMPRODUCT((Gastos!C4:C503="Seguro Social")*(MONTH(Gastos!A4:A503)=9)*(YEAR(Gastos!A4:A503)=C2)*Gastos!D4:D503),0) | L26: =IFERROR(SUMPRODUCT((Gastos!C4:C503="Seguro Social")*(MONTH(Gastos!A4:A503)=10)*(YEAR(Gastos!A4:A503)=C2)*Gastos!D4:D503),0) | M26: =IFERROR(SUMPRODUCT((Gastos!C4:C503="Seguro Social")*(MONTH(Gastos!A4:A503)=11)*(YEAR(Gastos!A4:A503)=C2)*Gastos!D4:D503),0) | N26: =IFERROR(SUMPRODUCT((Gastos!C4:C503="Seguro Social")*(MONTH(Gastos!A4:A503)=12)*(YEAR(Gastos!A4:A503)=C2)*Gastos!D4:D503),0) | O26: =SUM(C26:N26)
B27: Material de Oficina | C27: =IFERROR(SUMPRODUCT((Gastos!C4:C503="Material de Oficina")*(MONTH(Gastos!A4:A503)=1)*(YEAR(Gastos!A4:A503)=C2)*Gastos!D4:D503),0) | D27: =IFERROR(SUMPRODUCT((Gastos!C4:C503="Material de Oficina")*(MONTH(Gastos!A4:A503)=2)*(YEAR(Gastos!A4:A503)=C2)*Gastos!D4:D503),0) | E27: =IFERROR(SUMPRODUCT((Gastos!C4:C503="Material de Oficina")*(MONTH(Gastos!A4:A503)=3)*(YEAR(Gastos!A4:A503)=C2)*Gastos!D4:D503),0) | F27: =IFERROR(SUMPRODUCT((Gastos!C4:C503="Material de Oficina")*(MONTH(Gastos!A4:A503)=4)*(YEAR(Gastos!A4:A503)=C2)*Gastos!D4:D503),0) | G27: =IFERROR(SUMPRODUCT((Gastos!C4:C503="Material de Oficina")*(MONTH(Gastos!A4:A503)=5)*(YEAR(Gastos!A4:A503)=C2)*Gastos!D4:D503),0) | H27: =IFERROR(SUMPRODUCT((Gastos!C4:C503="Material de Oficina")*(MONTH(Gastos!A4:A503)=6)*(YEAR(Gastos!A4:A503)=C2)*Gastos!D4:D503),0) | I27: =IFERROR(SUMPRODUCT((Gastos!C4:C503="Material de Oficina")*(MONTH(Gastos!A4:A503)=7)*(YEAR(Gastos!A4:A503)=C2)*Gastos!D4:D503),0) | J27: =IFERROR(SUMPRODUCT((Gastos!C4:C503="Material de Oficina")*(MONTH(Gastos!A4:A503)=8)*(YEAR(Gastos!A4:A503)=C2)*Gastos!D4:D503),0) | K27: =IFERROR(SUMPRODUCT((Gastos!C4:C503="Material de Oficina")*(MONTH(Gastos!A4:A503)=9)*(YEAR(Gastos!A4:A503)=C2)*Gastos!D4:D503),0) | L27: =IFERROR(SUMPRODUCT((Gastos!C4:C503="Material de Oficina")*(MONTH(Gastos!A4:A503)=10)*(YEAR(Gastos!A4:A503)=C2)*Gastos!D4:D503),0) | M27: =IFERROR(SUMPRODUCT((Gastos!C4:C503="Material de Oficina")*(MONTH(Gastos!A4:A503)=11)*(YEAR(Gastos!A4:A503)=C2)*Gastos!D4:D503),0) | N27: =IFERROR(SUMPRODUCT((Gastos!C4:C503="Material de Oficina")*(MONTH(Gastos!A4:A503)=12)*(YEAR(Gastos!A4:A503)=C2)*Gastos!D4:D503),0) | O27: =SUM(C27:N27)
B28: Publicidad/Marketing | C28: =IFERROR(SUMPRODUCT((Gastos!C4:C503="Publicidad/Marketing")*(MONTH(Gastos!A4:A503)=1)*(YEAR(Gastos!A4:A503)=C2)*Gastos!D4:D503),0) | D28: =IFERROR(SUMPRODUCT((Gastos!C4:C503="Publicidad/Marketing")*(MONTH(Gastos!A4:A503)=2)*(YEAR(Gastos!A4:A503)=C2)*Gastos!D4:D503),0) | E28: =IFERROR(SUMPRODUCT((Gastos!C4:C503="Publicidad/Marketing")*(MONTH(Gastos!A4:A503)=3)*(YEAR(Gastos!A4:A503)=C2)*Gastos!D4:D503),0) | F28: =IFERROR(SUMPRODUCT((Gastos!C4:C503="Publicidad/Marketing")*(MONTH(Gastos!A4:A503)=4)*(YEAR(Gastos!A4:A503)=C2)*Gastos!D4:D503),0) | G28: =IFERROR(SUMPRODUCT((Gastos!C4:C503="Publicidad/Marketing")*(MONTH(Gastos!A4:A503)=5)*(YEAR(Gastos!A4:A503)=C2)*Gastos!D4:D503),0) | H28: =IFERROR(SUMPRODUCT((Gastos!C4:C503="Publicidad/Marketing")*(MONTH(Gastos!A4:A503)=6)*(YEAR(Gastos!A4:A503)=C2)*Gastos!D4:D503),0) | I28: =IFERROR(SUMPRODUCT((Gastos!C4:C503="Publicidad/Marketing")*(MONTH(Gastos!A4:A503)=7)*(YEAR(Gastos!A4:A503)=C2)*Gastos!D4:D503),0) | J28: =IFERROR(SUMPRODUCT((Gastos!C4:C503="Publicidad/Marketing")*(MONTH(Gastos!A4:A503)=8)*(YEAR(Gastos!A4:A503)=C2)*Gastos!D4:D503),0) | K28: =IFERROR(SUMPRODUCT((Gastos!C4:C503="Publicidad/Marketing")*(MONTH(Gastos!A4:A503)=9)*(YEAR(Gastos!A4:A503)=C2)*Gastos!D4:D503),0) | L28: =IFERROR(SUMPRODUCT((Gastos!C4:C503="Publicidad/Marketing")*(MONTH(Gastos!A4:A503)=10)*(YEAR(Gastos!A4:A503)=C2)*Gastos!D4:D503),0) | M28: =IFERROR(SUMPRODUCT((Gastos!C4:C503="Publicidad/Marketing")*(MONTH(Gastos!A4:A503)=11)*(YEAR(Gastos!A4:A503)=C2)*Gastos!D4:D503),0) | N28: =IFERROR(SUMPRODUCT((Gastos!C4:C503="Publicidad/Marketing")*(MONTH(Gastos!A4:A503)=12)*(YEAR(Gastos!A4:A503)=C2)*Gastos!D4:D503),0) | O28: =SUM(C28:N28)
B29: Transporte/Combustible | C29: =IFERROR(SUMPRODUCT((Gastos!C4:C503="Transporte/Combustible")*(MONTH(Gastos!A4:A503)=1)*(YEAR(Gastos!A4:A503)=C2)*Gastos!D4:D503),0) | D29: =IFERROR(SUMPRODUCT((Gastos!C4:C503="Transporte/Combustible")*(MONTH(Gastos!A4:A503)=2)*(YEAR(Gastos!A4:A503)=C2)*Gastos!D4:D503),0) | E29: =IFERROR(SUMPRODUCT((Gastos!C4:C503="Transporte/Combustible")*(MONTH(Gastos!A4:A503)=3)*(YEAR(Gastos!A4:A503)=C2)*Gastos!D4:D503),0) | F29: =IFERROR(SUMPRODUCT((Gastos!C4:C503="Transporte/Combustible")*(MONTH(Gastos!A4:A503)=4)*(YEAR(Gastos!A4:A503)=C2)*Gastos!D4:D503),0) | G29: =IFERROR(SUMPRODUCT((Gastos!C4:C503="Transporte/Combustible")*(MONTH(Gastos!A4:A503)=5)*(YEAR(Gastos!A4:A503)=C2)*Gastos!D4:D503),0) | H29: =IFERROR(SUMPRODUCT((Gastos!C4:C503="Transporte/Combustible")*(MONTH(Gastos!A4:A503)=6)*(YEAR(Gastos!A4:A503)=C2)*Gastos!D4:D503),0) | I29: =IFERROR(SUMPRODUCT((Gastos!C4:C503="Transporte/Combustible")*(MONTH(Gastos!A4:A503)=7)*(YEAR(Gastos!A4:A503)=C2)*Gastos!D4:D503),0) | J29: =IFERROR(SUMPRODUCT((Gastos!C4:C503="Transporte/Combustible")*(MONTH(Gastos!A4:A503)=8)*(YEAR(Gastos!A4:A503)=C2)*Gastos!D4:D503),0) | K29: =IFERROR(SUMPRODUCT((Gastos!C4:C503="Transporte/Combustible")*(MONTH(Gastos!A4:A503)=9)*(YEAR(Gastos!A4:A503)=C2)*Gastos!D4:D503),0) | L29: =IFERROR(SUMPRODUCT((Gastos!C4:C503="Transporte/Combustible")*(MONTH(Gastos!A4:A503)=10)*(YEAR(Gastos!A4:A503)=C2)*Gastos!D4:D503),0) | M29: =IFERROR(SUMPRODUCT((Gastos!C4:C503="Transporte/Combustible")*(MONTH(Gastos!A4:A503)=11)*(YEAR(Gastos!A4:A503)=C2)*Gastos!D4:D503),0) | N29: =IFERROR(SUMPRODUCT((Gastos!C4:C503="Transporte/Combustible")*(MONTH(Gastos!A4:A503)=12)*(YEAR(Gastos!A4:A503)=C2)*Gastos!D4:D503),0) | O29: =SUM(C29:N29)
B30: Mantenimiento | C30: =IFERROR(SUMPRODUCT((Gastos!C4:C503="Mantenimiento")*(MONTH(Gastos!A4:A503)=1)*(YEAR(Gastos!A4:A503)=C2)*Gastos!D4:D503),0) | D30: =IFERROR(SUMPRODUCT((Gastos!C4:C503="Mantenimiento")*(MONTH(Gastos!A4:A503)=2)*(YEAR(Gastos!A4:A503)=C2)*Gastos!D4:D503),0) | E30: =IFERROR(SUMPRODUCT((Gastos!C4:C503="Mantenimiento")*(MONTH(Gastos!A4:A503)=3)*(YEAR(Gastos!A4:A503)=C2)*Gastos!D4:D503),0) | F30: =IFERROR(SUMPRODUCT((Gastos!C4:C503="Mantenimiento")*(MONTH(Gastos!A4:A503)=4)*(YEAR(Gastos!A4:A503)=C2)*Gastos!D4:D503),0) | G30: =IFERROR(SUMPRODUCT((Gastos!C4:C503="Mantenimiento")*(MONTH(Gastos!A4:A503)=5)*(YEAR(Gastos!A4:A503)=C2)*Gastos!D4:D503),0) | H30: =IFERROR(SUMPRODUCT((Gastos!C4:C503="Mantenimiento")*(MONTH(Gastos!A4:A503)=6)*(YEAR(Gastos!A4:A503)=C2)*Gastos!D4:D503),0) | I30: =IFERROR(SUMPRODUCT((Gastos!C4:C503="Mantenimiento")*(MONTH(Gastos!A4:A503)=7)*(YEAR(Gastos!A4:A503)=C2)*Gastos!D4:D503),0) | J30: =IFERROR(SUMPRODUCT((Gastos!C4:C503="Mantenimiento")*(MONTH(Gastos!A4:A503)=8)*(YEAR(Gastos!A4:A503)=C2)*Gastos!D4:D503),0) | K30: =IFERROR(SUMPRODUCT((Gastos!C4:C503="Mantenimiento")*(MONTH(Gastos!A4:A503)=9)*(YEAR(Gastos!A4:A503)=C2)*Gastos!D4:D503),0) | L30: =IFERROR(SUMPRODUCT((Gastos!C4:C503="Mantenimiento")*(MONTH(Gastos!A4:A503)=10)*(YEAR(Gastos!A4:A503)=C2)*Gastos!D4:D503),0) | M30: =IFERROR(SUMPRODUCT((Gastos!C4:C503="Mantenimiento")*(MONTH(Gastos!A4:A503)=11)*(YEAR(Gastos!A4:A503)=C2)*Gastos!D4:D503),0) | N30: =IFERROR(SUMPRODUCT((Gastos!C4:C503="Mantenimiento")*(MONTH(Gastos!A4:A503)=12)*(YEAR(Gastos!A4:A503)=C2)*Gastos!D4:D503),0) | O30: =SUM(C30:N30)
B31: Seguros | C31: =IFERROR(SUMPRODUCT((Gastos!C4:C503="Seguros")*(MONTH(Gastos!A4:A503)=1)*(YEAR(Gastos!A4:A503)=C2)*Gastos!D4:D503),0) | D31: =IFERROR(SUMPRODUCT((Gastos!C4:C503="Seguros")*(MONTH(Gastos!A4:A503)=2)*(YEAR(Gastos!A4:A503)=C2)*Gastos!D4:D503),0) | E31: =IFERROR(SUMPRODUCT((Gastos!C4:C503="Seguros")*(MONTH(Gastos!A4:A503)=3)*(YEAR(Gastos!A4:A503)=C2)*Gastos!D4:D503),0) | F31: =IFERROR(SUMPRODUCT((Gastos!C4:C503="Seguros")*(MONTH(Gastos!A4:A503)=4)*(YEAR(Gastos!A4:A503)=C2)*Gastos!D4:D503),0) | G31: =IFERROR(SUMPRODUCT((Gastos!C4:C503="Seguros")*(MONTH(Gastos!A4:A503)=5)*(YEAR(Gastos!A4:A503)=C2)*Gastos!D4:D503),0) | H31: =IFERROR(SUMPRODUCT((Gastos!C4:C503="Seguros")*(MONTH(Gastos!A4:A503)=6)*(YEAR(Gastos!A4:A503)=C2)*Gastos!D4:D503),0) | I31: =IFERROR(SUMPRODUCT((Gastos!C4:C503="Seguros")*(MONTH(Gastos!A4:A503)=7)*(YEAR(Gastos!A4:A503)=C2)*Gastos!D4:D503),0) | J31: =IFERROR(SUMPRODUCT((Gastos!C4:C503="Seguros")*(MONTH(Gastos!A4:A503)=8)*(YEAR(Gastos!A4:A503)=C2)*Gastos!D4:D503),0) | K31: =IFERROR(SUMPRODUCT((Gastos!C4:C503="Seguros")*(MONTH(Gastos!A4:A503)=9)*(YEAR(Gastos!A4:A503)=C2)*Gastos!D4:D503),0) | L31: =IFERROR(SUMPRODUCT((Gastos!C4:C503="Seguros")*(MONTH(Gastos!A4:A503)=10)*(YEAR(Gastos!A4:A503)=C2)*Gastos!D4:D503),0) | M31: =IFERROR(SUMPRODUCT((Gastos!C4:C503="Seguros")*(MONTH(Gastos!A4:A503)=11)*(YEAR(Gastos!A4:A503)=C2)*Gastos!D4:D503),0) | N31: =IFERROR(SUMPRODUCT((Gastos!C4:C503="Seguros")*(MONTH(Gastos!A4:A503)=12)*(YEAR(Gastos!A4:A503)=C2)*Gastos!D4:D503),0) | O31: =SUM(C31:N31)
B32: Impuestos/Patentes | C32: =IFERROR(SUMPRODUCT((Gastos!C4:C503="Impuestos/Patentes")*(MONTH(Gastos!A4:A503)=1)*(YEAR(Gastos!A4:A503)=C2)*Gastos!D4:D503),0) | D32: =IFERROR(SUMPRODUCT((Gastos!C4:C503="Impuestos/Patentes")*(MONTH(Gastos!A4:A503)=2)*(YEAR(Gastos!A4:A503)=C2)*Gastos!D4:D503),0) | E32: =IFERROR(SUMPRODUCT((Gastos!C4:C503="Impuestos/Patentes")*(MONTH(Gastos!A4:A503)=3)*(YEAR(Gastos!A4:A503)=C2)*Gastos!D4:D503),0) | F32: =IFERROR(SUMPRODUCT((Gastos!C4:C503="Impuestos/Patentes")*(MONTH(Gastos!A4:A503)=4)*(YEAR(Gastos!A4:A503)=C2)*Gastos!D4:D503),0) | G32: =IFERROR(SUMPRODUCT((Gastos!C4:C503="Impuestos/Patentes")*(MONTH(Gastos!A4:A503)=5)*(YEAR(Gastos!A4:A503)=C2)*Gastos!D4:D503),0) | H32: =IFERROR(SUMPRODUCT((Gastos!C4:C503="Impuestos/Patentes")*(MONTH(Gastos!A4:A503)=6)*(YEAR(Gastos!A4:A503)=C2)*Gastos!D4:D503),0) | I32: =IFERROR(SUMPRODUCT((Gastos!C4:C503="Impuestos/Patentes")*(MONTH(Gastos!A4:A503)=7)*(YEAR(Gastos!A4:A503)=C2)*Gastos!D4:D503),0) | J32: =IFERROR(SUMPRODUCT((Gastos!C4:C503="Impuestos/Patentes")*(MONTH(Gastos!A4:A503)=8)*(YEAR(Gastos!A4:A503)=C2)*Gastos!D4:D503),0) | K32: =IFERROR(SUMPRODUCT((Gastos!C4:C503="Impuestos/Patentes")*(MONTH(Gastos!A4:A503)=9)*(YEAR(Gastos!A4:A503)=C2)*Gastos!D4:D503),0) | L32: =IFERROR(SUMPRODUCT((Gastos!C4:C503="Impuestos/Patentes")*(MONTH(Gastos!A4:A503)=10)*(YEAR(Gastos!A4:A503)=C2)*Gastos!D4:D503),0) | M32: =IFERROR(SUMPRODUCT((Gastos!C4:C503="Impuestos/Patentes")*(MONTH(Gastos!A4:A503)=11)*(YEAR(Gastos!A4:A503)=C2)*Gastos!D4:D503),0) | N32: =IFERROR(SUMPRODUCT((Gastos!C4:C503="Impuestos/Patentes")*(MONTH(Gastos!A4:A503)=12)*(YEAR(Gastos!A4:A503)=C2)*Gastos!D4:D503),0) | O32: =SUM(C32:N32)
B33: Otros Gastos | C33: =IFERROR(SUMPRODUCT((Gastos!C4:C503="Otros Gastos")*(MONTH(Gastos!A4:A503)=1)*(YEAR(Gastos!A4:A503)=C2)*Gastos!D4:D503),0) | D33: =IFERROR(SUMPRODUCT((Gastos!C4:C503="Otros Gastos")*(MONTH(Gastos!A4:A503)=2)*(YEAR(Gastos!A4:A503)=C2)*Gastos!D4:D503),0) | E33: =IFERROR(SUMPRODUCT((Gastos!C4:C503="Otros Gastos")*(MONTH(Gastos!A4:A503)=3)*(YEAR(Gastos!A4:A503)=C2)*Gastos!D4:D503),0) | F33: =IFERROR(SUMPRODUCT((Gastos!C4:C503="Otros Gastos")*(MONTH(Gastos!A4:A503)=4)*(YEAR(Gastos!A4:A503)=C2)*Gastos!D4:D503),0) | G33: =IFERROR(SUMPRODUCT((Gastos!C4:C503="Otros Gastos")*(MONTH(Gastos!A4:A503)=5)*(YEAR(Gastos!A4:A503)=C2)*Gastos!D4:D503),0) | H33: =IFERROR(SUMPRODUCT((Gastos!C4:C503="Otros Gastos")*(MONTH(Gastos!A4:A503)=6)*(YEAR(Gastos!A4:A503)=C2)*Gastos!D4:D503),0) | I33: =IFERROR(SUMPRODUCT((Gastos!C4:C503="Otros Gastos")*(MONTH(Gastos!A4:A503)=7)*(YEAR(Gastos!A4:A503)=C2)*Gastos!D4:D503),0) | J33: =IFERROR(SUMPRODUCT((Gastos!C4:C503="Otros Gastos")*(MONTH(Gastos!A4:A503)=8)*(YEAR(Gastos!A4:A503)=C2)*Gastos!D4:D503),0) | K33: =IFERROR(SUMPRODUCT((Gastos!C4:C503="Otros Gastos")*(MONTH(Gastos!A4:A503)=9)*(YEAR(Gastos!A4:A503)=C2)*Gastos!D4:D503),0) | L33: =IFERROR(SUMPRODUCT((Gastos!C4:C503="Otros Gastos")*(MONTH(Gastos!A4:A503)=10)*(YEAR(Gastos!A4:A503)=C2)*Gastos!D4:D503),0) | M33: =IFERROR(SUMPRODUCT((Gastos!C4:C503="Otros Gastos")*(MONTH(Gastos!A4:A503)=11)*(YEAR(Gastos!A4:A503)=C2)*Gastos!D4:D503),0) | N33: =IFERROR(SUMPRODUCT((Gastos!C4:C503="Otros Gastos")*(MONTH(Gastos!A4:A503)=12)*(YEAR(Gastos!A4:A503)=C2)*Gastos!D4:D503),0) | O33: =SUM(C33:N33)
B34: TOTAL REAL | C34: =SUM(C22:C33) | D34: =SUM(D22:D33) | E34: =SUM(E22:E33) | F34: =SUM(F22:F33) | G34: =SUM(G22:G33) | H34: =SUM(H22:H33) | I34: =SUM(I22:I33) | J34: =SUM(J22:J33) | ... O34: =SUM(O22:O33)
B36: DESVIACION (Presupuesto - Real)
B37: CATEGORIA | C37: ENE | D37: FEB | E37: MAR | F37: ABR | G37: MAY | H37: JUN | I37: JUL | J37: AGO | K37: SEP | L37: OCT | M37: NOV | N37: DIC | O37: TOTAL
B38: Alquiler | C38: =C6-C22 | D38: =D6-D22 | E38: =E6-E22 | F38: =F6-F22 | G38: =G6-G22 | H38: =H6-H22 | I38: =I6-I22 | J38: =J6-J22 | ... N38: =N6-N22 | O38: =SUM(C38:N38)
B39: Servicios (luz/agua/gas) | C39: =C7-C23 | D39: =D7-D23 | E39: =E7-E23 | F39: =F7-F23 | G39: =G7-G23 | H39: =H7-H23 | I39: =I7-I23 | J39: =J7-J23 | ... N39: =N7-N23 | O39: =SUM(C39:N39)
B40: Internet/Telefono | C40: =C8-C24 | D40: =D8-D24 | E40: =E8-E24 | F40: =F8-F24 | G40: =G8-G24 | H40: =H8-H24 | I40: =I8-I24 | J40: =J8-J24 | ... N40: =N8-N24 | O40: =SUM(C40:N40)
B41: Sueldos y Salarios | C41: =C9-C25 | D41: =D9-D25 | E41: =E9-E25 | F41: =F9-F25 | G41: =G9-G25 | H41: =H9-H25 | I41: =I9-I25 | J41: =J9-J25 | ... N41: =N9-N25 | O41: =SUM(C41:N41)
B42: Seguro Social | C42: =C10-C26 | D42: =D10-D26 | E42: =E10-E26 | F42: =F10-F26 | G42: =G10-G26 | H42: =H10-H26 | I42: =I10-I26 | J42: =J10-J26 | ... N42: =N10-N26 | O42: =SUM(C42:N42)
B43: Material de Oficina | C43: =C11-C27 | D43: =D11-D27 | E43: =E11-E27 | F43: =F11-F27 | G43: =G11-G27 | H43: =H11-H27 | I43: =I11-I27 | J43: =J11-J27 | ... N43: =N11-N27 | O43: =SUM(C43:N43)
...

Sheet Tendencias
B1: TENDENCIAS DE GASTOS
B2: Evolucion mensual por categoria. Datos calculados automaticamente desde el registro de gastos.
B4: CATEGORIA | C4: ENE | D4: FEB | E4: MAR | F4: ABR | G4: MAY | H4: JUN | I4: JUL | J4: AGO | K4: SEP | L4: OCT | M4: NOV | N4: DIC
B5: Alquiler | C5: =IFERROR(SUMPRODUCT((Gastos!C4:C503="Alquiler")*(MONTH(Gastos!A4:A503)=1)*(YEAR(Gastos!A4:A503)=Dashboard!C4)*Gastos!D4:D503),0) | D5: =IFERROR(SUMPRODUCT((Gastos!C4:C503="Alquiler")*(MONTH(Gastos!A4:A503)=2)*(YEAR(Gastos!A4:A503)=Dashboard!C4)*Gastos!D4:D503),0) | E5: =IFERROR(SUMPRODUCT((Gastos!C4:C503="Alquiler")*(MONTH(Gastos!A4:A503)=3)*(YEAR(Gastos!A4:A503)=Dashboard!C4)*Gastos!D4:D503),0) | F5: =IFERROR(SUMPRODUCT((Gastos!C4:C503="Alquiler")*(MONTH(Gastos!A4:A503)=4)*(YEAR(Gastos!A4:A503)=Dashboard!C4)*Gastos!D4:D503),0) | G5: =IFERROR(SUMPRODUCT((Gastos!C4:C503="Alquiler")*(MONTH(Gastos!A4:A503)=5)*(YEAR(Gastos!A4:A503)=Dashboard!C4)*Gastos!D4:D503),0) | H5: =IFERROR(SUMPRODUCT((Gastos!C4:C503="Alquiler")*(MONTH(Gastos!A4:A503)=6)*(YEAR(Gastos!A4:A503)=Dashboard!C4)*Gastos!D4:D503),0) | I5: =IFERROR(SUMPRODUCT((Gastos!C4:C503="Alquiler")*(MONTH(Gastos!A4:A503)=7)*(YEAR(Gastos!A4:A503)=Dashboard!C4)*Gastos!D4:D503),0) | J5: =IFERROR(SUMPRODUCT((Gastos!C4:C503="Alquiler")*(MONTH(Gastos!A4:A503)=8)*(YEAR(Gastos!A4:A503)=Dashboard!C4)*Gastos!D4:D503),0) | K5: =IFERROR(SUMPRODUCT((Gastos!C4:C503="Alquiler")*(MONTH(Gastos!A4:A503)=9)*(YEAR(Gastos!A4:A503)=Dashboard!C4)*Gastos!D4:D503),0) | L5: =IFERROR(SUMPRODUCT((Gastos!C4:C503="Alquiler")*(MONTH(Gastos!A4:A503)=10)*(YEAR(Gastos!A4:A503)=Dashboard!C4)*Gastos!D4:D503),0) | M5: =IFERROR(SUMPRODUCT((Gastos!C4:C503="Alquiler")*(MONTH(Gastos!A4:A503)=11)*(YEAR(Gastos!A4:A503)=Dashboard!C4)*Gastos!D4:D503),0) | N5: =IFERROR(SUMPRODUCT((Gastos!C4:C503="Alquiler")*(MONTH(Gastos!A4:A503)=12)*(YEAR(Gastos!A4:A503)=Dashboard!C4)*Gastos!D4:D503),0)
B6: Servicios (luz/agua/gas) | C6: =IFERROR(SUMPRODUCT((Gastos!C4:C503="Servicios (luz/agua/gas)")*(MONTH(Gastos!A4:A503)=1)*(YEAR(Gastos!A4:A503)=Dashboard!C4)*Gastos!D4:D503),0) | D6: =IFERROR(SUMPRODUCT((Gastos!C4:C503="Servicios (luz/agua/gas)")*(MONTH(Gastos!A4:A503)=2)*(YEAR(Gastos!A4:A503)=Dashboard!C4)*Gastos!D4:D503),0) | E6: =IFERROR(SUMPRODUCT((Gastos!C4:C503="Servicios (luz/agua/gas)")*(MONTH(Gastos!A4:A503)=3)*(YEAR(Gastos!A4:A503)=Dashboard!C4)*Gastos!D4:D503),0) | F6: =IFERROR(SUMPRODUCT((Gastos!C4:C503="Servicios (luz/agua/gas)")*(MONTH(Gastos!A4:A503)=4)*(YEAR(Gastos!A4:A503)=Dashboard!C4)*Gastos!D4:D503),0) | G6: =IFERROR(SUMPRODUCT((Gastos!C4:C503="Servicios (luz/agua/gas)")*(MONTH(Gastos!A4:A503)=5)*(YEAR(Gastos!A4:A503)=Dashboard!C4)*Gastos!D4:D503),0) | H6: =IFERROR(SUMPRODUCT((Gastos!C4:C503="Servicios (luz/agua/gas)")*(MONTH(Gastos!A4:A503)=6)*(YEAR(Gastos!A4:A503)=Dashboard!C4)*Gastos!D4:D503),0) | I6: =IFERROR(SUMPRODUCT((Gastos!C4:C503="Servicios (luz/agua/gas)")*(MONTH(Gastos!A4:A503)=7)*(YEAR(Gastos!A4:A503)=Dashboard!C4)*Gastos!D4:D503),0) | J6: =IFERROR(SUMPRODUCT((Gastos!C4:C503="Servicios (luz/agua/gas)")*(MONTH(Gastos!A4:A503)=8)*(YEAR(Gastos!A4:A503)=Dashboard!C4)*Gastos!D4:D503),0) | K6: =IFERROR(SUMPRODUCT((Gastos!C4:C503="Servicios (luz/agua/gas)")*(MONTH(Gastos!A4:A503)=9)*(YEAR(Gastos!A4:A503)=Dashboard!C4)*Gastos!D4:D503),0) | L6: =IFERROR(SUMPRODUCT((Gastos!C4:C503="Servicios (luz/agua/gas)")*(MONTH(Gastos!A4:A503)=10)*(YEAR(Gastos!A4:A503)=Dashboard!C4)*Gastos!D4:D503),0) | M6: =IFERROR(SUMPRODUCT((Gastos!C4:C503="Servicios (luz/agua/gas)")*(MONTH(Gastos!A4:A503)=11)*(YEAR(Gastos!A4:A503)=Dashboard!C4)*Gastos!D4:D503),0) | N6: =IFERROR(SUMPRODUCT((Gastos!C4:C503="Servicios (luz/agua/gas)")*(MONTH(Gastos!A4:A503)=12)*(YEAR(Gastos!A4:A503)=Dashboard!C4)*Gastos!D4:D503),0)
B7: Internet/Telefono | C7: =IFERROR(SUMPRODUCT((Gastos!C4:C503="Internet/Telefono")*(MONTH(Gastos!A4:A503)=1)*(YEAR(Gastos!A4:A503)=Dashboard!C4)*Gastos!D4:D503),0) | D7: =IFERROR(SUMPRODUCT((Gastos!C4:C503="Internet/Telefono")*(MONTH(Gastos!A4:A503)=2)*(YEAR(Gastos!A4:A503)=Dashboard!C4)*Gastos!D4:D503),0) | E7: =IFERROR(SUMPRODUCT((Gastos!C4:C503="Internet/Telefono")*(MONTH(Gastos!A4:A503)=3)*(YEAR(Gastos!A4:A503)=Dashboard!C4)*Gastos!D4:D503),0) | F7: =IFERROR(SUMPRODUCT((Gastos!C4:C503="Internet/Telefono")*(MONTH(Gastos!A4:A503)=4)*(YEAR(Gastos!A4:A503)=Dashboard!C4)*Gastos!D4:D503),0) | G7: =IFERROR(SUMPRODUCT((Gastos!C4:C503="Internet/Telefono")*(MONTH(Gastos!A4:A503)=5)*(YEAR(Gastos!A4:A503)=Dashboard!C4)*Gastos!D4:D503),0) | H7: =IFERROR(SUMPRODUCT((Gastos!C4:C503="Internet/Telefono")*(MONTH(Gastos!A4:A503)=6)*(YEAR(Gastos!A4:A503)=Dashboard!C4)*Gastos!D4:D503),0) | I7: =IFERROR(SUMPRODUCT((Gastos!C4:C503="Internet/Telefono")*(MONTH(Gastos!A4:A503)=7)*(YEAR(Gastos!A4:A503)=Dashboard!C4)*Gastos!D4:D503),0) | J7: =IFERROR(SUMPRODUCT((Gastos!C4:C503="Internet/Telefono")*(MONTH(Gastos!A4:A503)=8)*(YEAR(Gastos!A4:A503)=Dashboard!C4)*Gastos!D4:D503),0) | K7: =IFERROR(SUMPRODUCT((Gastos!C4:C503="Internet/Telefono")*(MONTH(Gastos!A4:A503)=9)*(YEAR(Gastos!A4:A503)=Dashboard!C4)*Gastos!D4:D503),0) | L7: =IFERROR(SUMPRODUCT((Gastos!C4:C503="Internet/Telefono")*(MONTH(Gastos!A4:A503)=10)*(YEAR(Gastos!A4:A503)=Dashboard!C4)*Gastos!D4:D503),0) | M7: =IFERROR(SUMPRODUCT((Gastos!C4:C503="Internet/Telefono")*(MONTH(Gastos!A4:A503)=11)*(YEAR(Gastos!A4:A503)=Dashboard!C4)*Gastos!D4:D503),0) | N7: =IFERROR(SUMPRODUCT((Gastos!C4:C503="Internet/Telefono")*(MONTH(Gastos!A4:A503)=12)*(YEAR(Gastos!A4:A503)=Dashboard!C4)*Gastos!D4:D503),0)
B8: Sueldos y Salarios | C8: =IFERROR(SUMPRODUCT((Gastos!C4:C503="Sueldos y Salarios")*(MONTH(Gastos!A4:A503)=1)*(YEAR(Gastos!A4:A503)=Dashboard!C4)*Gastos!D4:D503),0) | D8: =IFERROR(SUMPRODUCT((Gastos!C4:C503="Sueldos y Salarios")*(MONTH(Gastos!A4:A503)=2)*(YEAR(Gastos!A4:A503)=Dashboard!C4)*Gastos!D4:D503),0) | E8: =IFERROR(SUMPRODUCT((Gastos!C4:C503="Sueldos y Salarios")*(MONTH(Gastos!A4:A503)=3)*(YEAR(Gastos!A4:A503)=Dashboard!C4)*Gastos!D4:D503),0) | F8: =IFERROR(SUMPRODUCT((Gastos!C4:C503="Sueldos y Salarios")*(MONTH(Gastos!A4:A503)=4)*(YEAR(Gastos!A4:A503)=Dashboard!C4)*Gastos!D4:D503),0) | G8: =IFERROR(SUMPRODUCT((Gastos!C4:C503="Sueldos y Salarios")*(MONTH(Gastos!A4:A503)=5)*(YEAR(Gastos!A4:A503)=Dashboard!C4)*Gastos!D4:D503),0) | H8: =IFERROR(SUMPRODUCT((Gastos!C4:C503="Sueldos y Salarios")*(MONTH(Gastos!A4:A503)=6)*(YEAR(Gastos!A4:A503)=Dashboard!C4)*Gastos!D4:D503),0) | I8: =IFERROR(SUMPRODUCT((Gastos!C4:C503="Sueldos y Salarios")*(MONTH(Gastos!A4:A503)=7)*(YEAR(Gastos!A4:A503)=Dashboard!C4)*Gastos!D4:D503),0) | J8: =IFERROR(SUMPRODUCT((Gastos!C4:C503="Sueldos y Salarios")*(MONTH(Gastos!A4:A503)=8)*(YEAR(Gastos!A4:A503)=Dashboard!C4)*Gastos!D4:D503),0) | K8: =IFERROR(SUMPRODUCT((Gastos!C4:C503="Sueldos y Salarios")*(MONTH(Gastos!A4:A503)=9)*(YEAR(Gastos!A4:A503)=Dashboard!C4)*Gastos!D4:D503),0) | L8: =IFERROR(SUMPRODUCT((Gastos!C4:C503="Sueldos y Salarios")*(MONTH(Gastos!A4:A503)=10)*(YEAR(Gastos!A4:A503)=Dashboard!C4)*Gastos!D4:D503),0) | M8: =IFERROR(SUMPRODUCT((Gastos!C4:C503="Sueldos y Salarios")*(MONTH(Gastos!A4:A503)=11)*(YEAR(Gastos!A4:A503)=Dashboard!C4)*Gastos!D4:D503),0) | N8: =IFERROR(SUMPRODUCT((Gastos!C4:C503="Sueldos y Salarios")*(MONTH(Gastos!A4:A503)=12)*(YEAR(Gastos!A4:A503)=Dashboard!C4)*Gastos!D4:D503),0)
B9: Seguro Social | C9: =IFERROR(SUMPRODUCT((Gastos!C4:C503="Seguro Social")*(MONTH(Gastos!A4:A503)=1)*(YEAR(Gastos!A4:A503)=Dashboard!C4)*Gastos!D4:D503),0) | D9: =IFERROR(SUMPRODUCT((Gastos!C4:C503="Seguro Social")*(MONTH(Gastos!A4:A503)=2)*(YEAR(Gastos!A4:A503)=Dashboard!C4)*Gastos!D4:D503),0) | E9: =IFERROR(SUMPRODUCT((Gastos!C4:C503="Seguro Social")*(MONTH(Gastos!A4:A503)=3)*(YEAR(Gastos!A4:A503)=Dashboard!C4)*Gastos!D4:D503),0) | F9: =IFERROR(SUMPRODUCT((Gastos!C4:C503="Seguro Social")*(MONTH(Gastos!A4:A503)=4)*(YEAR(Gastos!A4:A503)=Dashboard!C4)*Gastos!D4:D503),0) | G9: =IFERROR(SUMPRODUCT((Gastos!C4:C503="Seguro Social")*(MONTH(Gastos!A4:A503)=5)*(YEAR(Gastos!A4:A503)=Dashboard!C4)*Gastos!D4:D503),0) | H9: =IFERROR(SUMPRODUCT((Gastos!C4:C503="Seguro Social")*(MONTH(Gastos!A4:A503)=6)*(YEAR(Gastos!A4:A503)=Dashboard!C4)*Gastos!D4:D503),0) | I9: =IFERROR(SUMPRODUCT((Gastos!C4:C503="Seguro Social")*(MONTH(Gastos!A4:A503)=7)*(YEAR(Gastos!A4:A503)=Dashboard!C4)*Gastos!D4:D503),0) | J9: =IFERROR(SUMPRODUCT((Gastos!C4:C503="Seguro Social")*(MONTH(Gastos!A4:A503)=8)*(YEAR(Gastos!A4:A503)=Dashboard!C4)*Gastos!D4:D503),0) | K9: =IFERROR(SUMPRODUCT((Gastos!C4:C503="Seguro Social")*(MONTH(Gastos!A4:A503)=9)*(YEAR(Gastos!A4:A503)=Dashboard!C4)*Gastos!D4:D503),0) | L9: =IFERROR(SUMPRODUCT((Gastos!C4:C503="Seguro Social")*(MONTH(Gastos!A4:A503)=10)*(YEAR(Gastos!A4:A503)=Dashboard!C4)*Gastos!D4:D503),0) | M9: =IFERROR(SUMPRODUCT((Gastos!C4:C503="Seguro Social")*(MONTH(Gastos!A4:A503)=11)*(YEAR(Gastos!A4:A503)=Dashboard!C4)*Gastos!D4:D503),0) | N9: =IFERROR(SUMPRODUCT((Gastos!C4:C503="Seguro Social")*(MONTH(Gastos!A4:A503)=12)*(YEAR(Gastos!A4:A503)=Dashboard!C4)*Gastos!D4:D503),0)
B10: Material de Oficina | C10: =IFERROR(SUMPRODUCT((Gastos!C4:C503="Material de Oficina")*(MONTH(Gastos!A4:A503)=1)*(YEAR(Gastos!A4:A503)=Dashboard!C4)*Gastos!D4:D503),0) | D10: =IFERROR(SUMPRODUCT((Gastos!C4:C503="Material de Oficina")*(MONTH(Gastos!A4:A503)=2)*(YEAR(Gastos!A4:A503)=Dashboard!C4)*Gastos!D4:D503),0) | E10: =IFERROR(SUMPRODUCT((Gastos!C4:C503="Material de Oficina")*(MONTH(Gastos!A4:A503)=3)*(YEAR(Gastos!A4:A503)=Dashboard!C4)*Gastos!D4:D503),0) | F10: =IFERROR(SUMPRODUCT((Gastos!C4:C503="Material de Oficina")*(MONTH(Gastos!A4:A503)=4)*(YEAR(Gastos!A4:A503)=Dashboard!C4)*Gastos!D4:D503),0) | G10: =IFERROR(SUMPRODUCT((Gastos!C4:C503="Material de Oficina")*(MONTH(Gastos!A4:A503)=5)*(YEAR(Gastos!A4:A503)=Dashboard!C4)*Gastos!D4:D503),0) | H10: =IFERROR(SUMPRODUCT((Gastos!C4:C503="Material de Oficina")*(MONTH(Gastos!A4:A503)=6)*(YEAR(Gastos!A4:A503)=Dashboard!C4)*Gastos!D4:D503),0) | I10: =IFERROR(SUMPRODUCT((Gastos!C4:C503="Material de Oficina")*(MONTH(Gastos!A4:A503)=7)*(YEAR(Gastos!A4:A503)=Dashboard!C4)*Gastos!D4:D503),0) | J10: =IFERROR(SUMPRODUCT((Gastos!C4:C503="Material de Oficina")*(MONTH(Gastos!A4:A503)=8)*(YEAR(Gastos!A4:A503)=Dashboard!C4)*Gastos!D4:D503),0) | K10: =IFERROR(SUMPRODUCT((Gastos!C4:C503="Material de Oficina")*(MONTH(Gastos!A4:A503)=9)*(YEAR(Gastos!A4:A503)=Dashboard!C4)*Gastos!D4:D503),0) | L10: =IFERROR(SUMPRODUCT((Gastos!C4:C503="Material de Oficina")*(MONTH(Gastos!A4:A503)=10)*(YEAR(Gastos!A4:A503)=Dashboard!C4)*Gastos!D4:D503),0) | M10: =IFERROR(SUMPRODUCT((Gastos!C4:C503="Material de Oficina")*(MONTH(Gastos!A4:A503)=11)*(YEAR(Gastos!A4:A503)=Dashboard!C4)*Gastos!D4:D503),0) | N10: =IFERROR(SUMPRODUCT((Gastos!C4:C503="Material de Oficina")*(MONTH(Gastos!A4:A503)=12)*(YEAR(Gastos!A4:A503)=Dashboard!C4)*Gastos!D4:D503),0)
B11: Publicidad/Marketing | C11: =IFERROR(SUMPRODUCT((Gastos!C4:C503="Publicidad/Marketing")*(MONTH(Gastos!A4:A503)=1)*(YEAR(Gastos!A4:A503)=Dashboard!C4)*Gastos!D4:D503),0) | D11: =IFERROR(SUMPRODUCT((Gastos!C4:C503="Publicidad/Marketing")*(MONTH(Gastos!A4:A503)=2)*(YEAR(Gastos!A4:A503)=Dashboard!C4)*Gastos!D4:D503),0) | E11: =IFERROR(SUMPRODUCT((Gastos!C4:C503="Publicidad/Marketing")*(MONTH(Gastos!A4:A503)=3)*(YEAR(Gastos!A4:A503)=Dashboard!C4)*Gastos!D4:D503),0) | F11: =IFERROR(SUMPRODUCT((Gastos!C4:C503="Publicidad/Marketing")*(MONTH(Gastos!A4:A503)=4)*(YEAR(Gastos!A4:A503)=Dashboard!C4)*Gastos!D4:D503),0) | G11: =IFERROR(SUMPRODUCT((Gastos!C4:C503="Publicidad/Marketing")*(MONTH(Gastos!A4:A503)=5)*(YEAR(Gastos!A4:A503)=Dashboard!C4)*Gastos!D4:D503),0) | H11: =IFERROR(SUMPRODUCT((Gastos!C4:C503="Publicidad/Marketing")*(MONTH(Gastos!A4:A503)=6)*(YEAR(Gastos!A4:A503)=Dashboard!C4)*Gastos!D4:D503),0) | I11: =IFERROR(SUMPRODUCT((Gastos!C4:C503="Publicidad/Marketing")*(MONTH(Gastos!A4:A503)=7)*(YEAR(Gastos!A4:A503)=Dashboard!C4)*Gastos!D4:D503),0) | J11: =IFERROR(SUMPRODUCT((Gastos!C4:C503="Publicidad/Marketing")*(MONTH(Gastos!A4:A503)=8)*(YEAR(Gastos!A4:A503)=Dashboard!C4)*Gastos!D4:D503),0) | K11: =IFERROR(SUMPRODUCT((Gastos!C4:C503="Publicidad/Marketing")*(MONTH(Gastos!A4:A503)=9)*(YEAR(Gastos!A4:A503)=Dashboard!C4)*Gastos!D4:D503),0) | L11: =IFERROR(SUMPRODUCT((Gastos!C4:C503="Publicidad/Marketing")*(MONTH(Gastos!A4:A503)=10)*(YEAR(Gastos!A4:A503)=Dashboard!C4)*Gastos!D4:D503),0) | M11: =IFERROR(SUMPRODUCT((Gastos!C4:C503="Publicidad/Marketing")*(MONTH(Gastos!A4:A503)=11)*(YEAR(Gastos!A4:A503)=Dashboard!C4)*Gastos!D4:D503),0) | N11: =IFERROR(SUMPRODUCT((Gastos!C4:C503="Publicidad/Marketing")*(MONTH(Gastos!A4:A503)=12)*(YEAR(Gastos!A4:A503)=Dashboard!C4)*Gastos!D4:D503),0)
B12: Transporte/Combustible | C12: =IFERROR(SUMPRODUCT((Gastos!C4:C503="Transporte/Combustible")*(MONTH(Gastos!A4:A503)=1)*(YEAR(Gastos!A4:A503)=Dashboard!C4)*Gastos!D4:D503),0) | D12: =IFERROR(SUMPRODUCT((Gastos!C4:C503="Transporte/Combustible")*(MONTH(Gastos!A4:A503)=2)*(YEAR(Gastos!A4:A503)=Dashboard!C4)*Gastos!D4:D503),0) | E12: =IFERROR(SUMPRODUCT((Gastos!C4:C503="Transporte/Combustible")*(MONTH(Gastos!A4:A503)=3)*(YEAR(Gastos!A4:A503)=Dashboard!C4)*Gastos!D4:D503),0) | F12: =IFERROR(SUMPRODUCT((Gastos!C4:C503="Transporte/Combustible")*(MONTH(Gastos!A4:A503)=4)*(YEAR(Gastos!A4:A503)=Dashboard!C4)*Gastos!D4:D503),0) | G12: =IFERROR(SUMPRODUCT((Gastos!C4:C503="Transporte/Combustible")*(MONTH(Gastos!A4:A503)=5)*(YEAR(Gastos!A4:A503)=Dashboard!C4)*Gastos!D4:D503),0) | H12: =IFERROR(SUMPRODUCT((Gastos!C4:C503="Transporte/Combustible")*(MONTH(Gastos!A4:A503)=6)*(YEAR(Gastos!A4:A503)=Dashboard!C4)*Gastos!D4:D503),0) | I12: =IFERROR(SUMPRODUCT((Gastos!C4:C503="Transporte/Combustible")*(MONTH(Gastos!A4:A503)=7)*(YEAR(Gastos!A4:A503)=Dashboard!C4)*Gastos!D4:D503),0) | J12: =IFERROR(SUMPRODUCT((Gastos!C4:C503="Transporte/Combustible")*(MONTH(Gastos!A4:A503)=8)*(YEAR(Gastos!A4:A503)=Dashboard!C4)*Gastos!D4:D503),0) | K12: =IFERROR(SUMPRODUCT((Gastos!C4:C503="Transporte/Combustible")*(MONTH(Gastos!A4:A503)=9)*(YEAR(Gastos!A4:A503)=Dashboard!C4)*Gastos!D4:D503),0) | L12: =IFERROR(SUMPRODUCT((Gastos!C4:C503="Transporte/Combustible")*(MONTH(Gastos!A4:A503)=10)*(YEAR(Gastos!A4:A503)=Dashboard!C4)*Gastos!D4:D503),0) | M12: =IFERROR(SUMPRODUCT((Gastos!C4:C503="Transporte/Combustible")*(MONTH(Gastos!A4:A503)=11)*(YEAR(Gastos!A4:A503)=Dashboard!C4)*Gastos!D4:D503),0) | N12: =IFERROR(SUMPRODUCT((Gastos!C4:C503="Transporte/Combustible")*(MONTH(Gastos!A4:A503)=12)*(YEAR(Gastos!A4:A503)=Dashboard!C4)*Gastos!D4:D503),0)
B13: Mantenimiento | C13: =IFERROR(SUMPRODUCT((Gastos!C4:C503="Mantenimiento")*(MONTH(Gastos!A4:A503)=1)*(YEAR(Gastos!A4:A503)=Dashboard!C4)*Gastos!D4:D503),0) | D13: =IFERROR(SUMPRODUCT((Gastos!C4:C503="Mantenimiento")*(MONTH(Gastos!A4:A503)=2)*(YEAR(Gastos!A4:A503)=Dashboard!C4)*Gastos!D4:D503),0) | E13: =IFERROR(SUMPRODUCT((Gastos!C4:C503="Mantenimiento")*(MONTH(Gastos!A4:A503)=3)*(YEAR(Gastos!A4:A503)=Dashboard!C4)*Gastos!D4:D503),0) | F13: =IFERROR(SUMPRODUCT((Gastos!C4:C503="Mantenimiento")*(MONTH(Gastos!A4:A503)=4)*(YEAR(Gastos!A4:A503)=Dashboard!C4)*Gastos!D4:D503),0) | G13: =IFERROR(SUMPRODUCT((Gastos!C4:C503="Mantenimiento")*(MONTH(Gastos!A4:A503)=5)*(YEAR(Gastos!A4:A503)=Dashboard!C4)*Gastos!D4:D503),0) | H13: =IFERROR(SUMPRODUCT((Gastos!C4:C503="Mantenimiento")*(MONTH(Gastos!A4:A503)=6)*(YEAR(Gastos!A4:A503)=Dashboard!C4)*Gastos!D4:D503),0) | I13: =IFERROR(SUMPRODUCT((Gastos!C4:C503="Mantenimiento")*(MONTH(Gastos!A4:A503)=7)*(YEAR(Gastos!A4:A503)=Dashboard!C4)*Gastos!D4:D503),0) | J13: =IFERROR(SUMPRODUCT((Gastos!C4:C503="Mantenimiento")*(MONTH(Gastos!A4:A503)=8)*(YEAR(Gastos!A4:A503)=Dashboard!C4)*Gastos!D4:D503),0) | K13: =IFERROR(SUMPRODUCT((Gastos!C4:C503="Mantenimiento")*(MONTH(Gastos!A4:A503)=9)*(YEAR(Gastos!A4:A503)=Dashboard!C4)*Gastos!D4:D503),0) | L13: =IFERROR(SUMPRODUCT((Gastos!C4:C503="Mantenimiento")*(MONTH(Gastos!A4:A503)=10)*(YEAR(Gastos!A4:A503)=Dashboard!C4)*Gastos!D4:D503),0) | M13: =IFERROR(SUMPRODUCT((Gastos!C4:C503="Mantenimiento")*(MONTH(Gastos!A4:A503)=11)*(YEAR(Gastos!A4:A503)=Dashboard!C4)*Gastos!D4:D503),0) | N13: =IFERROR(SUMPRODUCT((Gastos!C4:C503="Mantenimiento")*(MONTH(Gastos!A4:A503)=12)*(YEAR(Gastos!A4:A503)=Dashboard!C4)*Gastos!D4:D503),0)
B14: Seguros | C14: =IFERROR(SUMPRODUCT((Gastos!C4:C503="Seguros")*(MONTH(Gastos!A4:A503)=1)*(YEAR(Gastos!A4:A503)=Dashboard!C4)*Gastos!D4:D503),0) | D14: =IFERROR(SUMPRODUCT((Gastos!C4:C503="Seguros")*(MONTH(Gastos!A4:A503)=2)*(YEAR(Gastos!A4:A503)=Dashboard!C4)*Gastos!D4:D503),0) | E14: =IFERROR(SUMPRODUCT((Gastos!C4:C503="Seguros")*(MONTH(Gastos!A4:A503)=3)*(YEAR(Gastos!A4:A503)=Dashboard!C4)*Gastos!D4:D503),0) | F14: =IFERROR(SUMPRODUCT((Gastos!C4:C503="Seguros")*(MONTH(Gastos!A4:A503)=4)*(YEAR(Gastos!A4:A503)=Dashboard!C4)*Gastos!D4:D503),0) | G14: =IFERROR(SUMPRODUCT((Gastos!C4:C503="Seguros")*(MONTH(Gastos!A4:A503)=5)*(YEAR(Gastos!A4:A503)=Dashboard!C4)*Gastos!D4:D503),0) | H14: =IFERROR(SUMPRODUCT((Gastos!C4:C503="Seguros")*(MONTH(Gastos!A4:A503)=6)*(YEAR(Gastos!A4:A503)=Dashboard!C4)*Gastos!D4:D503),0) | I14: =IFERROR(SUMPRODUCT((Gastos!C4:C503="Seguros")*(MONTH(Gastos!A4:A503)=7)*(YEAR(Gastos!A4:A503)=Dashboard!C4)*Gastos!D4:D503),0) | J14: =IFERROR(SUMPRODUCT((Gastos!C4:C503="Seguros")*(MONTH(Gastos!A4:A503)=8)*(YEAR(Gastos!A4:A503)=Dashboard!C4)*Gastos!D4:D503),0) | K14: =IFERROR(SUMPRODUCT((Gastos!C4:C503="Seguros")*(MONTH(Gastos!A4:A503)=9)*(YEAR(Gastos!A4:A503)=Dashboard!C4)*Gastos!D4:D503),0) | L14: =IFERROR(SUMPRODUCT((Gastos!C4:C503="Seguros")*(MONTH(Gastos!A4:A503)=10)*(YEAR(Gastos!A4:A503)=Dashboard!C4)*Gastos!D4:D503),0) | M14: =IFERROR(SUMPRODUCT((Gastos!C4:C503="Seguros")*(MONTH(Gastos!A4:A503)=11)*(YEAR(Gastos!A4:A503)=Dashboard!C4)*Gastos!D4:D503),0) | N14: =IFERROR(SUMPRODUCT((Gastos!C4:C503="Seguros")*(MONTH(Gastos!A4:A503)=12)*(YEAR(Gastos!A4:A503)=Dashboard!C4)*Gastos!D4:D503),0)
B15: Impuestos/Patentes | C15: =IFERROR(SUMPRODUCT((Gastos!C4:C503="Impuestos/Patentes")*(MONTH(Gastos!A4:A503)=1)*(YEAR(Gastos!A4:A503)=Dashboard!C4)*Gastos!D4:D503),0) | D15: =IFERROR(SUMPRODUCT((Gastos!C4:C503="Impuestos/Patentes")*(MONTH(Gastos!A4:A503)=2)*(YEAR(Gastos!A4:A503)=Dashboard!C4)*Gastos!D4:D503),0) | E15: =IFERROR(SUMPRODUCT((Gastos!C4:C503="Impuestos/Patentes")*(MONTH(Gastos!A4:A503)=3)*(YEAR(Gastos!A4:A503)=Dashboard!C4)*Gastos!D4:D503),0) | F15: =IFERROR(SUMPRODUCT((Gastos!C4:C503="Impuestos/Patentes")*(MONTH(Gastos!A4:A503)=4)*(YEAR(Gastos!A4:A503)=Dashboard!C4)*Gastos!D4:D503),0) | G15: =IFERROR(SUMPRODUCT((Gastos!C4:C503="Impuestos/Patentes")*(MONTH(Gastos!A4:A503)=5)*(YEAR(Gastos!A4:A503)=Dashboard!C4)*Gastos!D4:D503),0) | H15: =IFERROR(SUMPRODUCT((Gastos!C4:C503="Impuestos/Patentes")*(MONTH(Gastos!A4:A503)=6)*(YEAR(Gastos!A4:A503)=Dashboard!C4)*Gastos!D4:D503),0) | I15: =IFERROR(SUMPRODUCT((Gastos!C4:C503="Impuestos/Patentes")*(MONTH(Gastos!A4:A503)=7)*(YEAR(Gastos!A4:A503)=Dashboard!C4)*Gastos!D4:D503),0) | J15: =IFERROR(SUMPRODUCT((Gastos!C4:C503="Impuestos/Patentes")*(MONTH(Gastos!A4:A503)=8)*(YEAR(Gastos!A4:A503)=Dashboard!C4)*Gastos!D4:D503),0) | K15: =IFERROR(SUMPRODUCT((Gastos!C4:C503="Impuestos/Patentes")*(MONTH(Gastos!A4:A503)=9)*(YEAR(Gastos!A4:A503)=Dashboard!C4)*Gastos!D4:D503),0) | L15: =IFERROR(SUMPRODUCT((Gastos!C4:C503="Impuestos/Patentes")*(MONTH(Gastos!A4:A503)=10)*(YEAR(Gastos!A4:A503)=Dashboard!C4)*Gastos!D4:D503),0) | M15: =IFERROR(SUMPRODUCT((Gastos!C4:C503="Impuestos/Patentes")*(MONTH(Gastos!A4:A503)=11)*(YEAR(Gastos!A4:A503)=Dashboard!C4)*Gastos!D4:D503),0) | N15: =IFERROR(SUMPRODUCT((Gastos!C4:C503="Impuestos/Patentes")*(MONTH(Gastos!A4:A503)=12)*(YEAR(Gastos!A4:A503)=Dashboard!C4)*Gastos!D4:D503),0)
B16: Otros Gastos | C16: =IFERROR(SUMPRODUCT((Gastos!C4:C503="Otros Gastos")*(MONTH(Gastos!A4:A503)=1)*(YEAR(Gastos!A4:A503)=Dashboard!C4)*Gastos!D4:D503),0) | D16: =IFERROR(SUMPRODUCT((Gastos!C4:C503="Otros Gastos")*(MONTH(Gastos!A4:A503)=2)*(YEAR(Gastos!A4:A503)=Dashboard!C4)*Gastos!D4:D503),0) | E16: =IFERROR(SUMPRODUCT((Gastos!C4:C503="Otros Gastos")*(MONTH(Gastos!A4:A503)=3)*(YEAR(Gastos!A4:A503)=Dashboard!C4)*Gastos!D4:D503),0) | F16: =IFERROR(SUMPRODUCT((Gastos!C4:C503="Otros Gastos")*(MONTH(Gastos!A4:A503)=4)*(YEAR(Gastos!A4:A503)=Dashboard!C4)*Gastos!D4:D503),0) | G16: =IFERROR(SUMPRODUCT((Gastos!C4:C503="Otros Gastos")*(MONTH(Gastos!A4:A503)=5)*(YEAR(Gastos!A4:A503)=Dashboard!C4)*Gastos!D4:D503),0) | H16: =IFERROR(SUMPRODUCT((Gastos!C4:C503="Otros Gastos")*(MONTH(Gastos!A4:A503)=6)*(YEAR(Gastos!A4:A503)=Dashboard!C4)*Gastos!D4:D503),0) | I16: =IFERROR(SUMPRODUCT((Gastos!C4:C503="Otros Gastos")*(MONTH(Gastos!A4:A503)=7)*(YEAR(Gastos!A4:A503)=Dashboard!C4)*Gastos!D4:D503),0) | J16: =IFERROR(SUMPRODUCT((Gastos!C4:C503="Otros Gastos")*(MONTH(Gastos!A4:A503)=8)*(YEAR(Gastos!A4:A503)=Dashboard!C4)*Gastos!D4:D503),0) | K16: =IFERROR(SUMPRODUCT((Gastos!C4:C503="Otros Gastos")*(MONTH(Gastos!A4:A503)=9)*(YEAR(Gastos!A4:A503)=Dashboard!C4)*Gastos!D4:D503),0) | L16: =IFERROR(SUMPRODUCT((Gastos!C4:C503="Otros Gastos")*(MONTH(Gastos!A4:A503)=10)*(YEAR(Gastos!A4:A503)=Dashboard!C4)*Gastos!D4:D503),0) | M16: =IFERROR(SUMPRODUCT((Gastos!C4:C503="Otros Gastos")*(MONTH(Gastos!A4:A503)=11)*(YEAR(Gastos!A4:A503)=Dashboard!C4)*Gastos!D4:D503),0) | N16: =IFERROR(SUMPRODUCT((Gastos!C4:C503="Otros Gastos")*(MONTH(Gastos!A4:A503)=12)*(YEAR(Gastos!A4:A503)=Dashboard!C4)*Gastos!D4:D503),0)

Sheet Config
A1: v1.0.0
A3: CONFIGURACION
A5: Producto | B5: Control de Gastos Operativos
A6: Version | B6: v1.0.0
A7: Marca | B7: No Somos Ignorantes
A8: Precio | B8: Bs. 59
A9: Proteccion | B9: nsi2024
A11: INSTRUCCIONES
A12: 1. | B12: Las celdas AMARILLAS son editables.
A13: 2. | B13: En 'Gastos', registra cada gasto con fecha, descripcion y categoria.
A14: 3. | B14: En 'Presupuesto', define tu presupuesto mensual por categoria.
A15: 4. | B15: El Dashboard muestra KPIs, graficos de tendencia y comparacion real vs presupuesto.
A16: 5. | B16: La hoja 'Tendencias' muestra la evolucion mensual por categoria.
A17: 6. | B17: Para desbloquear: Revisar -> Desproteger hoja -> nsi2024
