Workbook

Sheet Dashboard
B2: ESTADOS FINANCIEROS - PANEL EJECUTIVO
B3: No Somos Ignorantes | v1.0 | Balance + Resultados + Flujo de Caja
B4: Periodo: | C4: Enero - Diciembre 2025
B6: TOTAL ACTIVOS (Bs.) | F6: UTILIDAD NETA (Bs.)
B7: =BalanceGeneral!C20 | F7: =EstadoResultados!C27
B9: ROE (Retorno sobre Patrimonio) | F9: RAZON CORRIENTE
B10: =Razones!C5 | F10: =Razones!C8
B12: =IF(ABS(BalanceGeneral!C20-BalanceGeneral!C38)<0.01,"BALANCE CUADRA: Activos = Pasivos + Patrimonio","ERROR: EL BALANCE NO CUADRA")
B14: COMPOSICION DE ACTIVOS | F14: ESTADO DE RESULTADOS
B15: Tipo | C15: Monto | F15: Concepto | G15: Monto
B16: Activo Corriente | C16: =BalanceGeneral!C11 | F16: Ingresos | G16: =EstadoResultados!C7
B17: Activo No Corriente | C17: =BalanceGeneral!C19 | F17: Costo Ventas | G17: =EstadoResultados!C10
F18: Gastos Op. | G18: =EstadoResultados!C21
F19: Utilidad Neta | G19: =EstadoResultados!C27

Sheet PlanCuentas
A1: PLAN DE CUENTAS
A3: CODIGO | B3: CUENTA | C3: TIPO | D3: NATURALEZA
A4: 1000 | B4: ACTIVOS | C4: Titulo
A5: 1100 | B5: Activo Corriente | C5: Subtitulo
A6: 1110 | B6: Caja y Bancos | C6: Activo | D6: Deudora
A7: 1120 | B7: Cuentas por Cobrar | C7: Activo | D7: Deudora
A8: 1130 | B8: Inventarios | C8: Activo | D8: Deudora
A9: 1140 | B9: Anticipos y Prepagados | C9: Activo | D9: Deudora
A10: 1200 | B10: Activo No Corriente | C10: Subtitulo
A11: 1210 | B11: Propiedad, Planta y Equipo | C11: Activo | D11: Deudora
A12: 1220 | B12: Depreciacion Acumulada | C12: Activo | D12: Acreedora
A13: 1230 | B13: Intangibles | C13: Activo | D13: Deudora
A14: 2000 | B14: PASIVOS | C14: Titulo
A15: 2100 | B15: Pasivo Corriente | C15: Subtitulo
A16: 2110 | B16: Cuentas por Pagar | C16: Pasivo | D16: Acreedora
A17: 2120 | B17: Sueldos por Pagar | C17: Pasivo | D17: Acreedora
A18: 2130 | B18: Impuestos por Pagar | C18: Pasivo | D18: Acreedora
A19: 2140 | B19: Deudas a Corto Plazo | C19: Pasivo | D19: Acreedora
A20: 2200 | B20: Pasivo No Corriente | C20: Subtitulo
A21: 2210 | B21: Deudas a Largo Plazo | C21: Pasivo | D21: Acreedora
A22: 3000 | B22: PATRIMONIO | C22: Titulo
A23: 3100 | B23: Capital Social | C23: Patrimonio | D23: Acreedora
A24: 3200 | B24: Reservas | C24: Patrimonio | D24: Acreedora
A25: 3300 | B25: Utilidades Retenidas | C25: Patrimonio | D25: Acreedora
A26: 3400 | B26: Resultado del Ejercicio | C26: Patrimonio | D26: Acreedora
A27: 4000 | B27: INGRESOS | C27: Titulo
A28: 4100 | B28: Ventas | C28: Ingreso | D28: Acreedora
A29: 4200 | B29: Otros Ingresos | C29: Ingreso | D29: Acreedora
A30: 4300 | B30: Ingresos Financieros | C30: Ingreso | D30: Acreedora
A31: 5000 | B31: COSTOS | C31: Titulo
A32: 5100 | B32: Costo de Ventas | C32: Costo | D32: Deudora
A33: 6000 | B33: GASTOS OPERATIVOS | C33: Titulo
A34: 6100 | B34: Sueldos y Salarios | C34: Gasto | D34: Deudora
A35: 6200 | B35: Alquiler | C35: Gasto | D35: Deudora
A36: 6300 | B36: Servicios Basicos | C36: Gasto | D36: Deudora
A37: 6400 | B37: Depreciacion | C37: Gasto | D37: Deudora
A38: 6500 | B38: Publicidad y Marketing | C38: Gasto | D38: Deudora
A39: 6600 | B39: Otros Gastos Operativos | C39: Gasto | D39: Deudora
A40: 7000 | B40: GASTOS FINANCIEROS | C40: Titulo
A41: 7100 | B41: Intereses Pagados | C41: Gasto | D41: Deudora
...

Sheet BalanceGeneral
B1: ESTADO DE SITUACION FINANCIERA
B2: ="Al "&Dashboard!C4
B4: ACTIVOS
B5: Activo Corriente
B6: Caja y Bancos | C6: 25000
B7: Cuentas por Cobrar | C7: 15000
B8: Inventarios | C8: 30000
B9: Anticipos y Prepagados | C9: 5000
B11: Total Activo Corriente | C11: =SUM(C6:C9)
B13: Activo No Corriente
B14: Propiedad, Planta y Equipo | C14: 150000
B15: (-) Depreciacion Acumulada | C15: -30000
B16: Intangibles | C16: 10000
B19: Total Activo No Corriente | C19: =SUM(C14:C16)
B20: TOTAL ACTIVOS | C20: =C11+C19
B22: PASIVOS Y PATRIMONIO
B23: Pasivo Corriente
B24: Cuentas por Pagar | C24: 20000
B25: Sueldos por Pagar | C25: 5000
B26: Impuestos por Pagar | C26: 3000
B27: Deudas a Corto Plazo | C27: 15000
B28: Total Pasivo Corriente | C28: =SUM(C24:C27)
B29: Pasivo No Corriente
B30: Deudas a Largo Plazo | C30: 50000
B31: TOTAL PASIVOS | C31: =C28+C30
B32: Patrimonio
B33: Capital Social | C33: 80000
B34: Reservas | C34: 5000
B35: Utilidades Retenidas | C35: 17000
B36: Resultado del Ejercicio | C36: =EstadoResultados!C27
B37: TOTAL PATRIMONIO | C37: =SUM(C33:C36)
B38: TOTAL PASIVOS + PATRIMONIO | C38: =C31+C37
B39: =IF(ABS(C20-C38)<0.01,"CUADRA: Activos = Pasivos + Patrimonio","ERROR: NO CUADRA")

Sheet EstadoResultados
B1: ESTADO DE RESULTADOS
B2: ="Periodo: "&Dashboard!C4
B4: INGRESOS
B5: Ventas Netas | C5: 350000
B6: Otros Ingresos | C6: 8000
B7: TOTAL INGRESOS | C7: =SUM(C5:C6)
B9: COSTO DE VENTAS
B10: Costo de Ventas | C10: 180000
B12: UTILIDAD BRUTA | C12: =C7-C10
B14: GASTOS OPERATIVOS
B15: Sueldos y Salarios | C15: 80000
B16: Alquiler | C16: 36000
B17: Servicios Basicos | C17: 12000
B18: Depreciacion | C18: 15000
B19: Publicidad y Marketing | C19: 8000
B20: Otros Gastos Operativos | C20: 5000
B21: TOTAL GASTOS OPERATIVOS | C21: =SUM(C15:C20)
B22: UTILIDAD OPERATIVA (EBIT) | C22: =C12-C21
B24: (-) Gastos Financieros | C24: 6000
B25: UTILIDAD ANTES DE IMPUESTOS | C25: =C22-C24
B26: (-) Impuesto sobre Utilidades (25%) | C26: =IFERROR(IF(C25>0,C25*0.25,0),0)
B27: UTILIDAD NETA | C27: =C25-C26

Sheet FlujoCaja
B1: ESTADO DE FLUJO DE EFECTIVO
B2: ="Periodo: "&Dashboard!C4
B4: ACTIVIDADES DE OPERACION
B5: Utilidad Neta | C5: =EstadoResultados!C27
B6: (+) Depreciacion | C6: 15000
B7: (+/-) Cambio en Ctas por Cobrar | C7: -3000
B8: (+/-) Cambio en Inventarios | C8: 2000
B9: (+/-) Cambio en Ctas por Pagar | C9: 4000
B10: Flujo Neto de Operaciones | C10: =SUM(C5:C9)
B12: ACTIVIDADES DE INVERSION
B13: Compra de Activos Fijos | C13: -20000
B14: Venta de Activos | C14: 5000
B15: Flujo Neto de Inversion | C15: =SUM(C13:C14)
B17: ACTIVIDADES DE FINANCIAMIENTO
B18: Nuevos Prestamos | C18: 10000
B19: Pago de Prestamos | C19: -8000
B20: Aportes de Capital | C20: 0
B21: Distribucion de Dividendos | C21: -5000
B22: Flujo Neto de Financiamiento | C22: =SUM(C18:C21)
B24: AUMENTO/DISMINUCION NETO DE EFECTIVO | C24: =C10+C15+C22
B25: Efectivo al Inicio del Periodo | C25: 20000
B26: EFECTIVO AL FINAL DEL PERIODO | C26: =C24+C25

Sheet Razones
B1: RAZONES FINANCIERAS
B2: Indicadores calculados automaticamente desde el Balance y Estado de Resultados.
B3: INDICADOR | C3: VALOR | D3: INTERPRETACION
B4: RENTABILIDAD
B5: ROE (Retorno sobre Patrimonio) | C5: =IFERROR(EstadoResultados!C27/BalanceGeneral!C37,0) | D5: =IF(C5>0.15,"Excelente",IF(C5>0.08,"Bueno","Bajo"))
B6: ROA (Retorno sobre Activos) | C6: =IFERROR(EstadoResultados!C27/BalanceGeneral!C20,0) | D6: =IF(C6>0.10,"Excelente",IF(C6>0.05,"Bueno","Bajo"))
B7: LIQUIDEZ
B8: Razon Corriente | C8: =IFERROR(BalanceGeneral!C11/BalanceGeneral!C28,0) | D8: =IF(C8>2,"Holgada",IF(C8>1,"Adecuada","Riesgo"))
B9: Prueba Acida | C9: =IFERROR((BalanceGeneral!C11-BalanceGeneral!C8)/BalanceGeneral!C28,0) | D9: =IF(C9>1,"Buena",IF(C9>0.5,"Aceptable","Riesgo"))
B10: Capital de Trabajo (Bs.) | C10: =BalanceGeneral!C11-BalanceGeneral!C28 | D10: =IF(C10>0,"Positivo - Liquidez OK","Negativo - Riesgo")
B11: ENDEUDAMIENTO
B12: Razon de Endeudamiento | C12: =IFERROR(BalanceGeneral!C31/BalanceGeneral!C20,0) | D12: =IF(C12<0.4,"Conservador",IF(C12<0.6,"Moderado","Alto riesgo"))
B13: Apalancamiento (Deuda/Patrimonio) | C13: =IFERROR(BalanceGeneral!C31/BalanceGeneral!C37,0) | D13: =IF(C13<1,"Bajo apalancamiento",IF(C13<2,"Moderado","Alto"))
B14: EFICIENCIA
B15: Margen Bruto | C15: =IFERROR(EstadoResultados!C12/EstadoResultados!C7,0) | D15: =IF(C15>0.4,"Excelente",IF(C15>0.25,"Bueno","Bajo"))
B16: Margen Operativo | C16: =IFERROR(EstadoResultados!C22/EstadoResultados!C7,0) | D16: =IF(C16>0.15,"Excelente",IF(C16>0.08,"Bueno","Bajo"))
B17: Margen Neto | C17: =IFERROR(EstadoResultados!C27/EstadoResultados!C7,0) | D17: =IF(C17>0.10,"Excelente",IF(C17>0.05,"Bueno","Bajo"))

Sheet Config
A1: v1.0.0
A3: CONFIGURACION
A5: Producto | B5: Estados Financieros Completos
A6: Version | B6: v1.0.0
A7: Marca | B7: No Somos Ignorantes
A8: Precio | B8: Bs. 199 (Premium)
A9: Proteccion | B9: nsi2024
A11: INSTRUCCIONES
A12: 1. | B12: Ingresa el periodo en el Dashboard.
A13: 2. | B13: En 'BalanceGeneral', ingresa los saldos de cada cuenta (celdas amarillas).
A14: 3. | B14: En 'EstadoResultados', ingresa ingresos, costos y gastos.
A15: 4. | B15: En 'FlujoCaja', ingresa los movimientos de efectivo.
A16: 5. | B16: La Utilidad del Ejercicio se vincula automaticamente al Balance.
A17: 6. | B17: Las Razones Financieras se calculan automaticamente.
A18: 7. | B18: El Dashboard muestra KPIs, verificacion de cuadre y graficos.
A19: 8. | B19: Para desbloquear: Revisar -> Desproteger hoja -> nsi2024
A21: NOTA | B21: El Plan de Cuentas es referencial. Ajusta segun tu empresa.
