Workbook

Sheet Dashboard
B2: SISTEMA DE VENTAS — PANEL EJECUTIVO
B3: No Somos Ignorantes | v1.0 | Resumen en tiempo real
B5: VENTAS DEL MES (Bs.) | F5: UNIDADES VENDIDAS
B6: =IFERROR(SUMPRODUCT((MONTH(Ventas!A4:A203)=MONTH(TODAY()))*(YEAR(Ventas!A4:A203)=YEAR(TODAY()))*Ventas!H4:H203),0) | F6: =IFERROR(SUMPRODUCT((MONTH(Ventas!A4:A203)=MONTH(TODAY()))*(YEAR(Ventas!A4:A203)=YEAR(TODAY()))*Ventas!E4:E203),0)
B7: Meta mensual: | C7: 50000 | F7: Transacciones: | G7: =IFERROR(SUMPRODUCT((MONTH(Ventas!A4:A203)=MONTH(TODAY()))*(YEAR(Ventas!A4:A203)=YEAR(TODAY()))*(Ventas!H4:H203>0)*1),0)
B8: Cumplimiento: | C8: =IFERROR(B6/C7,0) | F8: Ticket promedio: | G8: =IFERROR(B6/G7,"—")
B11: GANANCIA BRUTA (Bs.) | F11: ALERTAS DE INVENTARIO
B12: =IFERROR(SUMPRODUCT((MONTH(Ventas!A4:A203)=MONTH(TODAY()))*(YEAR(Ventas!A4:A203)=YEAR(TODAY()))*Ventas!H4:H203)-SUMPRODUCT((MONTH(Ventas!A4:A203)=MONTH(TODAY()))*(YEAR(Ventas!A4:A203)=YEAR(TODAY()))*Ventas!E4:E203*IFERROR(VLOOKUP(Ventas!C4:C203,Productos!A4:H103,4,FALSE),0)),0) | F12: =COUNTIF(Productos!I4:I103,"BAJO")+COUNTIF(Productos!I4:I103,"AGOTADO")
B13: Margen (%): | C13: =IFERROR(B12/B6,0) | F13: Agotados: | G13: =COUNTIF(Productos!I4:I103,"AGOTADO")
F14: Stock bajo: | G14: =COUNTIF(Productos!I4:I103,"BAJO")
B17: TOTAL PRODUCTOS | F17: VALOR INVENTARIO (Bs.)
B18: =COUNTA(Productos!B4:B103) | F18: =IFERROR(SUMPRODUCT(Productos!E4:E103*Productos!G4:G103),0)
B21: TOP 5 PRODUCTOS POR VENTAS
B22: Producto | C22: Ventas (Bs.) | F22: Método de Pago | G22: Total (Bs.)
B23: =IFERROR(INDEX(Productos!B4:B103,MATCH(LARGE(Productos!J4:J103,1),Productos!J4:J103,0)),"—") | C23: =IFERROR(LARGE(Productos!J4:J103,1),0) | F23: Efectivo | G23: =IFERROR(SUMPRODUCT((Ventas!I4:I203="Efectivo")*Ventas!H4:H203),0)
B24: =IFERROR(INDEX(Productos!B4:B103,MATCH(LARGE(Productos!J4:J103,2),Productos!J4:J103,0)),"—") | C24: =IFERROR(LARGE(Productos!J4:J103,2),0) | F24: Transferencia | G24: =IFERROR(SUMPRODUCT((Ventas!I4:I203="Transferencia")*Ventas!H4:H203),0)
B25: =IFERROR(INDEX(Productos!B4:B103,MATCH(LARGE(Productos!J4:J103,3),Productos!J4:J103,0)),"—") | C25: =IFERROR(LARGE(Productos!J4:J103,3),0) | F25: QR | G25: =IFERROR(SUMPRODUCT((Ventas!I4:I203="QR")*Ventas!H4:H203),0)
B26: =IFERROR(INDEX(Productos!B4:B103,MATCH(LARGE(Productos!J4:J103,4),Productos!J4:J103,0)),"—") | C26: =IFERROR(LARGE(Productos!J4:J103,4),0) | F26: Tarjeta | G26: =IFERROR(SUMPRODUCT((Ventas!I4:I203="Tarjeta")*Ventas!H4:H203),0)
B27: =IFERROR(INDEX(Productos!B4:B103,MATCH(LARGE(Productos!J4:J103,5),Productos!J4:J103,0)),"—") | C27: =IFERROR(LARGE(Productos!J4:J103,5),0)

Sheet Productos
A1: CATÁLOGO DE PRODUCTOS
A2: Registra tus productos con código único. Las celdas amarillas son editables.
A3: CÓDIGO | B3: PRODUCTO | C3: CATEGORÍA | D3: COSTO (Bs.) | E3: PRECIO VENTA (Bs.) | F3: MARGEN (%) | G3: STOCK ACTUAL | H3: STOCK MÍNIMO | I3: ESTADO | J3: VENTAS ACUM. (Bs.)
A4: =IF(B4="","","PROD-"&TEXT(ROW()-3,"0000")) | B4: Café Molido 500g | C4: Alimentos | D4: 35 | E4: 55 | F4: =IFERROR((E4-D4)/D4,0) | G4: 50 | H4: 10 | I4: =IF(B4="","",IF(G4=0,"AGOTADO",IF(G4<=H4,"BAJO","NORMAL"))) | J4: =IFERROR(SUMPRODUCT((Ventas!C4:C203=A4)*Ventas!H4:H203),0)
A5: =IF(B5="","","PROD-"&TEXT(ROW()-3,"0000")) | B5: Jugo Natural 1L | C5: Bebidas | D5: 8 | E5: 15 | F5: =IFERROR((E5-D5)/D5,0) | G5: 120 | H5: 20 | I5: =IF(B5="","",IF(G5=0,"AGOTADO",IF(G5<=H5,"BAJO","NORMAL"))) | J5: =IFERROR(SUMPRODUCT((Ventas!C4:C203=A5)*Ventas!H4:H203),0)
A6: =IF(B6="","","PROD-"&TEXT(ROW()-3,"0000")) | B6: Detergente Premium | C6: Limpieza | D6: 22 | E6: 38 | F6: =IFERROR((E6-D6)/D6,0) | G6: 80 | H6: 15 | I6: =IF(B6="","",IF(G6=0,"AGOTADO",IF(G6<=H6,"BAJO","NORMAL"))) | J6: =IFERROR(SUMPRODUCT((Ventas!C4:C203=A6)*Ventas!H4:H203),0)
A7: =IF(B7="","","PROD-"&TEXT(ROW()-3,"0000")) | B7: Cable USB-C | C7: Electrónica | D7: 15 | E7: 35 | F7: =IFERROR((E7-D7)/D7,0) | G7: 45 | H7: 10 | I7: =IF(B7="","",IF(G7=0,"AGOTADO",IF(G7<=H7,"BAJO","NORMAL"))) | J7: =IFERROR(SUMPRODUCT((Ventas!C4:C203=A7)*Ventas!H4:H203),0)
A8: =IF(B8="","","PROD-"&TEXT(ROW()-3,"0000")) | B8: Camiseta Algodón | C8: Ropa | D8: 30 | E8: 65 | F8: =IFERROR((E8-D8)/D8,0) | G8: 60 | H8: 12 | I8: =IF(B8="","",IF(G8=0,"AGOTADO",IF(G8<=H8,"BAJO","NORMAL"))) | J8: =IFERROR(SUMPRODUCT((Ventas!C4:C203=A8)*Ventas!H4:H203),0)
A9: =IF(B9="","","PROD-"&TEXT(ROW()-3,"0000")) | F9: =IFERROR((E9-D9)/D9,0) | I9: =IF(B9="","",IF(G9=0,"AGOTADO",IF(G9<=H9,"BAJO","NORMAL"))) | J9: =IFERROR(SUMPRODUCT((Ventas!C4:C203=A9)*Ventas!H4:H203),0)
A10: =IF(B10="","","PROD-"&TEXT(ROW()-3,"0000")) | F10: =IFERROR((E10-D10)/D10,0) | I10: =IF(B10="","",IF(G10=0,"AGOTADO",IF(G10<=H10,"BAJO","NORMAL"))) | J10: =IFERROR(SUMPRODUCT((Ventas!C4:C203=A10)*Ventas!H4:H203),0)
A11: =IF(B11="","","PROD-"&TEXT(ROW()-3,"0000")) | F11: =IFERROR((E11-D11)/D11,0) | I11: =IF(B11="","",IF(G11=0,"AGOTADO",IF(G11<=H11,"BAJO","NORMAL"))) | J11: =IFERROR(SUMPRODUCT((Ventas!C4:C203=A11)*Ventas!H4:H203),0)
A12: =IF(B12="","","PROD-"&TEXT(ROW()-3,"0000")) | F12: =IFERROR((E12-D12)/D12,0) | I12: =IF(B12="","",IF(G12=0,"AGOTADO",IF(G12<=H12,"BAJO","NORMAL"))) | J12: =IFERROR(SUMPRODUCT((Ventas!C4:C203=A12)*Ventas!H4:H203),0)
A13: =IF(B13="","","PROD-"&TEXT(ROW()-3,"0000")) | F13: =IFERROR((E13-D13)/D13,0) | I13: =IF(B13="","",IF(G13=0,"AGOTADO",IF(G13<=H13,"BAJO","NORMAL"))) | J13: =IFERROR(SUMPRODUCT((Ventas!C4:C203=A13)*Ventas!H4:H203),0)
A14: =IF(B14="","","PROD-"&TEXT(ROW()-3,"0000")) | F14: =IFERROR((E14-D14)/D14,0) | I14: =IF(B14="","",IF(G14=0,"AGOTADO",IF(G14<=H14,"BAJO","NORMAL"))) | J14: =IFERROR(SUMPRODUCT((Ventas!C4:C203=A14)*Ventas!H4:H203),0)
A15: =IF(B15="","","PROD-"&TEXT(ROW()-3,"0000")) | F15: =IFERROR((E15-D15)/D15,0) | I15: =IF(B15="","",IF(G15=0,"AGOTADO",IF(G15<=H15,"BAJO","NORMAL"))) | J15: =IFERROR(SUMPRODUCT((Ventas!C4:C203=A15)*Ventas!H4:H203),0)
A16: =IF(B16="","","PROD-"&TEXT(ROW()-3,"0000")) | F16: =IFERROR((E16-D16)/D16,0) | I16: =IF(B16="","",IF(G16=0,"AGOTADO",IF(G16<=H16,"BAJO","NORMAL"))) | J16: =IFERROR(SUMPRODUCT((Ventas!C4:C203=A16)*Ventas!H4:H203),0)
A17: =IF(B17="","","PROD-"&TEXT(ROW()-3,"0000")) | F17: =IFERROR((E17-D17)/D17,0) | I17: =IF(B17="","",IF(G17=0,"AGOTADO",IF(G17<=H17,"BAJO","NORMAL"))) | J17: =IFERROR(SUMPRODUCT((Ventas!C4:C203=A17)*Ventas!H4:H203),0)
A18: =IF(B18="","","PROD-"&TEXT(ROW()-3,"0000")) | F18: =IFERROR((E18-D18)/D18,0) | I18: =IF(B18="","",IF(G18=0,"AGOTADO",IF(G18<=H18,"BAJO","NORMAL"))) | J18: =IFERROR(SUMPRODUCT((Ventas!C4:C203=A18)*Ventas!H4:H203),0)
A19: =IF(B19="","","PROD-"&TEXT(ROW()-3,"0000")) | F19: =IFERROR((E19-D19)/D19,0) | I19: =IF(B19="","",IF(G19=0,"AGOTADO",IF(G19<=H19,"BAJO","NORMAL"))) | J19: =IFERROR(SUMPRODUCT((Ventas!C4:C203=A19)*Ventas!H4:H203),0)
A20: =IF(B20="","","PROD-"&TEXT(ROW()-3,"0000")) | F20: =IFERROR((E20-D20)/D20,0) | I20: =IF(B20="","",IF(G20=0,"AGOTADO",IF(G20<=H20,"BAJO","NORMAL"))) | J20: =IFERROR(SUMPRODUCT((Ventas!C4:C203=A20)*Ventas!H4:H203),0)
A21: =IF(B21="","","PROD-"&TEXT(ROW()-3,"0000")) | F21: =IFERROR((E21-D21)/D21,0) | I21: =IF(B21="","",IF(G21=0,"AGOTADO",IF(G21<=H21,"BAJO","NORMAL"))) | J21: =IFERROR(SUMPRODUCT((Ventas!C4:C203=A21)*Ventas!H4:H203),0)
A22: =IF(B22="","","PROD-"&TEXT(ROW()-3,"0000")) | F22: =IFERROR((E22-D22)/D22,0) | I22: =IF(B22="","",IF(G22=0,"AGOTADO",IF(G22<=H22,"BAJO","NORMAL"))) | J22: =IFERROR(SUMPRODUCT((Ventas!C4:C203=A22)*Ventas!H4:H203),0)
A23: =IF(B23="","","PROD-"&TEXT(ROW()-3,"0000")) | F23: =IFERROR((E23-D23)/D23,0) | I23: =IF(B23="","",IF(G23=0,"AGOTADO",IF(G23<=H23,"BAJO","NORMAL"))) | J23: =IFERROR(SUMPRODUCT((Ventas!C4:C203=A23)*Ventas!H4:H203),0)
A24: =IF(B24="","","PROD-"&TEXT(ROW()-3,"0000")) | F24: =IFERROR((E24-D24)/D24,0) | I24: =IF(B24="","",IF(G24=0,"AGOTADO",IF(G24<=H24,"BAJO","NORMAL"))) | J24: =IFERROR(SUMPRODUCT((Ventas!C4:C203=A24)*Ventas!H4:H203),0)
A25: =IF(B25="","","PROD-"&TEXT(ROW()-3,"0000")) | F25: =IFERROR((E25-D25)/D25,0) | I25: =IF(B25="","",IF(G25=0,"AGOTADO",IF(G25<=H25,"BAJO","NORMAL"))) | J25: =IFERROR(SUMPRODUCT((Ventas!C4:C203=A25)*Ventas!H4:H203),0)
A26: =IF(B26="","","PROD-"&TEXT(ROW()-3,"0000")) | F26: =IFERROR((E26-D26)/D26,0) | I26: =IF(B26="","",IF(G26=0,"AGOTADO",IF(G26<=H26,"BAJO","NORMAL"))) | J26: =IFERROR(SUMPRODUCT((Ventas!C4:C203=A26)*Ventas!H4:H203),0)
A27: =IF(B27="","","PROD-"&TEXT(ROW()-3,"0000")) | F27: =IFERROR((E27-D27)/D27,0) | I27: =IF(B27="","",IF(G27=0,"AGOTADO",IF(G27<=H27,"BAJO","NORMAL"))) | J27: =IFERROR(SUMPRODUCT((Ventas!C4:C203=A27)*Ventas!H4:H203),0)
A28: =IF(B28="","","PROD-"&TEXT(ROW()-3,"0000")) | F28: =IFERROR((E28-D28)/D28,0) | I28: =IF(B28="","",IF(G28=0,"AGOTADO",IF(G28<=H28,"BAJO","NORMAL"))) | J28: =IFERROR(SUMPRODUCT((Ventas!C4:C203=A28)*Ventas!H4:H203),0)
A29: =IF(B29="","","PROD-"&TEXT(ROW()-3,"0000")) | F29: =IFERROR((E29-D29)/D29,0) | I29: =IF(B29="","",IF(G29=0,"AGOTADO",IF(G29<=H29,"BAJO","NORMAL"))) | J29: =IFERROR(SUMPRODUCT((Ventas!C4:C203=A29)*Ventas!H4:H203),0)
A30: =IF(B30="","","PROD-"&TEXT(ROW()-3,"0000")) | F30: =IFERROR((E30-D30)/D30,0) | I30: =IF(B30="","",IF(G30=0,"AGOTADO",IF(G30<=H30,"BAJO","NORMAL"))) | J30: =IFERROR(SUMPRODUCT((Ventas!C4:C203=A30)*Ventas!H4:H203),0)
A31: =IF(B31="","","PROD-"&TEXT(ROW()-3,"0000")) | F31: =IFERROR((E31-D31)/D31,0) | I31: =IF(B31="","",IF(G31=0,"AGOTADO",IF(G31<=H31,"BAJO","NORMAL"))) | J31: =IFERROR(SUMPRODUCT((Ventas!C4:C203=A31)*Ventas!H4:H203),0)
A32: =IF(B32="","","PROD-"&TEXT(ROW()-3,"0000")) | F32: =IFERROR((E32-D32)/D32,0) | I32: =IF(B32="","",IF(G32=0,"AGOTADO",IF(G32<=H32,"BAJO","NORMAL"))) | J32: =IFERROR(SUMPRODUCT((Ventas!C4:C203=A32)*Ventas!H4:H203),0)
A33: =IF(B33="","","PROD-"&TEXT(ROW()-3,"0000")) | F33: =IFERROR((E33-D33)/D33,0) | I33: =IF(B33="","",IF(G33=0,"AGOTADO",IF(G33<=H33,"BAJO","NORMAL"))) | J33: =IFERROR(SUMPRODUCT((Ventas!C4:C203=A33)*Ventas!H4:H203),0)
A34: =IF(B34="","","PROD-"&TEXT(ROW()-3,"0000")) | F34: =IFERROR((E34-D34)/D34,0) | I34: =IF(B34="","",IF(G34=0,"AGOTADO",IF(G34<=H34,"BAJO","NORMAL"))) | J34: =IFERROR(SUMPRODUCT((Ventas!C4:C203=A34)*Ventas!H4:H203),0)
A35: =IF(B35="","","PROD-"&TEXT(ROW()-3,"0000")) | F35: =IFERROR((E35-D35)/D35,0) | I35: =IF(B35="","",IF(G35=0,"AGOTADO",IF(G35<=H35,"BAJO","NORMAL"))) | J35: =IFERROR(SUMPRODUCT((Ventas!C4:C203=A35)*Ventas!H4:H203),0)
A36: =IF(B36="","","PROD-"&TEXT(ROW()-3,"0000")) | F36: =IFERROR((E36-D36)/D36,0) | I36: =IF(B36="","",IF(G36=0,"AGOTADO",IF(G36<=H36,"BAJO","NORMAL"))) | J36: =IFERROR(SUMPRODUCT((Ventas!C4:C203=A36)*Ventas!H4:H203),0)
A37: =IF(B37="","","PROD-"&TEXT(ROW()-3,"0000")) | F37: =IFERROR((E37-D37)/D37,0) | I37: =IF(B37="","",IF(G37=0,"AGOTADO",IF(G37<=H37,"BAJO","NORMAL"))) | J37: =IFERROR(SUMPRODUCT((Ventas!C4:C203=A37)*Ventas!H4:H203),0)
A38: =IF(B38="","","PROD-"&TEXT(ROW()-3,"0000")) | F38: =IFERROR((E38-D38)/D38,0) | I38: =IF(B38="","",IF(G38=0,"AGOTADO",IF(G38<=H38,"BAJO","NORMAL"))) | J38: =IFERROR(SUMPRODUCT((Ventas!C4:C203=A38)*Ventas!H4:H203),0)
A39: =IF(B39="","","PROD-"&TEXT(ROW()-3,"0000")) | F39: =IFERROR((E39-D39)/D39,0) | I39: =IF(B39="","",IF(G39=0,"AGOTADO",IF(G39<=H39,"BAJO","NORMAL"))) | J39: =IFERROR(SUMPRODUCT((Ventas!C4:C203=A39)*Ventas!H4:H203),0)
A40: =IF(B40="","","PROD-"&TEXT(ROW()-3,"0000")) | F40: =IFERROR((E40-D40)/D40,0) | I40: =IF(B40="","",IF(G40=0,"AGOTADO",IF(G40<=H40,"BAJO","NORMAL"))) | J40: =IFERROR(SUMPRODUCT((Ventas!C4:C203=A40)*Ventas!H4:H203),0)
...

Sheet Ventas
A1: REGISTRO DE VENTAS
A2: Ingresa el código del producto en la columna C. El nombre y precio se llenan automáticamente (VLOOKUP).
A3: FECHA | B3: # VENTA | C3: CÓDIGO PROD. | D3: PRODUCTO (auto) | E3: CANT. | F3: PRECIO UNIT. (auto) | G3: DESC. (%) | H3: TOTAL (Bs.) | I3: MÉTODO PAGO | J3: VENDEDOR
A4: 45672 | B4: =IF(A4="","",ROW()-3) | C4: PROD-0001 | D4: =IFERROR(VLOOKUP(C4,Productos!A4:B103,2,FALSE),"") | E4: 3 | F4: =IFERROR(VLOOKUP(C4,Productos!A4:E103,5,FALSE),0) | G4: 0 | H4: =IFERROR(E4*F4*(1-G4),0) | I4: Efectivo | J4: Ana
A5: 45672 | B5: =IF(A5="","",ROW()-3) | C5: PROD-0002 | D5: =IFERROR(VLOOKUP(C5,Productos!A4:B103,2,FALSE),"") | E5: 10 | F5: =IFERROR(VLOOKUP(C5,Productos!A4:E103,5,FALSE),0) | G5: 0.05 | H5: =IFERROR(E5*F5*(1-G5),0) | I5: QR | J5: Carlos
A6: 45673 | B6: =IF(A6="","",ROW()-3) | C6: PROD-0003 | D6: =IFERROR(VLOOKUP(C6,Productos!A4:B103,2,FALSE),"") | E6: 2 | F6: =IFERROR(VLOOKUP(C6,Productos!A4:E103,5,FALSE),0) | G6: 0 | H6: =IFERROR(E6*F6*(1-G6),0) | I6: Transferencia | J6: Ana
A7: 45673 | B7: =IF(A7="","",ROW()-3) | C7: PROD-0005 | D7: =IFERROR(VLOOKUP(C7,Productos!A4:B103,2,FALSE),"") | E7: 4 | F7: =IFERROR(VLOOKUP(C7,Productos!A4:E103,5,FALSE),0) | G7: 0.1 | H7: =IFERROR(E7*F7*(1-G7),0) | I7: Tarjeta | J7: María
A8: 45674 | B8: =IF(A8="","",ROW()-3) | C8: PROD-0001 | D8: =IFERROR(VLOOKUP(C8,Productos!A4:B103,2,FALSE),"") | E8: 5 | F8: =IFERROR(VLOOKUP(C8,Productos!A4:E103,5,FALSE),0) | G8: 0 | H8: =IFERROR(E8*F8*(1-G8),0) | I8: Efectivo | J8: Carlos
A9: 45674 | B9: =IF(A9="","",ROW()-3) | C9: PROD-0004 | D9: =IFERROR(VLOOKUP(C9,Productos!A4:B103,2,FALSE),"") | E9: 2 | F9: =IFERROR(VLOOKUP(C9,Productos!A4:E103,5,FALSE),0) | G9: 0 | H9: =IFERROR(E9*F9*(1-G9),0) | I9: QR | J9: Ana
A10: 45675 | B10: =IF(A10="","",ROW()-3) | C10: PROD-0002 | D10: =IFERROR(VLOOKUP(C10,Productos!A4:B103,2,FALSE),"") | E10: 8 | F10: =IFERROR(VLOOKUP(C10,Productos!A4:E103,5,FALSE),0) | G10: 0 | H10: =IFERROR(E10*F10*(1-G10),0) | I10: Transferencia | J10: María
A11: 45675 | B11: =IF(A11="","",ROW()-3) | C11: PROD-0005 | D11: =IFERROR(VLOOKUP(C11,Productos!A4:B103,2,FALSE),"") | E11: 3 | F11: =IFERROR(VLOOKUP(C11,Productos!A4:E103,5,FALSE),0) | G11: 0.05 | H11: =IFERROR(E11*F11*(1-G11),0) | I11: Efectivo | J11: Carlos
B12: =IF(A12="","",ROW()-3) | D12: =IFERROR(VLOOKUP(C12,Productos!A4:B103,2,FALSE),"") | F12: =IFERROR(VLOOKUP(C12,Productos!A4:E103,5,FALSE),0) | H12: =IFERROR(E12*F12*(1-G12),0)
B13: =IF(A13="","",ROW()-3) | D13: =IFERROR(VLOOKUP(C13,Productos!A4:B103,2,FALSE),"") | F13: =IFERROR(VLOOKUP(C13,Productos!A4:E103,5,FALSE),0) | H13: =IFERROR(E13*F13*(1-G13),0)
B14: =IF(A14="","",ROW()-3) | D14: =IFERROR(VLOOKUP(C14,Productos!A4:B103,2,FALSE),"") | F14: =IFERROR(VLOOKUP(C14,Productos!A4:E103,5,FALSE),0) | H14: =IFERROR(E14*F14*(1-G14),0)
B15: =IF(A15="","",ROW()-3) | D15: =IFERROR(VLOOKUP(C15,Productos!A4:B103,2,FALSE),"") | F15: =IFERROR(VLOOKUP(C15,Productos!A4:E103,5,FALSE),0) | H15: =IFERROR(E15*F15*(1-G15),0)
B16: =IF(A16="","",ROW()-3) | D16: =IFERROR(VLOOKUP(C16,Productos!A4:B103,2,FALSE),"") | F16: =IFERROR(VLOOKUP(C16,Productos!A4:E103,5,FALSE),0) | H16: =IFERROR(E16*F16*(1-G16),0)
B17: =IF(A17="","",ROW()-3) | D17: =IFERROR(VLOOKUP(C17,Productos!A4:B103,2,FALSE),"") | F17: =IFERROR(VLOOKUP(C17,Productos!A4:E103,5,FALSE),0) | H17: =IFERROR(E17*F17*(1-G17),0)
B18: =IF(A18="","",ROW()-3) | D18: =IFERROR(VLOOKUP(C18,Productos!A4:B103,2,FALSE),"") | F18: =IFERROR(VLOOKUP(C18,Productos!A4:E103,5,FALSE),0) | H18: =IFERROR(E18*F18*(1-G18),0)
B19: =IF(A19="","",ROW()-3) | D19: =IFERROR(VLOOKUP(C19,Productos!A4:B103,2,FALSE),"") | F19: =IFERROR(VLOOKUP(C19,Productos!A4:E103,5,FALSE),0) | H19: =IFERROR(E19*F19*(1-G19),0)
B20: =IF(A20="","",ROW()-3) | D20: =IFERROR(VLOOKUP(C20,Productos!A4:B103,2,FALSE),"") | F20: =IFERROR(VLOOKUP(C20,Productos!A4:E103,5,FALSE),0) | H20: =IFERROR(E20*F20*(1-G20),0)
B21: =IF(A21="","",ROW()-3) | D21: =IFERROR(VLOOKUP(C21,Productos!A4:B103,2,FALSE),"") | F21: =IFERROR(VLOOKUP(C21,Productos!A4:E103,5,FALSE),0) | H21: =IFERROR(E21*F21*(1-G21),0)
B22: =IF(A22="","",ROW()-3) | D22: =IFERROR(VLOOKUP(C22,Productos!A4:B103,2,FALSE),"") | F22: =IFERROR(VLOOKUP(C22,Productos!A4:E103,5,FALSE),0) | H22: =IFERROR(E22*F22*(1-G22),0)
B23: =IF(A23="","",ROW()-3) | D23: =IFERROR(VLOOKUP(C23,Productos!A4:B103,2,FALSE),"") | F23: =IFERROR(VLOOKUP(C23,Productos!A4:E103,5,FALSE),0) | H23: =IFERROR(E23*F23*(1-G23),0)
B24: =IF(A24="","",ROW()-3) | D24: =IFERROR(VLOOKUP(C24,Productos!A4:B103,2,FALSE),"") | F24: =IFERROR(VLOOKUP(C24,Productos!A4:E103,5,FALSE),0) | H24: =IFERROR(E24*F24*(1-G24),0)
B25: =IF(A25="","",ROW()-3) | D25: =IFERROR(VLOOKUP(C25,Productos!A4:B103,2,FALSE),"") | F25: =IFERROR(VLOOKUP(C25,Productos!A4:E103,5,FALSE),0) | H25: =IFERROR(E25*F25*(1-G25),0)
B26: =IF(A26="","",ROW()-3) | D26: =IFERROR(VLOOKUP(C26,Productos!A4:B103,2,FALSE),"") | F26: =IFERROR(VLOOKUP(C26,Productos!A4:E103,5,FALSE),0) | H26: =IFERROR(E26*F26*(1-G26),0)
B27: =IF(A27="","",ROW()-3) | D27: =IFERROR(VLOOKUP(C27,Productos!A4:B103,2,FALSE),"") | F27: =IFERROR(VLOOKUP(C27,Productos!A4:E103,5,FALSE),0) | H27: =IFERROR(E27*F27*(1-G27),0)
B28: =IF(A28="","",ROW()-3) | D28: =IFERROR(VLOOKUP(C28,Productos!A4:B103,2,FALSE),"") | F28: =IFERROR(VLOOKUP(C28,Productos!A4:E103,5,FALSE),0) | H28: =IFERROR(E28*F28*(1-G28),0)
B29: =IF(A29="","",ROW()-3) | D29: =IFERROR(VLOOKUP(C29,Productos!A4:B103,2,FALSE),"") | F29: =IFERROR(VLOOKUP(C29,Productos!A4:E103,5,FALSE),0) | H29: =IFERROR(E29*F29*(1-G29),0)
B30: =IF(A30="","",ROW()-3) | D30: =IFERROR(VLOOKUP(C30,Productos!A4:B103,2,FALSE),"") | F30: =IFERROR(VLOOKUP(C30,Productos!A4:E103,5,FALSE),0) | H30: =IFERROR(E30*F30*(1-G30),0)
B31: =IF(A31="","",ROW()-3) | D31: =IFERROR(VLOOKUP(C31,Productos!A4:B103,2,FALSE),"") | F31: =IFERROR(VLOOKUP(C31,Productos!A4:E103,5,FALSE),0) | H31: =IFERROR(E31*F31*(1-G31),0)
B32: =IF(A32="","",ROW()-3) | D32: =IFERROR(VLOOKUP(C32,Productos!A4:B103,2,FALSE),"") | F32: =IFERROR(VLOOKUP(C32,Productos!A4:E103,5,FALSE),0) | H32: =IFERROR(E32*F32*(1-G32),0)
B33: =IF(A33="","",ROW()-3) | D33: =IFERROR(VLOOKUP(C33,Productos!A4:B103,2,FALSE),"") | F33: =IFERROR(VLOOKUP(C33,Productos!A4:E103,5,FALSE),0) | H33: =IFERROR(E33*F33*(1-G33),0)
B34: =IF(A34="","",ROW()-3) | D34: =IFERROR(VLOOKUP(C34,Productos!A4:B103,2,FALSE),"") | F34: =IFERROR(VLOOKUP(C34,Productos!A4:E103,5,FALSE),0) | H34: =IFERROR(E34*F34*(1-G34),0)
B35: =IF(A35="","",ROW()-3) | D35: =IFERROR(VLOOKUP(C35,Productos!A4:B103,2,FALSE),"") | F35: =IFERROR(VLOOKUP(C35,Productos!A4:E103,5,FALSE),0) | H35: =IFERROR(E35*F35*(1-G35),0)
B36: =IF(A36="","",ROW()-3) | D36: =IFERROR(VLOOKUP(C36,Productos!A4:B103,2,FALSE),"") | F36: =IFERROR(VLOOKUP(C36,Productos!A4:E103,5,FALSE),0) | H36: =IFERROR(E36*F36*(1-G36),0)
B37: =IF(A37="","",ROW()-3) | D37: =IFERROR(VLOOKUP(C37,Productos!A4:B103,2,FALSE),"") | F37: =IFERROR(VLOOKUP(C37,Productos!A4:E103,5,FALSE),0) | H37: =IFERROR(E37*F37*(1-G37),0)
B38: =IF(A38="","",ROW()-3) | D38: =IFERROR(VLOOKUP(C38,Productos!A4:B103,2,FALSE),"") | F38: =IFERROR(VLOOKUP(C38,Productos!A4:E103,5,FALSE),0) | H38: =IFERROR(E38*F38*(1-G38),0)
B39: =IF(A39="","",ROW()-3) | D39: =IFERROR(VLOOKUP(C39,Productos!A4:B103,2,FALSE),"") | F39: =IFERROR(VLOOKUP(C39,Productos!A4:E103,5,FALSE),0) | H39: =IFERROR(E39*F39*(1-G39),0)
B40: =IF(A40="","",ROW()-3) | D40: =IFERROR(VLOOKUP(C40,Productos!A4:B103,2,FALSE),"") | F40: =IFERROR(VLOOKUP(C40,Productos!A4:E103,5,FALSE),0) | H40: =IFERROR(E40*F40*(1-G40),0)
...

Sheet Inventario
A1: MOVIMIENTOS DE INVENTARIO
A2: Registra entradas y salidas de inventario. Tipo: ENTRADA = compras/reposición, SALIDA = ajustes/pérdidas.
A3: FECHA | B3: CÓDIGO PROD. | C3: PRODUCTO (auto) | D3: TIPO | E3: CANTIDAD | F3: COSTO UNIT. | G3: TOTAL MOVIMIENTO | H3: OBSERVACIÓN
C4: =IFERROR(VLOOKUP(B4,Productos!A4:B103,2,FALSE),"") | G4: =IFERROR(E4*F4,0)
C5: =IFERROR(VLOOKUP(B5,Productos!A4:B103,2,FALSE),"") | G5: =IFERROR(E5*F5,0)
C6: =IFERROR(VLOOKUP(B6,Productos!A4:B103,2,FALSE),"") | G6: =IFERROR(E6*F6,0)
C7: =IFERROR(VLOOKUP(B7,Productos!A4:B103,2,FALSE),"") | G7: =IFERROR(E7*F7,0)
C8: =IFERROR(VLOOKUP(B8,Productos!A4:B103,2,FALSE),"") | G8: =IFERROR(E8*F8,0)
C9: =IFERROR(VLOOKUP(B9,Productos!A4:B103,2,FALSE),"") | G9: =IFERROR(E9*F9,0)
C10: =IFERROR(VLOOKUP(B10,Productos!A4:B103,2,FALSE),"") | G10: =IFERROR(E10*F10,0)
C11: =IFERROR(VLOOKUP(B11,Productos!A4:B103,2,FALSE),"") | G11: =IFERROR(E11*F11,0)
C12: =IFERROR(VLOOKUP(B12,Productos!A4:B103,2,FALSE),"") | G12: =IFERROR(E12*F12,0)
C13: =IFERROR(VLOOKUP(B13,Productos!A4:B103,2,FALSE),"") | G13: =IFERROR(E13*F13,0)
C14: =IFERROR(VLOOKUP(B14,Productos!A4:B103,2,FALSE),"") | G14: =IFERROR(E14*F14,0)
C15: =IFERROR(VLOOKUP(B15,Productos!A4:B103,2,FALSE),"") | G15: =IFERROR(E15*F15,0)
C16: =IFERROR(VLOOKUP(B16,Productos!A4:B103,2,FALSE),"") | G16: =IFERROR(E16*F16,0)
C17: =IFERROR(VLOOKUP(B17,Productos!A4:B103,2,FALSE),"") | G17: =IFERROR(E17*F17,0)
C18: =IFERROR(VLOOKUP(B18,Productos!A4:B103,2,FALSE),"") | G18: =IFERROR(E18*F18,0)
C19: =IFERROR(VLOOKUP(B19,Productos!A4:B103,2,FALSE),"") | G19: =IFERROR(E19*F19,0)
C20: =IFERROR(VLOOKUP(B20,Productos!A4:B103,2,FALSE),"") | G20: =IFERROR(E20*F20,0)
C21: =IFERROR(VLOOKUP(B21,Productos!A4:B103,2,FALSE),"") | G21: =IFERROR(E21*F21,0)
C22: =IFERROR(VLOOKUP(B22,Productos!A4:B103,2,FALSE),"") | G22: =IFERROR(E22*F22,0)
C23: =IFERROR(VLOOKUP(B23,Productos!A4:B103,2,FALSE),"") | G23: =IFERROR(E23*F23,0)
C24: =IFERROR(VLOOKUP(B24,Productos!A4:B103,2,FALSE),"") | G24: =IFERROR(E24*F24,0)
C25: =IFERROR(VLOOKUP(B25,Productos!A4:B103,2,FALSE),"") | G25: =IFERROR(E25*F25,0)
C26: =IFERROR(VLOOKUP(B26,Productos!A4:B103,2,FALSE),"") | G26: =IFERROR(E26*F26,0)
C27: =IFERROR(VLOOKUP(B27,Productos!A4:B103,2,FALSE),"") | G27: =IFERROR(E27*F27,0)
C28: =IFERROR(VLOOKUP(B28,Productos!A4:B103,2,FALSE),"") | G28: =IFERROR(E28*F28,0)
C29: =IFERROR(VLOOKUP(B29,Productos!A4:B103,2,FALSE),"") | G29: =IFERROR(E29*F29,0)
C30: =IFERROR(VLOOKUP(B30,Productos!A4:B103,2,FALSE),"") | G30: =IFERROR(E30*F30,0)
C31: =IFERROR(VLOOKUP(B31,Productos!A4:B103,2,FALSE),"") | G31: =IFERROR(E31*F31,0)
C32: =IFERROR(VLOOKUP(B32,Productos!A4:B103,2,FALSE),"") | G32: =IFERROR(E32*F32,0)
C33: =IFERROR(VLOOKUP(B33,Productos!A4:B103,2,FALSE),"") | G33: =IFERROR(E33*F33,0)
C34: =IFERROR(VLOOKUP(B34,Productos!A4:B103,2,FALSE),"") | G34: =IFERROR(E34*F34,0)
C35: =IFERROR(VLOOKUP(B35,Productos!A4:B103,2,FALSE),"") | G35: =IFERROR(E35*F35,0)
C36: =IFERROR(VLOOKUP(B36,Productos!A4:B103,2,FALSE),"") | G36: =IFERROR(E36*F36,0)
C37: =IFERROR(VLOOKUP(B37,Productos!A4:B103,2,FALSE),"") | G37: =IFERROR(E37*F37,0)
C38: =IFERROR(VLOOKUP(B38,Productos!A4:B103,2,FALSE),"") | G38: =IFERROR(E38*F38,0)
C39: =IFERROR(VLOOKUP(B39,Productos!A4:B103,2,FALSE),"") | G39: =IFERROR(E39*F39,0)
C40: =IFERROR(VLOOKUP(B40,Productos!A4:B103,2,FALSE),"") | G40: =IFERROR(E40*F40,0)
...

Sheet Reportes
B2: REPORTES DE VENTAS
B4: VENTAS POR CATEGORÍA | G4: VENTAS POR VENDEDOR
B5: Categoría | C5: Ventas (Bs.) | D5: % del Total | G5: Vendedor | H5: Ventas (Bs.) | I5: # Transacciones
B6: Alimentos | C6: =IFERROR(SUMPRODUCT((VLOOKUP(Ventas!C4:C203,Productos!A4:C103,3,FALSE)="Alimentos")*Ventas!H4:H203),0) | D6: =IFERROR(C6/SUM(C6:C11),0) | G6: Ana | H6: =IFERROR(SUMPRODUCT((Ventas!J4:J203="Ana")*Ventas!H4:H203),0) | I6: =COUNTIF(Ventas!J4:J203,"Ana")
B7: Bebidas | C7: =IFERROR(SUMPRODUCT((VLOOKUP(Ventas!C4:C203,Productos!A4:C103,3,FALSE)="Bebidas")*Ventas!H4:H203),0) | D7: =IFERROR(C7/SUM(C6:C11),0) | G7: Carlos | H7: =IFERROR(SUMPRODUCT((Ventas!J4:J203="Carlos")*Ventas!H4:H203),0) | I7: =COUNTIF(Ventas!J4:J203,"Carlos")
B8: Limpieza | C8: =IFERROR(SUMPRODUCT((VLOOKUP(Ventas!C4:C203,Productos!A4:C103,3,FALSE)="Limpieza")*Ventas!H4:H203),0) | D8: =IFERROR(C8/SUM(C6:C11),0) | G8: María | H8: =IFERROR(SUMPRODUCT((Ventas!J4:J203="María")*Ventas!H4:H203),0) | I8: =COUNTIF(Ventas!J4:J203,"María")
B9: Electrónica | C9: =IFERROR(SUMPRODUCT((VLOOKUP(Ventas!C4:C203,Productos!A4:C103,3,FALSE)="Electrónica")*Ventas!H4:H203),0) | D9: =IFERROR(C9/SUM(C6:C11),0) | G9: Pedro | H9: =IFERROR(SUMPRODUCT((Ventas!J4:J203="Pedro")*Ventas!H4:H203),0) | I9: =COUNTIF(Ventas!J4:J203,"Pedro")
B10: Ropa | C10: =IFERROR(SUMPRODUCT((VLOOKUP(Ventas!C4:C203,Productos!A4:C103,3,FALSE)="Ropa")*Ventas!H4:H203),0) | D10: =IFERROR(C10/SUM(C6:C11),0) | G10: Lucía | H10: =IFERROR(SUMPRODUCT((Ventas!J4:J203="Lucía")*Ventas!H4:H203),0) | I10: =COUNTIF(Ventas!J4:J203,"Lucía")
B11: Otros | C11: =IFERROR(SUMPRODUCT((VLOOKUP(Ventas!C4:C203,Productos!A4:C103,3,FALSE)="Otros")*Ventas!H4:H203),0) | D11: =IFERROR(C11/SUM(C6:C11),0)
B12: TOTAL | C12: =SUM(C6:C11)

Sheet Config
A1: v1.0.0
A3: CONFIGURACIÓN
A5: Producto | B5: Sistema de Ventas con Código Único
A6: Versión | B6: v1.0.0
A7: Marca | B7: No Somos Ignorantes
A8: Precio | B8: Bs. 89
A9: Protección | B9: nsi2024
A11: INSTRUCCIONES
A12: 1. | B12: Las celdas AMARILLAS son editables — ingresa tus datos ahí.
A13: 2. | B13: Las celdas VERDES se calculan automáticamente — no las modifiques.
A14: 3. | B14: En la hoja 'Productos', registra tus productos con nombre, costo y precio.
A15: 4. | B15: El CÓDIGO se genera automáticamente (PROD-0001, PROD-0002, etc.).
A16: 5. | B16: En la hoja 'Ventas', ingresa el código del producto y la cantidad.
A17: 6. | B17: El nombre y precio se llenan solos con VLOOKUP.
A18: 7. | B18: El Dashboard muestra KPIs, gráficos y alertas en tiempo real.
A19: 8. | B19: Para desbloquear una hoja: Revisar → Desproteger hoja → nsi2024
